Workbook

Sheet Rozpočet - průběžný stav
A1: Klíč | B1: Skupina | C1: Kategorie | D1: Ověření | E1: Položka | F1: Datum evidence | G1: Datum zaúčtování | H1: Účet | I1: Příjem | J1: Výdaj | K1: Obrat | L1: Záloha | M1: Převod | N1: Bilance | O1: Rok | P1: Poznámka | Q1: TJ účet | R1: Air účet | S1: Fio účet | T1: Hotovost 2 | U1: Hotovost 3 | V1: Kontrolní součet | W1: stav | X1: datum stavu | Y1: datum účet TJ | Z1: datum účet Air | AA1: datum účet Fio
A2: =O2&"_"&B2&"_"&C2 -> 2017_Převody_Převod z 2016 | B2: Převody | C2: Převod z 2016 | E2: Počáteční stav 2017 | F2: 42736 | I2: 99427 | K2: =I2-J2 -> 99427 | N2: =I2-J2 -> 99427 | O2: 2017 | P2: bez vlivu | Q2: 64352 | R2: 0 | S2: 0 | T2: 34075 | V2: =IF(ISBLANK(Q2),"",SUM(Q2:U2)-N2) -> -1000
A3: =O3&"_"&B3&"_"&C3 -> 2017_Běžný provoz_Příspěvky ČSK | B3: Běžný provoz | C3: Příspěvky ČSK | E3: Příspěvky ČSK | F3: 42786 | J3: 1420 | K3: =I3-J3 -> -1420 | N3: =N2+I3-J3 -> 98007 | O3: 2017 | P3: bez vlivu | V3: =IF(ISBLANK(Q3),"",SUM(Q3:U3)-N3)
A4: =O4&"_"&B4&"_"&C4 -> 2017_Běžný provoz_Příspěvky | B4: Běžný provoz | C4: Příspěvky | E4: Vybrané příspěvky na VH | F4: 42787 | I4: 11750 | K4: =I4-J4 -> 11750 | N4: =N3+I4-J4 -> 109757 | O4: 2017 | P4: y 2017 | Q4: =Q2 -> 64352 | S4: 11750 | T4: 32655 | V4: =IF(ISBLANK(Q4),"",SUM(Q4:U4)-N4) -> -1000
A5: =O5&"_"&B5&"_"&C5 -> 2017_Hamerák-akce_Hamerák materiál | B5: Hamerák-akce | C5: Hamerák materiál | E5: Záloha - Jáchym Kopřiva | F5: 42787 | K5: =I5-J5 -> 0 | L5: 3000 | N5: =N4+I5-J5 -> 109757 | O5: 2017 | P5: bez vlivu | Q5: =Q4 -> 64352 | R5: 0 | S5: 8750 | T5: 32655 | U5: 3000 | V5: =IF(ISBLANK(Q5),"",SUM(Q5:U5)-N5) -> -1000 | W5: kde je 1000? | X5: 42816
A6: =O6&"_"&B6&"_"&C6 -> 2017_Hamerák-akce_Hamerák materiál | B6: Hamerák-akce | C6: Hamerák materiál | E6: Jáchym K - schody Hamerák | F6: 42809 | J6: =4029+449 -> 4478 | K6: =I6-J6 -> -4478 | N6: =N5+I6-J6 -> 105279 | O6: 2017 | P6: bez vlivu | V6: =IF(ISBLANK(Q6),"",SUM(Q6:U6)-N6)
A7: =O7&"_"&B7&"_"&C7 -> 2017_Běžný provoz_Oddílová soutěž | B7: Běžný provoz | C7: Oddílová soutěž | E7: Jáchym K - soutěž 1. místo | F7: 42809 | J7: 1200 | K7: =I7-J7 -> -1200 | N7: =N6+I7-J7 -> 104079 | O7: 2017 | P7: y 2017 | V7: =IF(ISBLANK(Q7),"",SUM(Q7:U7)-N7)
A8: =O8&"_"&B8&"_"&C8 -> 2017_Převody_převod | B8: Převody | C8: převod | E8: z hotovosti na účet | F8: 42822 | K8: =I8-J8 -> 0 | M8: 5000 | N8: =N7+I8-J8 -> 104079 | O8: 2017 | P8: bez vlivu | V8: =IF(ISBLANK(Q8),"",SUM(Q8:U8)-N8)
A9: =O9&"_"&B9&"_"&C9 -> 2017_Hamerák-akce_Hamerák materiál | B9: Hamerák-akce | C9: Hamerák materiál | E9: Jáchym K - převod na účet | F9: 42822 | K9: =I9-J9 -> 0 | L9: -3000 | M9: -2678 | N9: =N8+I9-J9 -> 104079 | O9: 2017 | P9: bez vlivu | Q9: =Q5 -> 64352 | R9: 2322 | S9: 3750 | T9: 32655 | U9: 0 | V9: =IF(ISBLANK(Q9),"",SUM(Q9:U9)-N9) -> -1000 | W9: OK / kromě 1000 | X9: 42822
A10: =O10&"_"&B10&"_"&C10 -> 2017_Běžný provoz_Příspěvky | B10: Běžný provoz | C10: Příspěvky | E10: Příspěvky členů TJ účet (do 21.3. Čermák) | F10: 42826 | G10: 42815 | I10: 20250 | K10: =I10-J10 -> 20250 | N10: =N9+I10-J10 -> 124329 | O10: 2017 | P10: y 2017 | V10: =IF(ISBLANK(Q10),"",SUM(Q10:U10)-N10)
A11: =O11&"_"&B11&"_"&C11 -> 2017_Běžný provoz_Interní nájmy | B11: Běžný provoz | C11: Interní nájmy | E11: Interní nájmy (krakorce, klubovna, sklad) | F11: 42826 | G11: 42766 | J11: 8212 | K11: =I11-J11 -> -8212 | N11: =N10+I11-J11 -> 116117 | O11: 2017 | P11: y 2017 | V11: =IF(ISBLANK(Q11),"",SUM(Q11:U11)-N11)
A12: =O12&"_"&B12&"_"&C12 -> 2017_Běžný provoz_Interní nájmy | B12: Běžný provoz | C12: Interní nájmy | E12: Interní nájmy (tělocvična) | F12: 42826 | G12: 42766 | J12: 7488 | K12: =I12-J12 -> -7488 | N12: =N11+I12-J12 -> 108629 | O12: 2017 | P12: y 2017 | Q12: =Q$2+20250-8212-7488 -> 68902 | R12: 2322 | S12: 3750 | T12: 32655 | U12: 0 | V12: =IF(ISBLANK(Q12),"",SUM(Q12:U12)-N12) -> -1000 | W12: OK / kromě 1000 | X12: 42825 | Y12: 42815
A13: =O13&"_"&B13&"_"&C13 -> 2017_Běžný provoz_Příspěvky | B13: Běžný provoz | C13: Příspěvky | E13: příspěvky Jirka Klíma | F13: 42829 | I13: 400 | K13: =I13-J13 -> 400 | N13: =N12+I13-J13 -> 109029 | O13: 2017 | P13: y 2017 | V13: =IF(ISBLANK(Q13),"",SUM(Q13:U13)-N13)
A14: =O14&"_"&B14&"_"&C14 -> 2017_Převody_převod | B14: Převody | C14: převod | E14: z hotovosti na účet (E60) | F14: 42833 | K14: =I14-J14 -> 0 | M14: 28550 | N14: =N13+I14-J14 -> 109029 | O14: 2017 | P14: bez vlivu | V14: =IF(ISBLANK(Q14),"",SUM(Q14:U14)-N14)
A15: =O15&"_"&B15&"_"&C15 -> 2017_Běžný provoz_Příspěvky | B15: Běžný provoz | C15: Příspěvky | E15: příspěvky Klára Machová | F15: 42834 | I15: 1450 | K15: =I15-J15 -> 1450 | N15: =N14+I15-J15 -> 110479 | O15: 2017 | P15: y 2017 | Q15: =Q$2+20250-8212-7488 -> 68902 | R15: 32322 | S15: 9255 | T15: 0 | U15: 0 | V15: =IF(ISBLANK(Q15),"",SUM(Q15:U15)-N15) -> 0 | W15: OK | X15: 42834 | Y15: 42815
A16: =O16&"_"&B16&"_"&C16 -> 2017_Převody_převod | B16: Převody | C16: převod | E16: z hotovosti na účet (T) | F16: 42838 | K16: =I16-J16 -> 0 | M16: 4000 | N16: =N15+I16-J16 -> 110479 | O16: 2017 | P16: bez vlivu | V16: =IF(ISBLANK(Q16),"",SUM(Q16:U16)-N16)
A17: =O17&"_"&B17&"_"&C17 -> 2017_Běžný provoz_Příspěvky | B17: Běžný provoz | C17: Příspěvky | E17: Příspěvky M.Kalátová+M.Pelc | F17: 42844 | I17: 1600 | K17: =I17-J17 -> 1600 | N17: =N16+I17-J17 -> 112079 | O17: 2017 | P17: y 2017 | Q17: =Q$2+20250-8212-7488 -> 68902 | R17: 37922 | S17: 5255 | T17: 0 | U17: 0 | V17: =IF(ISBLANK(Q17),"",SUM(Q17:U17)-N17) -> 0 | W17: OK | X17: 42844 | Y17: 42815
A18: =O18&"_"&B18&"_"&C18 -> 2017_Hamerák-akce_Hamerák materiál | B18: Hamerák-akce | C18: Hamerák materiál | E18: Jáchym K - převod na účet | F18: 42860 | J18: 190 | K18: =I18-J18 -> -190 | N18: =N17+I18-J18 -> 111889 | O18: 2017 | P18: bez vlivu | V18: =IF(ISBLANK(Q18),"",SUM(Q18:U18)-N18)
A19: =O19&"_"&B19&"_"&C19 -> 2017_Běžný provoz_Příspěvky | B19: Běžný provoz | C19: Příspěvky | E19: Tomáš Matějka přeplatek | F19: 42860 | J19: 850 | K19: =I19-J19 -> -850 | N19: =N18+I19-J19 -> 111039 | O19: 2017 | P19: y 2017 | Q19: =Q$2+20250-8212-7488 -> 68902 | R19: 36882 | V19: =IF(ISBLANK(Q19),"",SUM(Q19:U19)-N19) -> -5255
A20: =O20&"_"&B20&"_"&C20 -> 2017_Převody_převod | B20: Převody | C20: převod | E20: z hotovosti na účet (T) | F20: 42860 | K20: =I20-J20 -> 0 | M20: 5000 | N20: =N19+I20-J20 -> 111039 | O20: 2017 | P20: bez vlivu | Q20: =Q$2+20250-8212-7488 -> 68902 | R20: 41882 | S20: 255 | T20: 0 | U20: 0 | V20: =IF(ISBLANK(Q20),"",SUM(Q20:U20)-N20) -> 0 | W20: OK | X20: 42860 | Y20: 42815
A21: =O21&"_"&B21&"_"&C21 -> 2017_Běžný provoz_Příspěvky | B21: Běžný provoz | C21: Příspěvky | E21: příspěvky Air Gábina, Fiala, Ouškatá, Lucka+Dominika, Lina, Jakub, Anna Dostálová, Pavel Bastl | F21: 42874 | I21: =7850+1300 -> 9150 | K21: =I21-J21 -> 9150 | N21: =N20+I21-J21 -> 120189 | O21: 2017 | P21: y 2017 | V21: =IF(ISBLANK(Q21),"",SUM(Q21:U21)-N21)
A22: =O22&"_"&B22&"_"&C22 -> 2017_Běžný provoz_Oddílová soutěž | B22: Běžný provoz | C22: Oddílová soutěž | E22: Evka Matějková 1. místo | F22: 42877 | J22: 1200 | K22: =I22-J22 -> -1200 | N22: =N21+I22-J22 -> 118989 | O22: 2017 | P22: y 2017 | V22: =IF(ISBLANK(Q22),"",SUM(Q22:U22)-N22)
A23: =O23&"_"&B23&"_"&C23 -> 2017_Podpora činnosti_Dotace ČPV | B23: Podpora činnosti | C23: Dotace ČPV | E23: Dotace Sázava (Jakub) | F23: 42879 | J23: 2000 | K23: =I23-J23 -> -2000 | N23: =N22+I23-J23 -> 116989 | O23: 2017 | P23: y 2017 | V23: =IF(ISBLANK(Q23),"",SUM(Q23:U23)-N23)
A24: =O24&"_"&B24&"_"&C24 -> 2017_Podpora činnosti_Oddílový den | B24: Podpora činnosti | C24: Oddílový den | E24: Dotace (Jakub) | F24: 42886 | J24: 1500 | K24: =I24-J24 -> -1500 | N24: =N23+I24-J24 -> 115489 | O24: 2017 | P24: y 2017 | V24: =IF(ISBLANK(Q24),"",SUM(Q24:U24)-N24)
A25: =O25&"_"&B25&"_"&C25 -> 2017_Podpora činnosti_Oddílový den | B25: Podpora činnosti | C25: Oddílový den | E25: Záloha Jakub | F25: 42886 | K25: =I25-J25 -> 0 | L25: 3000 | N25: =N24+I25-J25 -> 115489 | O25: 2017 | P25: bez vlivu | V25: =IF(ISBLANK(Q25),"",SUM(Q25:U25)-N25)
A26: =O26&"_"&B26&"_"&C26 -> 2017_Běžný provoz_Příspěvky | B26: Běžný provoz | C26: Příspěvky | E26: přeplatek Jakub loď | F26: 42886 | J26: 200 | K26: =I26-J26 -> -200 | N26: =N25+I26-J26 -> 115289 | O26: 2017 | P26: y 2017 | V26: =IF(ISBLANK(Q26),"",SUM(Q26:U26)-N26)
A27: =O27&"_"&B27&"_"&C27 -> 2017_Podpora činnosti_Oddílový den | B27: Podpora činnosti | C27: Oddílový den | E27: Dotace (Evka) | F27: 42892 | J27: 500 | K27: =I27-J27 -> -500 | N27: =N26+I27-J27 -> 114789 | O27: 2017 | P27: y 2017 | V27: =IF(ISBLANK(Q27),"",SUM(Q27:U27)-N27)
A28: =O28&"_"&B28&"_"&C28 -> 2017_Podpora činnosti_Dotace eskymáky | B28: Podpora činnosti | C28: Dotace eskymáky | E28: Podpora eskymáků (Mára) | F28: 42893 | J28: 1000 | K28: =I28-J28 -> -1000 | N28: =N27+I28-J28 -> 113789 | O28: 2017 | P28: y 2017 | V28: =IF(ISBLANK(Q28),"",SUM(Q28:U28)-N28)
A29: =O29&"_"&B29&"_"&C29 -> 2017_Běžný provoz_Údržba vleků | B29: Běžný provoz | C29: Údržba vleků | E29: STK vlek (Mára) | F29: 42893 | J29: =800+30+300 -> 1130 | K29: =I29-J29 -> -1130 | N29: =N28+I29-J29 -> 112659 | O29: 2017 | P29: y 2017 | Q29: =Q$2+20250-8212-7488 -> 68902 | R29: 40502 | S29: 255 | U29: 3000 | V29: =IF(ISBLANK(Q29),"",SUM(Q29:U29)-N29) -> 0 | W29: OK
A30: =O30&"_"&B30&"_"&C30 -> 2017_Běžný provoz_Příspěvky | B30: Běžný provoz | C30: Příspěvky | E30: Příspěvky členů TJ účet (22.3.-7.4. Pilatova) | F30: 42893 | G30: 42850 | I30: 13550 | K30: =I30-J30 -> 13550 | N30: =N29+I30-J30 -> 126209 | O30: 2017 | P30: y 2017 | Q30: 73952 | R30: 40502 | S30: 255 | U30: 3000 | V30: =IF(ISBLANK(Q30),"",SUM(Q30:U30)-N30) -> -8500 | W30: OK | X30: 42893 | Y30: 42850 | Z30: 42893
A31: =O31&"_"&B31&"_"&C31 -> 2017_Podpora činnosti_Oddílový den | B31: Podpora činnosti | C31: Oddílový den | E31: Záloha Jakub zpět | F31: 42900 | K31: =I31-J31 -> 0 | L31: -3000 | N31: =N30+I31-J31 -> 126209 | O31: 2017 | P31: bez vlivu | V31: =IF(ISBLANK(Q31),"",SUM(Q31:U31)-N31)
A32: =O32&"_"&B32&"_"&C32 -> 2017_Běžný provoz_Příspěvky | B32: Běžný provoz | C32: Příspěvky | E32: Elis 2. loď | F32: 42914 | I32: 200 | K32: =I32-J32 -> 200 | N32: =N31+I32-J32 -> 126409 | O32: 2017 | P32: y 2017 | V32: =IF(ISBLANK(Q32),"",SUM(Q32:U32)-N32)
A33: =O33&"_"&B33&"_"&C33 -> 2017_Běžný provoz_Interní nájmy | B33: Běžný provoz | C33: Interní nájmy | E33: Interní nájmy (krakorce, klubovna, sklad) | F33: 42916 | G33: 31.4.2017 | J33: 8212 | K33: =I33-J33 -> -8212 | N33: =N32+I33-J33 -> 118197 | O33: 2017 | P33: y 2017 | V33: =IF(ISBLANK(Q33),"",SUM(Q33:U33)-N33)
A34: =O34&"_"&B34&"_"&C34 -> 2017_Běžný provoz_Interní nájmy | B34: Běžný provoz | C34: Interní nájmy | E34: Interní nájmy (tělocvična) | F34: 42916 | G34: 31.4.2017 | J34: 7488 | K34: =I34-J34 -> -7488 | N34: =N33+I34-J34 -> 110709 | O34: 2017 | P34: y 2017 | Q34: 66952 | R34: 43502 | S34: 255 | T34: 0 | U34: 0 | V34: =IF(ISBLANK(Q34),"",SUM(Q34:U34)-N34) -> 0 | W34: OK | X34: 42930 | Y34: 42928 | Z34: 42930
A35: =O35&"_"&B35&"_"&C35 -> 2017_Podpora činnosti_Dotace záchrana | B35: Podpora činnosti | C35: Dotace záchrana | E35: Dotace záchrana Roudnice | F35: 42930 | J35: 1500 | K35: =I35-J35 -> -1500 | N35: =N34+I35-J35 -> 109209 | O35: 2017 | P35: y 2017 | V35: =IF(ISBLANK(Q35),"",SUM(Q35:U35)-N35)
A36: =O36&"_"&B36&"_"&C36 -> 2017_Běžný provoz_Oddílová soutěž | B36: Běžný provoz | C36: Oddílová soutěž | E36: Bára Kostková 3. místo | F36: 42933 | J36: 800 | K36: =I36-J36 -> -800 | N36: =N35+I36-J36 -> 108409 | O36: 2017 | P36: y 2017 | Q36: 66952 | R36: 41202 | S36: 255 | T36: 0 | U36: 0 | V36: =IF(ISBLANK(Q36),"",SUM(Q36:U36)-N36) -> 0 | W36: OK | X36: 42931 | Y36: 42928 | Z36: 42933
A37: =O37&"_"&B37&"_"&C37 -> 2017_Hamerák-akce_Hamerák materiál | B37: Hamerák-akce | C37: Hamerák materiál | E37: Jáchym K - barvy na brigádě | F37: 42940 | J37: 1730 | K37: =I37-J37 -> -1730 | N37: =N36+I37-J37 -> 106679 | O37: 2017 | P37: bez vlivu | V37: =IF(ISBLANK(Q37),"",SUM(Q37:U37)-N37)
A38: =O38&"_"&B38&"_"&C38 -> 2017_Hamerák-akce_Hamerák materiál | B38: Hamerák-akce | C38: Hamerák materiál | E38: Jáchym K - spojovací, karbolka, tmel | F38: 42943 | J38: 2860 | K38: =I38-J38 -> -2860 | N38: =N37+I38-J38 -> 103819 | O38: 2017 | P38: bez vlivu | V38: =IF(ISBLANK(Q38),"",SUM(Q38:U38)-N38)
A39: =O39&"_"&B39&"_"&C39 -> 2017_Běžný provoz_Interní nájmy | B39: Běžný provoz | C39: Interní nájmy | E39: Interní nájmy (krakorce, klubovna, sklad) | F39: 42947 | G39: 42947 | J39: 8212 | K39: =I39-J39 -> -8212 | N39: =N38+I39-J39 -> 95607 | O39: 2017 | P39: y 2017 | V39: =IF(ISBLANK(Q39),"",SUM(Q39:U39)-N39)
A40: =O40&"_"&B40&"_"&C40 -> 2017_Běžný provoz_Interní nájmy | B40: Běžný provoz | C40: Interní nájmy | E40: Interní nájmy (tělocvična) | F40: 42947 | G40: 42947 | J40: 7488 | K40: =I40-J40 -> -7488 | N40: =N39+I40-J40 -> 88119 | O40: 2017 | P40: y 2017 | V40: =IF(ISBLANK(Q40),"",SUM(Q40:U40)-N40)
...

Sheet Rozpočet 2026
A1: =CONCAT("Rozpočet OVT ",$F$1) -> Rozpočet OVT 2026 | B1: Plán | C1: Plnění | D1: Rozdíl | F1: 2026
A2: =CONCAT("Převod z roku ",$F$1-1) -> Převod z roku 2025 | B2: 108166 | C2: automaticky z průběžného stavu
F3: Údaje pro automatické doplnění sloupce "Plnění" z listu "Rozpočet - průběžný stav"
A4: Kapitola běžný provoz | B4: =CONCAT("Plán ",$F$1) -> Plán 2026 | C4: =CONCAT("Plnění ",$F$1) -> Plnění 2026 | D4: Rozdíl | F4: Rok | G4: Skupina | H4: Kategorie | I4: Klíč
A5: Příjmy | D5: rozdíl
A6: Příspěvky | B6: 65000 | C6: =SUMIFS('Rozpočet - průběžný stav'!K:K,'Rozpočet - průběžný stav'!A:A,I6) -> 0 | D6: =C6-B6 -> -65000 | F6: =$F$1 -> 2026 | G6: Běžný provoz | H6: =A6 -> Příspěvky | I6: =F6&"_"&G6&"_"&H6 -> 2026_Běžný provoz_Příspěvky
A7: Přeúčtování TOM | B7: 14305 | C7: =SUMIFS('Rozpočet - průběžný stav'!K:K,'Rozpočet - průběžný stav'!A:A,I7) -> 0 | D7: =C7-B7 -> -14305 | F7: =$F$1 -> 2026 | G7: Běžný provoz | H7: =A7 -> Přeúčtování TOM | I7: =F7&"_"&G7&"_"&H7 -> 2026_Běžný provoz_Přeúčtování TOM | K7: Oddílová soutěž
A8: Příjem půjčení vleků | B8: 5000 | C8: =SUMIFS('Rozpočet - průběžný stav'!K:K,'Rozpočet - průběžný stav'!A:A,I8) -> 0 | D8: =C8-B8 -> -5000 | F8: =$F$1 -> 2026 | G8: Běžný provoz | H8: =A8 -> Příjem půjčení vleků | I8: =F8&"_"&G8&"_"&H8 -> 2026_Běžný provoz_Příjem půjčení vleků
A9: Ostatní | B9: 2500 | C9: =SUMIFS('Rozpočet - průběžný stav'!K:K,'Rozpočet - průběžný stav'!A:A,I9) -> 0 | D9: =C9-B9 -> -2500 | F9: =$F$1 -> 2026 | G9: Běžný provoz | H9: =A9 -> Ostatní | I9: =F9&"_"&G9&"_"&H9 -> 2026_Běžný provoz_Ostatní
A10: Příjmy běžný provoz celkem | B10: =SUM(B6:B9) -> 86805 | C10: =SUM(C6:C9) -> 0 | D10: =C10-B10 -> -86805 | K10: Nejlepší ženy: | L10: doplnit
A12: Výdaje | K12: Katka Měrková | L12: 1000
A13: Interní nájmy | B13: 90000 | C13: =-SUMIFS('Rozpočet - průběžný stav'!K:K,'Rozpočet - průběžný stav'!A:A,I13) -> 0 | D13: =C13-B13 -> -90000 | F13: =$F$1 -> 2026 | G13: Běžný provoz | H13: =A13 -> Interní nájmy | I13: =F13&"_"&G13&"_"&H13 -> 2026_Běžný provoz_Interní nájmy | K13: Kateřina Šedivá | L13: 800
A14: Interní nájmy ostatní | C14: =-SUMIFS('Rozpočet - průběžný stav'!K:K,'Rozpočet - průběžný stav'!A:A,I14) -> 0 | D14: =C14-B14 -> 0 | F14: =$F$1 -> 2026 | G14: Běžný provoz | H14: =A14 -> Interní nájmy ostatní | I14: =F14&"_"&G14&"_"&H14 -> 2026_Běžný provoz_Interní nájmy ostatní | K14: Bára Bernardová | L14: 600
A15: Příspěvky ČSK | B15: 1300 | C15: =-SUMIFS('Rozpočet - průběžný stav'!K:K,'Rozpočet - průběžný stav'!A:A,I15) -> 0 | D15: =C15-B15 -> -1300 | E15: více je TOM, viz přeúčtování TOM | F15: =$F$1 -> 2026 | G15: Běžný provoz | H15: =A15 -> Příspěvky ČSK | I15: =F15&"_"&G15&"_"&H15 -> 2026_Běžný provoz_Příspěvky ČSK | K15: Nejlepší muži: | L15: doplnit
A16: Příspěvky TJ Bohemians | B16: 4800 | C16: =-SUMIFS('Rozpočet - průběžný stav'!K:K,'Rozpočet - průběžný stav'!A:A,I16) -> 0 | D16: =C16-B16 -> -4800 | F16: =$F$1 -> 2026 | G16: Běžný provoz | H16: Příspěvky TJ Bohemians | I16: =F16&"_"&G16&"_"&H16 -> 2026_Běžný provoz_Příspěvky TJ Bohemians
A17: Údržba vleků | B17: 6000 | C17: =-SUMIFS('Rozpočet - průběžný stav'!K:K,'Rozpočet - průběžný stav'!A:A,I17) -> 0 | D17: =C17-B17 -> -6000 | E17: náklady na vleky jsou napůl s TOM, viz přeúčtování TOM | F17: =$F$1 -> 2026 | G17: Běžný provoz | H17: =A17 -> Údržba vleků | I17: =F17&"_"&G17&"_"&H17 -> 2026_Běžný provoz_Údržba vleků | K17: Jiří Klíma | L17: 1000
A18: Materiál | B18: 2000 | C18: =-SUMIFS('Rozpočet - průběžný stav'!K:K,'Rozpočet - průběžný stav'!A:A,I18) -> 0 | D18: =C18-B18 -> -2000 | F18: =$F$1 -> 2026 | G18: Běžný provoz | H18: =A18 -> Materiál | I18: =F18&"_"&G18&"_"&H18 -> 2026_Běžný provoz_Materiál | K18: Jáchym Kopřiva | L18: 800
A19: Výdaje ostatní | B19: 600 | C19: =-SUMIFS('Rozpočet - průběžný stav'!K:K,'Rozpočet - průběžný stav'!A:A,I19) -> 0 | D19: =C19-B19 -> -600 | E19: webhosting | F19: =$F$1 -> 2026 | G19: Běžný provoz | H19: =A19 -> Výdaje ostatní | I19: =F19&"_"&G19&"_"&H19 -> 2026_Běžný provoz_Výdaje ostatní | K19: Martin Kříž | L19: 600
A20: Výdaje běžný provoz celkem | B20: =SUM(B12:B19) -> 104700 | C20: =SUM(C12:C19) -> 0 | D20: =C20-B20 -> -104700
A22: Bilance běžný provoz | B22: =B10-B20 -> -17895 | C22: =C10-C20 -> 0 | D22: =C22-B22 -> 17895
A24: Kapitola podpora činnosti | B24: =CONCAT("Plán ",$F$1) -> Plán 2026 | C24: =CONCAT("Plnění ",$F$1) -> Plnění 2026 | D24: Rozdíl | F24: Rok | G24: Skupina | H24: Kategorie | I24: Klíč
A25: Příjmy
A26: Příjem Hamerák | B26: 0 | C26: =SUMIFS('Rozpočet - průběžný stav'!K:K,'Rozpočet - průběžný stav'!A:A,I26) -> 0 | F26: =$F$1 -> 2026 | G26: Hamerák-akce | H26: Hamerák finance | I26: =F26&"_"&G26&"_"&H26 -> 2026_Hamerák-akce_Hamerák finance
A27: Příjmy dotace a dary | B27: 0 | C27: =SUMIFS('Rozpočet - průběžný stav'!K:K,'Rozpočet - průběžný stav'!A:A,I27) -> 0 | D27: =C27-B27 -> 0 | F27: =$F$1 -> 2026 | G27: Podpora činnosti | H27: =A27 -> Příjmy dotace a dary | I27: =F27&"_"&G27&"_"&H27 -> 2026_Podpora činnosti_Příjmy dotace a dary
A28: Příjmy podpora činnosti celkem | B28: =SUM(B25:B27) -> 0 | C28: =SUM(C25:C27) -> 0 | D28: =C28-B28 -> 0
A30: Výdaje
A31: Podpora akcí | B31: 30000 | C31: =-SUMIFS('Rozpočet - průběžný stav'!K:K,'Rozpočet - průběžný stav'!A:A,I31) -> 0 | D31: =C31-B31 -> -30000 | F31: =$F$1 -> 2026 | G31: Podpora činnosti | H31: =A31 -> Podpora akcí | I31: =F31&"_"&G31&"_"&H31 -> 2026_Podpora činnosti_Podpora akcí
A32: Hamerák příprava výdaje | B32: 5000 | C32: =-SUMIFS('Rozpočet - průběžný stav'!K:K,'Rozpočet - průběžný stav'!A:A,I32) -> 0 | D32: =C32-B32 -> -5000 | F32: =$F$1 -> 2026 | G32: Hamerák-akce | H32: Náklady příprava | I32: =F32&"_"&G32&"_"&H32 -> 2026_Hamerák-akce_Náklady příprava | K32: Výsledek Hamerák: | L32: =C26-#REF!-C32 -> #REF!
A33: Výdaje podpora činnosti celkem | B33: =sum(B31:B32) -> 35000 | C33: =sum(C31:C32) -> 0 | D33: =C33-B33 -> -35000
A35: Bilance podpora činnosti | B35: =B28-B33 -> -35000 | C35: =C28-C33 -> 0 | D35: =C35-B35 -> 35000
A37: Bilance Hamerák | B37: 0 | C37: =C26-C32 -> 0
C38: =-SUMIFS('Rozpočet - průběžný stav'!K:K,'Rozpočet - průběžný stav'!A:A,I38) -> 0 | F38: =$F$1 -> 2026 | G38: Převody | H38: Převod z 2019 | I38: =F38&"_"&G38&"_"&H38 -> 2026_Převody_Převod z 2019
C39: =-SUMIFS('Rozpočet - průběžný stav'!K:K,'Rozpočet - průběžný stav'!A:A,I39) -> 0 | F39: =$F$1 -> 2026 | G39: Převody | H39: převod | I39: =F39&"_"&G39&"_"&H39 -> 2026_Převody_převod
C40: =-SUMIFS('Rozpočet - průběžný stav'!K:K,'Rozpočet - průběžný stav'!A:A,I40) -> 0 | F40: =$F$1 -> 2026 | G40: Převody | H40: stav | I40: =F40&"_"&G40&"_"&H40 -> 2026_Převody_stav
A43: Rekapitulace | B43: =CONCAT("Plán ",$F$1) -> Plán 2026 | C43: =CONCAT("Plnění ",$F$1) -> Plnění 2026 | D43: Rozdíl
A44: Převod z 2024 | B44: =B2 -> 108166 | C44: =B44 -> 108166
A45: Příjmy běžný provoz | B45: =B10 -> 86805 | C45: =C10 -> 0
A46: Příjmy podpora činnosti | B46: =B28 -> 0 | C46: =C28 -> 0
A47: Celkem příjmy 2025 | B47: =B45+B46 -> 86805 | C47: =C45+C46 -> 0
A48: Výdaje běžný provoz | B48: =-B20 -> -104700 | C48: =-C20 -> 0
...

Sheet Rozpočet 2025
A1: =CONCAT("Rozpočet OVT ",$F$1) -> Rozpočet OVT 2025 | B1: Plán | C1: Plnění | D1: Rozdíl | F1: 2025
A2: =CONCAT("Převod z roku ",$F$1-1) -> Převod z roku 2024 | B2: 158324 | C2: automaticky z průběžného stavu
F3: Údaje pro automatické doplnění sloupce "Plnění" z listu "Rozpočet - průběžný stav"
A4: Kapitola běžný provoz | B4: =CONCAT("Plán ",$F$1) -> Plán 2025 | C4: =CONCAT("Plnění ",$F$1) -> Plnění 2025 | D4: Rozdíl | F4: Rok | G4: Skupina | H4: Kategorie | I4: Klíč
A5: Příjmy | D5: rozdíl
A6: Příspěvky | B6: 65000 | C6: =SUMIFS('Rozpočet - průběžný stav'!K:K,'Rozpočet - průběžný stav'!A:A,I6) -> 56600 | D6: =C6-B6 -> -8400 | F6: =$F$1 -> 2025 | G6: Běžný provoz | H6: =A6 -> Příspěvky | I6: =F6&"_"&G6&"_"&H6 -> 2025_Běžný provoz_Příspěvky
A7: Přeúčtování TOM | B7: 14305 | C7: =SUMIFS('Rozpočet - průběžný stav'!K:K,'Rozpočet - průběžný stav'!A:A,I7) -> 0 | D7: =C7-B7 -> -14305 | F7: =$F$1 -> 2025 | G7: Běžný provoz | H7: =A7 -> Přeúčtování TOM | I7: =F7&"_"&G7&"_"&H7 -> 2025_Běžný provoz_Přeúčtování TOM | K7: Oddílová soutěž
A8: Příjem půjčení vleků | B8: 5000 | C8: =SUMIFS('Rozpočet - průběžný stav'!K:K,'Rozpočet - průběžný stav'!A:A,I8) -> 0 | D8: =C8-B8 -> -5000 | F8: =$F$1 -> 2025 | G8: Běžný provoz | H8: =A8 -> Příjem půjčení vleků | I8: =F8&"_"&G8&"_"&H8 -> 2025_Běžný provoz_Příjem půjčení vleků
A9: Ostatní | B9: 2500 | C9: =SUMIFS('Rozpočet - průběžný stav'!K:K,'Rozpočet - průběžný stav'!A:A,I9) -> 2755.74 | D9: =C9-B9 -> 255.74 | F9: =$F$1 -> 2025 | G9: Běžný provoz | H9: =A9 -> Ostatní | I9: =F9&"_"&G9&"_"&H9 -> 2025_Běžný provoz_Ostatní
A10: Příjmy běžný provoz celkem | B10: =SUM(B6:B9) -> 86805 | C10: =SUM(C6:C9) -> 59355.74 | D10: =C10-B10 -> -27449.26 | K10: Nejlepší ženy: | L10: doplnit
A12: Výdaje | K12: Katka Měrková | L12: 1000
A13: Interní nájmy | B13: 90000 | C13: =-SUMIFS('Rozpočet - průběžný stav'!K:K,'Rozpočet - průběžný stav'!A:A,I13) -> 84914 | D13: =C13-B13 -> -5086 | F13: =$F$1 -> 2025 | G13: Běžný provoz | H13: =A13 -> Interní nájmy | I13: =F13&"_"&G13&"_"&H13 -> 2025_Běžný provoz_Interní nájmy | K13: Kateřina Šedivá | L13: 800
A14: Interní nájmy ostatní | C14: =-SUMIFS('Rozpočet - průběžný stav'!K:K,'Rozpočet - průběžný stav'!A:A,I14) -> 0 | D14: =C14-B14 -> 0 | F14: =$F$1 -> 2025 | G14: Běžný provoz | H14: =A14 -> Interní nájmy ostatní | I14: =F14&"_"&G14&"_"&H14 -> 2025_Běžný provoz_Interní nájmy ostatní | K14: Bára Bernardová | L14: 600
A15: Příspěvky ČSK | B15: 1300 | C15: =-SUMIFS('Rozpočet - průběžný stav'!K:K,'Rozpočet - průběžný stav'!A:A,I15) -> 1840 | D15: =C15-B15 -> 540 | E15: více je TOM, viz přeúčtování TOM | F15: =$F$1 -> 2025 | G15: Běžný provoz | H15: =A15 -> Příspěvky ČSK | I15: =F15&"_"&G15&"_"&H15 -> 2025_Běžný provoz_Příspěvky ČSK | K15: Nejlepší muži: | L15: doplnit
A16: Příspěvky TJ Bohemians | C16: =-SUMIFS('Rozpočet - průběžný stav'!K:K,'Rozpočet - průběžný stav'!A:A,I16) -> 4800 | D16: =C16-B16 -> 4800 | F16: =$F$1 -> 2025 | G16: Běžný provoz | H16: Příspěvky TJ Bohemians | I16: =F16&"_"&G16&"_"&H16 -> 2025_Běžný provoz_Příspěvky TJ Bohemians
A17: Údržba vleků | B17: 6000 | C17: =-SUMIFS('Rozpočet - průběžný stav'!K:K,'Rozpočet - průběžný stav'!A:A,I17) -> 0 | D17: =C17-B17 -> -6000 | E17: náklady na vleky jsou napůl s TOM, viz přeúčtování TOM | F17: =$F$1 -> 2025 | G17: Běžný provoz | H17: =A17 -> Údržba vleků | I17: =F17&"_"&G17&"_"&H17 -> 2025_Běžný provoz_Údržba vleků | K17: Jiří Klíma | L17: 1000
A18: Materiál | B18: 0 | C18: =-SUMIFS('Rozpočet - průběžný stav'!K:K,'Rozpočet - průběžný stav'!A:A,I18) -> 2940 | D18: =C18-B18 -> 2940 | F18: =$F$1 -> 2025 | G18: Běžný provoz | H18: =A18 -> Materiál | I18: =F18&"_"&G18&"_"&H18 -> 2025_Běžný provoz_Materiál | K18: Jáchym Kopřiva | L18: 800
A19: Výdaje ostatní | B19: 600 | C19: =-SUMIFS('Rozpočet - průběžný stav'!K:K,'Rozpočet - průběžný stav'!A:A,I19) -> 0 | D19: =C19-B19 -> -600 | E19: webhosting | F19: =$F$1 -> 2025 | G19: Běžný provoz | H19: =A19 -> Výdaje ostatní | I19: =F19&"_"&G19&"_"&H19 -> 2025_Běžný provoz_Výdaje ostatní | K19: Martin Kříž | L19: 600
A20: Výdaje běžný provoz celkem | B20: =SUM(B12:B19) -> 97900 | C20: =SUM(C12:C19) -> 94494 | D20: =C20-B20 -> -3406
A22: Bilance běžný provoz | B22: =B10-B20 -> -11095 | C22: =C10-C20 -> -35138.26 | D22: =C22-B22 -> -24043.26
A24: Kapitola podpora činnosti | B24: =CONCAT("Plán ",$F$1) -> Plán 2025 | C24: =CONCAT("Plnění ",$F$1) -> Plnění 2025 | D24: Rozdíl | F24: Rok | G24: Skupina | H24: Kategorie | I24: Klíč
A25: Příjmy
A26: Příjem Hamerák | B26: 0 | C26: =SUMIFS('Rozpočet - průběžný stav'!K:K,'Rozpočet - průběžný stav'!A:A,I26) -> 31000 | F26: =$F$1 -> 2025 | G26: Hamerák-akce | H26: Hamerák finance | I26: =F26&"_"&G26&"_"&H26 -> 2025_Hamerák-akce_Hamerák finance
A27: Příjmy dotace a dary | B27: 0 | C27: =SUMIFS('Rozpočet - průběžný stav'!K:K,'Rozpočet - průběžný stav'!A:A,I27) -> 0 | D27: =C27-B27 -> 0 | F27: =$F$1 -> 2025 | G27: Podpora činnosti | H27: =A27 -> Příjmy dotace a dary | I27: =F27&"_"&G27&"_"&H27 -> 2025_Podpora činnosti_Příjmy dotace a dary
A28: Příjmy podpora činnosti celkem | B28: =SUM(B25:B27) -> 0 | C28: =SUM(C25:C27) -> 31000 | D28: =C28-B28 -> 31000
A30: Výdaje
A31: Podpora akcí | B31: 30000 | C31: =-SUMIFS('Rozpočet - průběžný stav'!K:K,'Rozpočet - průběžný stav'!A:A,I31) -> 15680.2 | D31: =C31-B31 -> -14319.8 | F31: =$F$1 -> 2025 | G31: Podpora činnosti | H31: =A31 -> Podpora akcí | I31: =F31&"_"&G31&"_"&H31 -> 2025_Podpora činnosti_Podpora akcí
A32: Hamerák příprava výdaje | B32: 5000 | C32: =-SUMIFS('Rozpočet - průběžný stav'!K:K,'Rozpočet - průběžný stav'!A:A,I32) -> 30340 | D32: =C32-B32 -> 25340 | F32: =$F$1 -> 2025 | G32: Hamerák-akce | H32: Náklady příprava | I32: =F32&"_"&G32&"_"&H32 -> 2025_Hamerák-akce_Náklady příprava | K32: Výsledek Hamerák: | L32: =C26-#REF!-C32 -> #REF!
A33: Výdaje podpora činnosti celkem | B33: =sum(B31:B32) -> 35000 | C33: =sum(C31:C32) -> 46020.2 | D33: =C33-B33 -> 11020.2
A35: Bilance podpora činnosti | B35: =B28-B33 -> -35000 | C35: =C28-C33 -> -15020.2 | D35: =C35-B35 -> 19979.8
A37: Bilance Hamerák | B37: 0 | C37: =C26-C32 -> 660
C38: =-SUMIFS('Rozpočet - průběžný stav'!K:K,'Rozpočet - průběžný stav'!A:A,I38) -> 0 | F38: =$F$1 -> 2025 | G38: Převody | H38: Převod z 2019 | I38: =F38&"_"&G38&"_"&H38 -> 2025_Převody_Převod z 2019
C39: =-SUMIFS('Rozpočet - průběžný stav'!K:K,'Rozpočet - průběžný stav'!A:A,I39) -> 0 | F39: =$F$1 -> 2025 | G39: Převody | H39: převod | I39: =F39&"_"&G39&"_"&H39 -> 2025_Převody_převod
C40: =-SUMIFS('Rozpočet - průběžný stav'!K:K,'Rozpočet - průběžný stav'!A:A,I40) -> 0 | F40: =$F$1 -> 2025 | G40: Převody | H40: stav | I40: =F40&"_"&G40&"_"&H40 -> 2025_Převody_stav
A43: Rekapitulace | B43: =CONCAT("Plán ",$F$1) -> Plán 2025 | C43: =CONCAT("Plnění ",$F$1) -> Plnění 2025 | D43: Rozdíl
A44: Převod z 2024 | B44: =B2 -> 158324 | C44: =B44 -> 158324
A45: Příjmy běžný provoz | B45: =B10 -> 86805 | C45: =C10 -> 59355.74
A46: Příjmy podpora činnosti | B46: =B28 -> 0 | C46: =C28 -> 31000
A47: Celkem příjmy 2025 | B47: =B45+B46 -> 86805 | C47: =C45+C46 -> 90355.74
A48: Výdaje běžný provoz | B48: =-B20 -> -97900 | C48: =-C20 -> -94494
...

Sheet Rozpočet 2024
A1: =CONCAT("Rozpočet OVT ",$F$1) -> Rozpočet OVT 2024 | B1: Plán | C1: Plnění | D1: Rozdíl | F1: 2024
A2: =CONCAT("Převod z roku ",$F$1-1) -> Převod z roku 2023 | B2: 181921 | C2: automaticky z průběžného stavu
F3: Údaje pro automatické doplnění sloupce "Plnění" z listu "Rozpočet - průběžný stav"
A4: Kapitola běžný provoz | B4: =CONCAT("Plán ",$F$1) -> Plán 2024 | C4: =CONCAT("Plnění ",$F$1) -> Plnění 2024 | D4: Rozdíl | F4: Rok | G4: Skupina | H4: Kategorie | I4: Klíč
A5: Příjmy | D5: rozdíl
A6: Příspěvky | B6: 65000 | C6: =SUMIFS('Rozpočet - průběžný stav'!K:K,'Rozpočet - průběžný stav'!A:A,I6) -> 68400 | D6: =C6-B6 -> 3400 | F6: =$F$1 -> 2024 | G6: Běžný provoz | H6: =A6 -> Příspěvky | I6: =F6&"_"&G6&"_"&H6 -> 2024_Běžný provoz_Příspěvky
A7: Přeúčtování TOM | B7: 14305 | C7: =SUMIFS('Rozpočet - průběžný stav'!K:K,'Rozpočet - průběžný stav'!A:A,I7) -> 0 | F7: =$F$1 -> 2024 | G7: Běžný provoz | H7: =A7 -> Přeúčtování TOM | I7: =F7&"_"&G7&"_"&H7 -> 2024_Běžný provoz_Přeúčtování TOM | K7: Oddílová soutěž
A8: Příjem půjčení vleků | B8: 5000 | C8: =SUMIFS('Rozpočet - průběžný stav'!K:K,'Rozpočet - průběžný stav'!A:A,I8) -> 0 | D8: =C8-B8 -> -5000 | F8: =$F$1 -> 2024 | G8: Běžný provoz | H8: =A8 -> Příjem půjčení vleků | I8: =F8&"_"&G8&"_"&H8 -> 2024_Běžný provoz_Příjem půjčení vleků
A9: Ostatní | C9: =SUMIFS('Rozpočet - průběžný stav'!K:K,'Rozpočet - průběžný stav'!A:A,I9) -> 2954.46 | F9: =$F$1 -> 2024 | G9: Běžný provoz | H9: =A9 -> Ostatní | I9: =F9&"_"&G9&"_"&H9 -> 2024_Běžný provoz_Ostatní
A10: Příjmy běžný provoz celkem | B10: =SUM(B6:B9) -> 84305 | C10: =SUM(C6:C9) -> 71354.46 | D10: =C10-B10 -> -12950.54 | K10: Nejlepší ženy: | L10: doplnit
A12: Výdaje | L12: 1000
A13: Interní nájmy | B13: 85484 | C13: =-SUMIFS('Rozpočet - průběžný stav'!K:K,'Rozpočet - průběžný stav'!A:A,I13) -> 92704 | D13: =C13-B13 -> 7220 | F13: =$F$1 -> 2024 | G13: Běžný provoz | H13: =A13 -> Interní nájmy | I13: =F13&"_"&G13&"_"&H13 -> 2024_Běžný provoz_Interní nájmy | L13: 800
A14: Interní nájmy ostatní | C14: =-SUMIFS('Rozpočet - průběžný stav'!K:K,'Rozpočet - průběžný stav'!A:A,I14) -> 0 | D14: =C14-B14 -> 0 | F14: =$F$1 -> 2024 | G14: Běžný provoz | H14: =A14 -> Interní nájmy ostatní | I14: =F14&"_"&G14&"_"&H14 -> 2024_Běžný provoz_Interní nájmy ostatní | L14: 600
A15: Příspěvky ČSK | B15: 1300 | C15: =-SUMIFS('Rozpočet - průběžný stav'!K:K,'Rozpočet - průběžný stav'!A:A,I15) -> 1270 | D15: =C15-B15 -> -30 | E15: více je TOM, viz přeúčtování TOM | F15: =$F$1 -> 2024 | G15: Běžný provoz | H15: =A15 -> Příspěvky ČSK | I15: =F15&"_"&G15&"_"&H15 -> 2024_Běžný provoz_Příspěvky ČSK | K15: Nejlepší muži: | L15: doplnit
A16: Údržba vleků | B16: 5000 | C16: =-SUMIFS('Rozpočet - průběžný stav'!K:K,'Rozpočet - průběžný stav'!A:A,I16) -> 8481 | D16: =C16-B16 -> 3481 | E16: náklady na vleky jsou napůl s TOM, viz přeúčtování TOM | F16: =$F$1 -> 2024 | G16: Běžný provoz | H16: =A16 -> Údržba vleků | I16: =F16&"_"&G16&"_"&H16 -> 2024_Běžný provoz_Údržba vleků | L16: 1000
A17: Materiál | B17: 1000 | C17: =-SUMIFS('Rozpočet - průběžný stav'!K:K,'Rozpočet - průběžný stav'!A:A,I17) -> 0 | D17: =C17-B17 -> -1000 | F17: =$F$1 -> 2024 | G17: Běžný provoz | H17: =A17 -> Materiál | I17: =F17&"_"&G17&"_"&H17 -> 2024_Běžný provoz_Materiál | L17: 800
A18: Výdaje ostatní | C18: =-SUMIFS('Rozpočet - průběžný stav'!K:K,'Rozpočet - průběžný stav'!A:A,I18) -> 3555 | D18: =C18-B18 -> 3555 | F18: =$F$1 -> 2024 | G18: Běžný provoz | H18: =A18 -> Výdaje ostatní | I18: =F18&"_"&G18&"_"&H18 -> 2024_Běžný provoz_Výdaje ostatní | L18: 600
A19: Výdaje běžný provoz celkem | B19: =SUM(B12:B18) -> 92784 | C19: =SUM(C12:C18) -> 106010 | D19: =C19-B19 -> 13226
A21: Bilance běžný provoz | B21: =B10-B19 -> -8479 | C21: =C10-C19 -> -34655.54 | D21: =C21-B21 -> -26176.54
A23: Kapitola podpora činnosti | B23: =CONCAT("Plán ",$F$1) -> Plán 2024 | C23: =CONCAT("Plnění ",$F$1) -> Plnění 2024 | D23: Rozdíl | F23: Rok | G23: Skupina | H23: Kategorie | I23: Klíč
A24: Příjmy
A25: Příjem Hamerák | B25: 0 | C25: =SUMIFS('Rozpočet - průběžný stav'!K:K,'Rozpočet - průběžný stav'!A:A,I25) -> 27578 | D25: =C25-B25 -> 27578 | F25: =$F$1 -> 2024 | G25: Hamerák-akce | H25: Hamerák finance | I25: =F25&"_"&G25&"_"&H25 -> 2024_Hamerák-akce_Hamerák finance
A26: Příjmy dotace a dary | B26: 2000 | C26: =SUMIFS('Rozpočet - průběžný stav'!K:K,'Rozpočet - průběžný stav'!A:A,I26) -> 0 | D26: =C26-B26 -> -2000 | F26: =$F$1 -> 2024 | G26: Podpora činnosti | H26: =A26 -> Příjmy dotace a dary | I26: =F26&"_"&G26&"_"&H26 -> 2024_Podpora činnosti_Příjmy dotace a dary
A27: Příjmy podpora činnosti celkem | B27: =SUM(B24:B26) -> 2000 | C27: =SUM(C24:C26) -> 27578 | D27: =C27-B27 -> 25578
A29: Výdaje
A30: Podpora akcí | B30: 30000 | C30: =-SUMIFS('Rozpočet - průběžný stav'!K:K,'Rozpočet - průběžný stav'!A:A,I30) -> 15119.22 | D30: =C30-B30 -> -14880.78 | F30: =$F$1 -> 2024 | G30: Podpora činnosti | H30: =A30 -> Podpora akcí | I30: =F30&"_"&G30&"_"&H30 -> 2024_Podpora činnosti_Podpora akcí
A31: Hamerák příprava výdaje | B31: 0 | C31: =-SUMIFS('Rozpočet - průběžný stav'!K:K,'Rozpočet - průběžný stav'!A:A,I31) -> 1400 | D31: =C31-B31 -> 1400 | F31: =$F$1 -> 2024 | G31: Hamerák-akce | H31: Náklady příprava | I31: =F31&"_"&G31&"_"&H31 -> 2024_Hamerák-akce_Náklady příprava | K31: Výsledek Hamerák: | L31: =C25-#REF!-C31 -> #REF!
A32: Výdaje podpora činnosti celkem | B32: =sum(B30:B31) -> 30000 | C32: =sum(C30:C31) -> 16519.22 | D32: =C32-B32 -> -13480.78
A34: Bilance podpora činnosti | B34: =B27-B32 -> -28000 | C34: =C27-C32 -> 11058.78 | D34: =C34-B34 -> 39058.78
A36: Bilance Hamerák | B36: 0 | C36: =C25-C31 -> 26178
C37: =-SUMIFS('Rozpočet - průběžný stav'!K:K,'Rozpočet - průběžný stav'!A:A,I37) -> 0 | F37: =$F$1 -> 2024 | G37: Převody | H37: Převod z 2019 | I37: =F37&"_"&G37&"_"&H37 -> 2024_Převody_Převod z 2019
C38: =-SUMIFS('Rozpočet - průběžný stav'!K:K,'Rozpočet - průběžný stav'!A:A,I38) -> 0 | F38: =$F$1 -> 2024 | G38: Převody | H38: převod | I38: =F38&"_"&G38&"_"&H38 -> 2024_Převody_převod
C39: =-SUMIFS('Rozpočet - průběžný stav'!K:K,'Rozpočet - průběžný stav'!A:A,I39) -> 0 | F39: =$F$1 -> 2024 | G39: Převody | H39: stav | I39: =F39&"_"&G39&"_"&H39 -> 2024_Převody_stav
A42: Rekapitulace | B42: =CONCAT("Plán ",$F$1) -> Plán 2024 | C42: =CONCAT("Plnění ",$F$1) -> Plnění 2024 | D42: Rozdíl
A43: Převod z 20223 | B43: =B2 -> 181921 | C43: =B43 -> 181921
A44: Příjmy běžný provoz | B44: =B10 -> 84305 | C44: =C10 -> 71354.46 | D44: =C44-B44 -> -12950.54
A45: Příjmy podpora činnosti | B45: =B27 -> 2000 | C45: =C27 -> 27578 | D45: =C45-B45 -> 25578
A46: Celkem příjmy 2023 | B46: =B44+B45 -> 86305 | C46: =C44+C45 -> 98932.46 | D46: =C46-B46 -> 12627.46
A47: Výdaje běžný provoz | B47: =-B19 -> -92784 | C47: =-C19 -> -106010 | D47: =C47-B47 -> -13226
A48: Výdaje podpora činnosti | B48: =-B32 -> -30000 | C48: =-C32 -> -16519.22 | D48: =C48-B48 -> 13480.78
...

Sheet Vývoj rozpočtu
A1: Rok | B1: Stav na konci
A2: 2017 | B2: 121759
A3: 2018 | B3: 133443
A4: 2019 | B4: 169424
A5: 2020 | B5: 192476
A6: 2021 | B6: 246189
A7: 2022 | B7: 219956
A8: 2023 | B8: 181921
A9: 2024 | B9: 158324
A10: 2025
A11: 2026
A12: 2027
A13: 2028
A14: 2029

Sheet Rozpočet 2023
A1: Rozpočet OVT 2023 | B1: Plán | C1: Plnění | D1: Rozdíl
A2: Převod z roku 2022 | B2: 219956 | C2: automaticky z průběžného stavu
F3: Údaje pro automatické doplnění sloupce "Plnění" z listu "Rozpočet - průběžný stav"
A4: Kapitola běžný provoz | B4: Plán 2023 | C4: Plnění 2023 | D4: Rozdíl | F4: Rok | G4: Skupina | H4: Kategorie | I4: Klíč
A5: Příjmy | D5: rozdíl
A6: Příspěvky | B6: 53000 | C6: =SUMIFS('Rozpočet - průběžný stav'!K:K,'Rozpočet - průběžný stav'!A:A,I6) -> 66150 | D6: =C6-B6 -> 13150 | F6: 2023 | G6: Běžný provoz | H6: =A6 -> Příspěvky | I6: =F6&"_"&G6&"_"&H6 -> 2023_Běžný provoz_Příspěvky
A7: Přeúčtování TOM | B7: 2117 | C7: =SUMIFS('Rozpočet - průběžný stav'!K:K,'Rozpočet - průběžný stav'!A:A,I7) -> 0 | D7: =C7-B7 -> -2117 | F7: 2023 | G7: Běžný provoz | H7: =A7 -> Přeúčtování TOM | I7: =F7&"_"&G7&"_"&H7 -> 2023_Běžný provoz_Přeúčtování TOM | K7: Oddílová soutěž
A8: Příjem půjčení vleků | B8: 5000 | C8: =SUMIFS('Rozpočet - průběžný stav'!K:K,'Rozpočet - průběžný stav'!A:A,I8) -> 0 | D8: =C8-B8 -> -5000 | F8: 2023 | G8: Běžný provoz | H8: =A8 -> Příjem půjčení vleků | I8: =F8&"_"&G8&"_"&H8 -> 2023_Běžný provoz_Příjem půjčení vleků
A9: Ostatní | C9: =SUMIFS('Rozpočet - průběžný stav'!K:K,'Rozpočet - průběžný stav'!A:A,I9) -> 0 | F9: 2023 | G9: Běžný provoz | H9: =A9 -> Ostatní | I9: =F9&"_"&G9&"_"&H9 -> 2023_Běžný provoz_Ostatní
A10: Příjmy běžný provoz celkem | B10: =SUM(B6:B9) -> 60117 | C10: =SUM(C6:C9) -> 66150 | D10: =C10-B10 -> 6033 | K10: Nejlepší ženy: | L10: doplnit
A12: Výdaje | K12: Katka Měrková | L12: 1000
A13: Interní nájmy | B13: 76000 | C13: =-SUMIFS('Rozpočet - průběžný stav'!K:K,'Rozpočet - průběžný stav'!A:A,I13) -> 85484 | D13: =C13-B13 -> 9484 | F13: 2023 | G13: Běžný provoz | H13: =A13 -> Interní nájmy | I13: =F13&"_"&G13&"_"&H13 -> 2023_Běžný provoz_Interní nájmy | K13: Kateřina Šedivá | L13: 800
A14: Interní nájmy ostatní | C14: =-SUMIFS('Rozpočet - průběžný stav'!K:K,'Rozpočet - průběžný stav'!A:A,I14) -> 0 | D14: =C14-B14 -> 0 | F14: 2023 | G14: Běžný provoz | H14: =A14 -> Interní nájmy ostatní | I14: =F14&"_"&G14&"_"&H14 -> 2023_Běžný provoz_Interní nájmy ostatní | K14: Bára Bernardová | L14: 600
A15: Příspěvky ČSK | B15: 1300 | C15: =-SUMIFS('Rozpočet - průběžný stav'!K:K,'Rozpočet - průběžný stav'!A:A,I15) -> 1370 | D15: =C15-B15 -> 70 | E15: více je TOM, viz přeúčtování TOM | F15: 2023 | G15: Běžný provoz | H15: =A15 -> Příspěvky ČSK | I15: =F15&"_"&G15&"_"&H15 -> 2023_Běžný provoz_Příspěvky ČSK | K15: Nejlepší muži: | L15: doplnit
A16: Údržba vleků | B16: 3000 | C16: =-SUMIFS('Rozpočet - průběžný stav'!K:K,'Rozpočet - průběžný stav'!A:A,I16) -> 16663 | D16: =C16-B16 -> 13663 | E16: náklady na vleky jsou napůl s TOM, viz přeúčtování TOM | F16: 2023 | G16: Běžný provoz | H16: =A16 -> Údržba vleků | I16: =F16&"_"&G16&"_"&H16 -> 2023_Běžný provoz_Údržba vleků | K16: Jiří Klíma | L16: 1000
A17: Materiál | B17: 1000 | C17: =-SUMIFS('Rozpočet - průběžný stav'!K:K,'Rozpočet - průběžný stav'!A:A,I17) -> 0 | D17: =C17-B17 -> -1000 | F17: 2023 | G17: Běžný provoz | H17: =A17 -> Materiál | I17: =F17&"_"&G17&"_"&H17 -> 2023_Běžný provoz_Materiál | K17: Jáchym Kopřiva | L17: 800
A18: Výdaje ostatní | C18: =-SUMIFS('Rozpočet - průběžný stav'!K:K,'Rozpočet - průběžný stav'!A:A,I18) -> 589.27 | D18: =C18-B18 -> 589.27 | E18: webhosting | F18: 2023 | G18: Běžný provoz | H18: =A18 -> Výdaje ostatní | I18: =F18&"_"&G18&"_"&H18 -> 2023_Běžný provoz_Výdaje ostatní | K18: Martin Kříž | L18: 600
A19: Výdaje běžný provoz celkem | B19: =SUM(B12:B18) -> 81300 | C19: =SUM(C12:C18) -> 104106.27 | D19: =C19-B19 -> 22806.27
A21: Bilance běžný provoz | B21: =B10-B19 -> -21183 | C21: =C10-C19 -> -37956.27 | D21: =C21-B21 -> -16773.27
A23: Kapitola podpora činnosti | B23: Plán 2023 | C23: Plnění 2023 | D23: Rozdíl | F23: Rok | G23: Skupina | H23: Kategorie | I23: Klíč
A24: Příjmy
A25: Příjem Hamerák | B25: 0 | C25: =SUMIFS('Rozpočet - průběžný stav'!K:K,'Rozpočet - průběžný stav'!A:A,I25) -> 18631 | F25: 2023 | G25: Hamerák-akce | H25: Hamerák finance | I25: =F25&"_"&G25&"_"&H25 -> 2023_Hamerák-akce_Hamerák finance
A26: Příjmy dotace a dary | B26: 0 | C26: =SUMIFS('Rozpočet - průběžný stav'!K:K,'Rozpočet - průběžný stav'!A:A,I26) -> 3400 | D26: =C26-B26 -> 3400 | F26: 2023 | G26: Podpora činnosti | H26: =A26 -> Příjmy dotace a dary | I26: =F26&"_"&G26&"_"&H26 -> 2023_Podpora činnosti_Příjmy dotace a dary
A27: Příjmy podpora činnosti celkem | B27: =SUM(B24:B26) -> 0 | C27: =SUM(C24:C26) -> 22031 | D27: =C27-B27 -> 22031
A29: Výdaje
A30: Podpora akcí | B30: 30000 | C30: =-SUMIFS('Rozpočet - průběžný stav'!K:K,'Rozpočet - průběžný stav'!A:A,I30) -> 22110 | D30: =C30-B30 -> -7890 | F30: 2023 | G30: Podpora činnosti | H30: =A30 -> Podpora akcí | I30: =F30&"_"&G30&"_"&H30 -> 2023_Podpora činnosti_Podpora akcí
A31: Podpora ČPV | C31: =-SUMIFS('Rozpočet - průběžný stav'!K:K,'Rozpočet - průběžný stav'!A:A,I31) -> 0 | D31: =C31-B31 -> 0 | F31: 2023 | G31: Podpora činnosti | H31: =A31 -> Podpora ČPV | I31: =F31&"_"&G31&"_"&H31 -> 2023_Podpora činnosti_Podpora ČPV
A32: Podpora eskymáků | C32: =-SUMIFS('Rozpočet - průběžný stav'!K:K,'Rozpočet - průběžný stav'!A:A,I32) -> 0 | D32: =C32-B32 -> 0 | F32: 2023 | G32: Podpora činnosti | H32: =A32 -> Podpora eskymáků | I32: =F32&"_"&G32&"_"&H32 -> 2023_Podpora činnosti_Podpora eskymáků
A33: Podpora výcviku záchrany | C33: =-SUMIFS('Rozpočet - průběžný stav'!K:K,'Rozpočet - průběžný stav'!A:A,I33) -> 0 | D33: =C33-B33 -> 0 | F33: 2023 | G33: Podpora činnosti | H33: =A33 -> Podpora výcviku záchrany | I33: =F33&"_"&G33&"_"&H33 -> 2023_Podpora činnosti_Podpora výcviku záchrany
A34: Podpora zahraniční zájezd | C34: =-SUMIFS('Rozpočet - průběžný stav'!K:K,'Rozpočet - průběžný stav'!A:A,I34) -> 0 | D34: =C34-B34 -> 0 | F34: 2023 | G34: Podpora činnosti | H34: =A34 -> Podpora zahraniční zájezd | I34: =F34&"_"&G34&"_"&H34 -> 2023_Podpora činnosti_Podpora zahraniční zájezd
A35: Oddílový den | C35: =-SUMIFS('Rozpočet - průběžný stav'!K:K,'Rozpočet - průběžný stav'!A:A,I35) -> 0 | D35: =C35-B35 -> 0 | F35: 2023 | G35: Podpora činnosti | H35: =A35 -> Oddílový den | I35: =F35&"_"&G35&"_"&H35 -> 2023_Podpora činnosti_Oddílový den
A36: Oddílové vánoce | C36: =-SUMIFS('Rozpočet - průběžný stav'!K:K,'Rozpočet - průběžný stav'!A:A,I36) -> 0 | D36: =C36-B36 -> 0 | F36: 2023 | G36: Podpora činnosti | H36: =A36 -> Oddílové vánoce | I36: =F36&"_"&G36&"_"&H36 -> 2023_Podpora činnosti_Oddílové vánoce
A37: Oddílová soutěž | B37: 0 | C37: =-SUMIFS('Rozpočet - průběžný stav'!K:K,'Rozpočet - průběžný stav'!A:A,I37) -> 0 | D37: =C37-B37 -> 0 | F37: 2023 | G37: Podpora činnosti | H37: =A37 -> Oddílová soutěž | I37: =F37&"_"&G37&"_"&H37 -> 2023_Podpora činnosti_Oddílová soutěž
A38: Materiál | B38: 0 | C38: =-SUMIFS('Rozpočet - průběžný stav'!K:K,'Rozpočet - průběžný stav'!A:A,I38) -> 0 | D38: =C38-B38 -> 0 | F38: 2023 | G38: Podpora činnosti | H38: =A38 -> Materiál | I38: =F38&"_"&G38&"_"&H38 -> 2023_Podpora činnosti_Materiál
A39: Hamerák výbor (večeře) | B39: 0 | C39: =-SUMIFS('Rozpočet - průběžný stav'!K:K,'Rozpočet - průběžný stav'!A:A,I39) -> 0 | D39: =C39-B39 -> 0 | F39: 2023 | G39: Hamerák-akce | H39: Výbor večeře | I39: =F39&"_"&G39&"_"&H39 -> 2023_Hamerák-akce_Výbor večeře
A40: Hamerák ostatní výdaje | B40: 0 | C40: =-SUMIFS('Rozpočet - průběžný stav'!K:K,'Rozpočet - průběžný stav'!A:A,I40) -> 0 | D40: =C40-B40 -> 0 | F40: 2023 | G40: Hamerák-akce | H40: Náklady příprava | I40: =F40&"_"&G40&"_"&H40 -> 2023_Hamerák-akce_Náklady příprava | K40: Výsledek Hamerák: | L40: =C25-C39-C40 -> 18631
A41: Výdaje podpora činnosti celkem | B41: =sum(B30:B40) -> 30000 | C41: =sum(C30:C40) -> 22110 | D41: =C41-B41 -> -7890
A43: Bilance podpora činnosti | B43: =B27-B41 -> -30000 | C43: =C27-C41 -> -79 | D43: =C43-B43 -> 29921
A45: Bilance Hamerák | B45: 0 | C45: =C25-C39-C40 -> 18631
C46: =-SUMIFS('Rozpočet - průběžný stav'!K:K,'Rozpočet - průběžný stav'!A:A,I46) -> 0 | F46: 2023 | G46: Převody | H46: Převod z 2019 | I46: =F46&"_"&G46&"_"&H46 -> 2023_Převody_Převod z 2019
...

Sheet Rozpočet 2022
A1: Rozpočet OVT 2022 | B1: Plán | C1: (2021 plán) | D1: Plnění | E1: Rozdíl
A2: Převod z roku 2021 | B2: 246189 | D2: automaticky z průběžného stavu
G3: Údaje pro automatické doplnění sloupce "Plnění" z listu "Rozpočet - průběžný stav"
A4: Kapitola běžný provoz | B4: Plán 2022 | C4: (Plán 2021) | D4: Plnění 2022 | E4: Rozdíl | G4: Rok | H4: Skupina | I4: Kategorie | J4: Klíč
A5: Příjmy | E5: rozdíl
A6: Příspěvky | B6: 40000 | C6: 40000 | D6: =SUMIFS('Rozpočet - průběžný stav'!K:K,'Rozpočet - průběžný stav'!A:A,J6) -> 43150 | E6: =D6-B6 -> 3150 | G6: 2022 | H6: Běžný provoz | I6: =A6 -> Příspěvky | J6: =G6&"_"&H6&"_"&I6 -> 2022_Běžný provoz_Příspěvky
A7: Přeúčtování TOM | B7: 10000 | C7: 5500 | D7: =SUMIFS('Rozpočet - průběžný stav'!K:K,'Rozpočet - průběžný stav'!A:A,J7) -> 2117 | G7: 2022 | H7: Běžný provoz | I7: =A7 -> Přeúčtování TOM | J7: =G7&"_"&H7&"_"&I7 -> 2022_Běžný provoz_Přeúčtování TOM | L7: Oddílová soutěž
A8: Příjem půjčení vleků | B8: 5000 | C8: 5000 | D8: =SUMIFS('Rozpočet - průběžný stav'!K:K,'Rozpočet - průběžný stav'!A:A,J8) -> 5000 | E8: =D8-B8 -> 0 | G8: 2022 | H8: Běžný provoz | I8: =A8 -> Příjem půjčení vleků | J8: =G8&"_"&H8&"_"&I8 -> 2022_Běžný provoz_Příjem půjčení vleků
A9: Ostatní | D9: =SUMIFS('Rozpočet - průběžný stav'!K:K,'Rozpočet - průběžný stav'!A:A,J9) -> 0 | G9: 2022 | H9: Běžný provoz | I9: =A9 -> Ostatní | J9: =G9&"_"&H9&"_"&I9 -> 2022_Běžný provoz_Ostatní
A10: Příjmy běžný provoz celkem | B10: =SUM(B6:B9) -> 55000 | C10: =SUM(C6:C9) -> 50500 | D10: =SUM(D6:D9) -> 50267 | E10: =D10-B10 -> -4733 | L10: Nejlepší ženy: | M10: doplnit
A12: Výdaje | L12: Katka Měrková | M12: 1000
A13: Interní nájmy | B13: 52000 | C13: 50000 | D13: =-SUMIFS('Rozpočet - průběžný stav'!K:K,'Rozpočet - průběžný stav'!A:A,J13) -> 58420 | E13: =D13-B13 -> 6420 | G13: 2022 | H13: Běžný provoz | I13: =A13 -> Interní nájmy | J13: =G13&"_"&H13&"_"&I13 -> 2022_Běžný provoz_Interní nájmy | L13: Kateřina Šedivá | M13: 800
A14: Interní nájmy ostatní | D14: =-SUMIFS('Rozpočet - průběžný stav'!K:K,'Rozpočet - průběžný stav'!A:A,J14) -> 0 | E14: =D14-B14 -> 0 | G14: 2022 | H14: Běžný provoz | I14: =A14 -> Interní nájmy ostatní | J14: =G14&"_"&H14&"_"&I14 -> 2022_Běžný provoz_Interní nájmy ostatní | L14: Bára Bernardová | M14: 600
A15: Příspěvky ČSK | B15: 1300 | C15: 630 | D15: =-SUMIFS('Rozpočet - průběžný stav'!K:K,'Rozpočet - průběžný stav'!A:A,J15) -> 1290 | E15: =D15-B15 -> -10 | F15: více je TOM, viz přeúčtování TOM | G15: 2022 | H15: Běžný provoz | I15: =A15 -> Příspěvky ČSK | J15: =G15&"_"&H15&"_"&I15 -> 2022_Běžný provoz_Příspěvky ČSK | L15: Nejlepší muži: | M15: doplnit
A16: Údržba vleků | B16: 3000 | C16: 5000 | D16: =-SUMIFS('Rozpočet - průběžný stav'!K:K,'Rozpočet - průběžný stav'!A:A,J16) -> 1106 | E16: =D16-B16 -> -1894 | F16: náklady na vleky jsou napůl s TOM, viz přeúčtování TOM | G16: 2022 | H16: Běžný provoz | I16: =A16 -> Údržba vleků | J16: =G16&"_"&H16&"_"&I16 -> 2022_Běžný provoz_Údržba vleků | L16: Jiří Klíma | M16: 1000
A17: Materiál | B17: 1000 | C17: 1000 | D17: =-SUMIFS('Rozpočet - průběžný stav'!K:K,'Rozpočet - průběžný stav'!A:A,J17) -> 0 | E17: =D17-B17 -> -1000 | G17: 2022 | H17: Běžný provoz | I17: =A17 -> Materiál | J17: =G17&"_"&H17&"_"&I17 -> 2022_Běžný provoz_Materiál | L17: Jáchym Kopřiva | M17: 800
A18: Výdaje ostatní | D18: =-SUMIFS('Rozpočet - průběžný stav'!K:K,'Rozpočet - průběžný stav'!A:A,J18) -> 497.31 | E18: =D18-B18 -> 497.31 | F18: webhosting | G18: 2022 | H18: Běžný provoz | I18: =A18 -> Výdaje ostatní | J18: =G18&"_"&H18&"_"&I18 -> 2022_Běžný provoz_Výdaje ostatní | L18: Martin Kříž | M18: 600
A19: Výdaje běžný provoz celkem | B19: =SUM(B12:B18) -> 57300 | C19: =SUM(C12:C18) -> 56630 | D19: =SUM(D12:D18) -> 61313.31 | E19: =D19-B19 -> 4013.31
A21: Bilance běžný provoz | B21: =B10-B19 -> -2300 | C21: =C10-C19 -> -6130 | D21: =D10-D19 -> -11046.31 | E21: =D21-B21 -> -8746.31
A23: Kapitola podpora činnosti | B23: Plán 2022 | C23: (Plán 2021) | D23: Plnění 2022 | E23: Rozdíl | G23: Rok | H23: Skupina | I23: Kategorie | J23: Klíč
A24: Příjmy
A25: Příjem Hamerák | B25: 0 | C25: 0 | D25: =SUMIFS('Rozpočet - průběžný stav'!K:K,'Rozpočet - průběžný stav'!A:A,J25) -> -2525 | G25: 2022 | H25: Hamerák-akce | I25: Hamerák finance | J25: =G25&"_"&H25&"_"&I25 -> 2022_Hamerák-akce_Hamerák finance
A26: Příjmy dotace a dary | B26: 0 | C26: 4000 | D26: =SUMIFS('Rozpočet - průběžný stav'!K:K,'Rozpočet - průběžný stav'!A:A,J26) -> 3577 | E26: =D26-B26 -> 3577 | G26: 2022 | H26: Podpora činnosti | I26: =A26 -> Příjmy dotace a dary | J26: =G26&"_"&H26&"_"&I26 -> 2022_Podpora činnosti_Příjmy dotace a dary
A27: Příjmy podpora činnosti celkem | B27: =SUM(B24:B26) -> 0 | C27: =SUM(C24:C26) -> 4000 | D27: =SUM(D24:D26) -> 1052 | E27: =D27-B27 -> 1052
A29: Výdaje
A30: Podpora akcí | B30: 30000 | D30: =-SUMIFS('Rozpočet - průběžný stav'!K:K,'Rozpočet - průběžný stav'!A:A,J30) -> 14839 | E30: =D30-B30 -> -15161 | G30: 2022 | H30: Podpora činnosti | I30: =A30 -> Podpora akcí | J30: =G30&"_"&H30&"_"&I30 -> 2022_Podpora činnosti_Podpora akcí
A31: Podpora ČPV | C31: 10000 | D31: =-SUMIFS('Rozpočet - průběžný stav'!K:K,'Rozpočet - průběžný stav'!A:A,J31) -> 0 | E31: =D31-B31 -> 0 | G31: 2022 | H31: Podpora činnosti | I31: =A31 -> Podpora ČPV | J31: =G31&"_"&H31&"_"&I31 -> 2022_Podpora činnosti_Podpora ČPV
A32: Podpora eskymáků | C32: 0 | D32: =-SUMIFS('Rozpočet - průběžný stav'!K:K,'Rozpočet - průběžný stav'!A:A,J32) -> 0 | E32: =D32-B32 -> 0 | G32: 2022 | H32: Podpora činnosti | I32: =A32 -> Podpora eskymáků | J32: =G32&"_"&H32&"_"&I32 -> 2022_Podpora činnosti_Podpora eskymáků
A33: Podpora výcviku záchrany | C33: 1500 | D33: =-SUMIFS('Rozpočet - průběžný stav'!K:K,'Rozpočet - průběžný stav'!A:A,J33) -> 0 | E33: =D33-B33 -> 0 | G33: 2022 | H33: Podpora činnosti | I33: =A33 -> Podpora výcviku záchrany | J33: =G33&"_"&H33&"_"&I33 -> 2022_Podpora činnosti_Podpora výcviku záchrany
A34: Podpora zahraniční zájezd | C34: 4000 | D34: =-SUMIFS('Rozpočet - průběžný stav'!K:K,'Rozpočet - průběžný stav'!A:A,J34) -> 0 | E34: =D34-B34 -> 0 | G34: 2022 | H34: Podpora činnosti | I34: =A34 -> Podpora zahraniční zájezd | J34: =G34&"_"&H34&"_"&I34 -> 2022_Podpora činnosti_Podpora zahraniční zájezd
A35: Oddílový den | C35: 3000 | D35: =-SUMIFS('Rozpočet - průběžný stav'!K:K,'Rozpočet - průběžný stav'!A:A,J35) -> 0 | E35: =D35-B35 -> 0 | G35: 2022 | H35: Podpora činnosti | I35: =A35 -> Oddílový den | J35: =G35&"_"&H35&"_"&I35 -> 2022_Podpora činnosti_Oddílový den
A36: Oddílové vánoce | C36: 3000 | D36: =-SUMIFS('Rozpočet - průběžný stav'!K:K,'Rozpočet - průběžný stav'!A:A,J36) -> 0 | E36: =D36-B36 -> 0 | G36: 2022 | H36: Podpora činnosti | I36: =A36 -> Oddílové vánoce | J36: =G36&"_"&H36&"_"&I36 -> 2022_Podpora činnosti_Oddílové vánoce
A37: Oddílová soutěž | B37: 4800 | C37: 4800 | D37: =-SUMIFS('Rozpočet - průběžný stav'!K:K,'Rozpočet - průběžný stav'!A:A,J37) -> 1400 | E37: =D37-B37 -> -3400 | G37: 2022 | H37: Podpora činnosti | I37: =A37 -> Oddílová soutěž | J37: =G37&"_"&H37&"_"&I37 -> 2022_Podpora činnosti_Oddílová soutěž
A38: Materiál | B38: 0 | C38: 0 | D38: =-SUMIFS('Rozpočet - průběžný stav'!K:K,'Rozpočet - průběžný stav'!A:A,J38) -> 0 | E38: =D38-B38 -> 0 | G38: 2022 | H38: Podpora činnosti | I38: =A38 -> Materiál | J38: =G38&"_"&H38&"_"&I38 -> 2022_Podpora činnosti_Materiál
A39: Hamerák výbor (večeře) | B39: 0 | C39: 5000 | D39: =-SUMIFS('Rozpočet - průběžný stav'!K:K,'Rozpočet - průběžný stav'!A:A,J39) -> 0 | E39: =D39-B39 -> 0 | G39: 2022 | H39: Hamerák-akce | I39: Výbor večeře | J39: =G39&"_"&H39&"_"&I39 -> 2022_Hamerák-akce_Výbor večeře
A40: Hamerák ostatní výdaje | B40: 0 | C40: 0 | D40: =-SUMIFS('Rozpočet - průběžný stav'!K:K,'Rozpočet - průběžný stav'!A:A,J40) -> 0 | E40: =D40-B40 -> 0 | G40: 2022 | H40: Hamerák-akce | I40: Náklady příprava | J40: =G40&"_"&H40&"_"&I40 -> 2022_Hamerák-akce_Náklady příprava | L40: Výsledek Hamerák: | M40: =D25-D39-D40 -> -2525
A41: Výdaje podpora činnosti celkem | B41: =sum(B30:B40) -> 34800 | C41: =sum(C30:C40) -> 31300 | D41: =sum(D30:D40) -> 16239 | E41: =D41-B41 -> -18561
A43: Bilance podpora činnosti | B43: =B27-B41 -> -34800 | C43: =C27-C41 -> -27300 | D43: =D27-D41 -> -15187 | E43: =D43-B43 -> 19613
A45: Bilance Hamerák | B45: 0 | C45: 0 | D45: =D25-D39-D40 -> -2525
D46: =-SUMIFS('Rozpočet - průběžný stav'!K:K,'Rozpočet - průběžný stav'!A:A,J46) -> 0 | G46: 2022 | H46: Převody | I46: Převod z 2019 | J46: =G46&"_"&H46&"_"&I46 -> 2022_Převody_Převod z 2019
...

Sheet Rozpočet 2021
A1: Rozpočet OVT 2021 | B1: Plán | C1: (2020 plán) | D1: Plnění | E1: Rozdíl
A2: Převod z roku 2020 | B2: 192476 | D2: automaticky z průběžného stavu
G3: Údaje pro automatické doplnění sloupce "Plnění" z listu "Rozpočet - průběžný stav"
A4: Kapitola běžný provoz | B4: Plán | C4: Plán 2020 | D4: Plnění 2021 | E4: Rozdíl | G4: Rok | H4: Skupina | I4: Kategorie | J4: Klíč
A5: Příjmy 2021 | E5: rozdíl
A6: Příspěvky | B6: 40000 | C6: 60000 | D6: =SUMIFS('Rozpočet - průběžný stav'!K:K,'Rozpočet - průběžný stav'!A:A,J6) -> 45000 | E6: =D6-B6 -> 5000 | G6: 2021 | H6: Běžný provoz | I6: =A6 -> Příspěvky | J6: =G6&"_"&H6&"_"&I6 -> 2021_Běžný provoz_Příspěvky
A7: Přeúčtování TOM | B7: 5500 | C7: 5500 | D7: =SUMIFS('Rozpočet - průběžný stav'!K:K,'Rozpočet - průběžný stav'!A:A,J7) -> 0 | G7: 2021 | H7: Běžný provoz | I7: =A7 -> Přeúčtování TOM | J7: =G7&"_"&H7&"_"&I7 -> 2021_Běžný provoz_Přeúčtování TOM | L7: Oddílová soutěž
A8: Příjem půjčení vleků | B8: 5000 | C8: 5000 | D8: =SUMIFS('Rozpočet - průběžný stav'!K:K,'Rozpočet - průběžný stav'!A:A,J8) -> 5000 | E8: =D8-B8 -> 0 | G8: 2021 | H8: Běžný provoz | I8: =A8 -> Příjem půjčení vleků | J8: =G8&"_"&H8&"_"&I8 -> 2021_Běžný provoz_Příjem půjčení vleků
A9: Ostatní | D9: =SUMIFS('Rozpočet - průběžný stav'!K:K,'Rozpočet - průběžný stav'!A:A,J9) -> 0 | G9: 2021 | H9: Běžný provoz | I9: =A9 -> Ostatní | J9: =G9&"_"&H9&"_"&I9 -> 2021_Běžný provoz_Ostatní
A10: Příjmy běžný provoz celkem | B10: =SUM(B6:B9) -> 50500 | C10: =SUM(C6:C9) -> 70500 | D10: =SUM(D6:D9) -> 50000 | E10: =D10-B10 -> -500 | L10: Nejlepší ženy: | M10: doplnit
A12: Výdaje 2021 | L12: Kateřina Měrková | M12: 1000
A13: Interní nájmy | B13: 50000 | C13: 50000 | D13: =-SUMIFS('Rozpočet - průběžný stav'!K:K,'Rozpočet - průběžný stav'!A:A,J13) -> 22414 | E13: =D13-B13 -> -27586 | G13: 2021 | H13: Běžný provoz | I13: =A13 -> Interní nájmy | J13: =G13&"_"&H13&"_"&I13 -> 2021_Běžný provoz_Interní nájmy | L13: Majka Hořejší | M13: 800
A14: Interní nájmy ostatní | D14: =-SUMIFS('Rozpočet - průběžný stav'!K:K,'Rozpočet - průběžný stav'!A:A,J14) -> 0 | E14: =D14-B14 -> 0 | G14: 2021 | H14: Běžný provoz | I14: =A14 -> Interní nájmy ostatní | J14: =G14&"_"&H14&"_"&I14 -> 2021_Běžný provoz_Interní nájmy ostatní | L14: Kateřina Šedivá | M14: 600
A15: Interní nájmy - srovnání TOM | D15: =-SUMIFS('Rozpočet - průběžný stav'!K:K,'Rozpočet - průběžný stav'!A:A,J15) -> 0 | E15: =D15-B15 -> 0 | G15: 2021 | H15: Běžný provoz | I15: =A15 -> Interní nájmy - srovnání TOM | J15: =G15&"_"&H15&"_"&I15 -> 2021_Běžný provoz_Interní nájmy - srovnání TOM
A16: Příspěvky ČSK | B16: 630 | C16: 630 | D16: =-SUMIFS('Rozpočet - průběžný stav'!K:K,'Rozpočet - průběžný stav'!A:A,J16) -> 1330 | E16: =D16-B16 -> 700 | F16: více je TOM, viz přeúčtování TOM | G16: 2021 | H16: Běžný provoz | I16: =A16 -> Příspěvky ČSK | J16: =G16&"_"&H16&"_"&I16 -> 2021_Běžný provoz_Příspěvky ČSK | L16: Nejlepší muži: | M16: doplnit
A17: Údržba vleků | B17: 5000 | C17: 2000 | D17: =-SUMIFS('Rozpočet - průběžný stav'!K:K,'Rozpočet - průběžný stav'!A:A,J17) -> 212 | E17: =D17-B17 -> -4788 | F17: náklady na vleky jsou napůl s TOM, viz přeúčtování TOM | G17: 2021 | H17: Běžný provoz | I17: =A17 -> Údržba vleků | J17: =G17&"_"&H17&"_"&I17 -> 2021_Běžný provoz_Údržba vleků | L17: Jáchym Kopřiva | M17: 1000
A18: Materiál | B18: 1000 | C18: 2000 | D18: =-SUMIFS('Rozpočet - průběžný stav'!K:K,'Rozpočet - průběžný stav'!A:A,J18) -> 0 | E18: =D18-B18 -> -1000 | G18: 2021 | H18: Běžný provoz | I18: =A18 -> Materiál | J18: =G18&"_"&H18&"_"&I18 -> 2021_Běžný provoz_Materiál | L18: Šálek Pavel | M18: 800
A19: Výdaje ostatní | D19: =-SUMIFS('Rozpočet - průběžný stav'!K:K,'Rozpočet - průběžný stav'!A:A,J19) -> 497.31 | E19: =D19-B19 -> 497.31 | F19: webhosting | G19: 2021 | H19: Běžný provoz | I19: =A19 -> Výdaje ostatní | J19: =G19&"_"&H19&"_"&I19 -> 2021_Běžný provoz_Výdaje ostatní | L19: Martin Kříž | M19: 600
A20: Výdaje běžný provoz celkem | B20: =SUM(B12:B19) -> 56630 | C20: =SUM(C12:C19) -> 54630 | D20: =SUM(D12:D19) -> 24453.31 | E20: =D20-B20 -> -32176.69
A22: Bilance běžný provoz | B22: =B10-B20 -> -6130 | C22: =C10-C20 -> 15870 | D22: =D10-D20 -> 25546.69 | E22: =D22-B22 -> 31676.69
A24: Kapitola podpora činnosti | B24: Plán | C24: Plán 2020 | D24: Plnění 2021 | E24: Rozdíl | G24: Rok | H24: Skupina | I24: Kategorie | J24: Klíč
A25: Příjmy 2021
A26: Hamerák příjem | B26: 0 | C26: 0 | D26: =SUMIFS('Rozpočet - průběžný stav'!K:K,'Rozpočet - průběžný stav'!A:A,J26) -> 44518.6 | G26: 2021 | H26: Hamerák-akce | I26: Hamerák finance | J26: =G26&"_"&H26&"_"&I26 -> 2021_Hamerák-akce_Hamerák finance
A27: Příjmy dotace | B27: 2000 | C27: 2000 | D27: =SUMIFS('Rozpočet - průběžný stav'!K:K,'Rozpočet - průběžný stav'!A:A,J27) -> 0 | E27: =D27-B27 -> -2000 | G27: 2021 | H27: Podpora činnosti | I27: =A27 -> Příjmy dotace | J27: =G27&"_"&H27&"_"&I27 -> 2021_Podpora činnosti_Příjmy dotace
A28: Příjmy dary | B28: 2000 | C28: 2000 | D28: =SUMIFS('Rozpočet - průběžný stav'!K:K,'Rozpočet - průběžný stav'!A:A,J28) -> 0 | E28: =D28-B28 -> -2000 | G28: 2021 | H28: Podpora činnosti | I28: =A28 -> Příjmy dary | J28: =G28&"_"&H28&"_"&I28 -> 2021_Podpora činnosti_Příjmy dary
A29: Příjmy ostatní | D29: =SUMIFS('Rozpočet - průběžný stav'!K:K,'Rozpočet - průběžný stav'!A:A,J29) -> 0 | E29: =D29-B29 -> 0 | G29: 2021 | H29: Podpora činnosti | I29: =A29 -> Příjmy ostatní | J29: =G29&"_"&H29&"_"&I29 -> 2021_Podpora činnosti_Příjmy ostatní
A30: Příjmy podpora činnosti celkem | B30: =SUM(B25:B29) -> 4000 | C30: =SUM(C25:C29) -> 4000 | D30: =SUM(D25:D29) -> 44518.6 | E30: =D30-B30 -> 40518.6
A32: Výdaje 2021
A33: Podpora ČPV | B33: 10000 | C33: 10000 | D33: =-SUMIFS('Rozpočet - průběžný stav'!K:K,'Rozpočet - průběžný stav'!A:A,J33) -> 4500 | E33: =D33-B33 -> -5500 | G33: 2021 | H33: Podpora činnosti | I33: =A33 -> Podpora ČPV | J33: =G33&"_"&H33&"_"&I33 -> 2021_Podpora činnosti_Podpora ČPV
A34: Podpora eskymáků | B34: 0 | C34: 0 | D34: =-SUMIFS('Rozpočet - průběžný stav'!K:K,'Rozpočet - průběžný stav'!A:A,J34) -> 0 | E34: =D34-B34 -> 0 | G34: 2021 | H34: Podpora činnosti | I34: =A34 -> Podpora eskymáků | J34: =G34&"_"&H34&"_"&I34 -> 2021_Podpora činnosti_Podpora eskymáků
A35: Podpora výcviku záchrany | B35: 1500 | C35: 1500 | D35: =-SUMIFS('Rozpočet - průběžný stav'!K:K,'Rozpočet - průběžný stav'!A:A,J35) -> 0 | E35: =D35-B35 -> -1500 | G35: 2021 | H35: Podpora činnosti | I35: =A35 -> Podpora výcviku záchrany | J35: =G35&"_"&H35&"_"&I35 -> 2021_Podpora činnosti_Podpora výcviku záchrany
A36: Podpora zahraniční zájezd | B36: 4000 | C36: 4000 | D36: =-SUMIFS('Rozpočet - průběžný stav'!K:K,'Rozpočet - průběžný stav'!A:A,J36) -> 0 | E36: =D36-B36 -> -4000 | G36: 2021 | H36: Podpora činnosti | I36: =A36 -> Podpora zahraniční zájezd | J36: =G36&"_"&H36&"_"&I36 -> 2021_Podpora činnosti_Podpora zahraniční zájezd
A37: Oddílový den | B37: 3000 | C37: 3000 | D37: =-SUMIFS('Rozpočet - průběžný stav'!K:K,'Rozpočet - průběžný stav'!A:A,J37) -> 0 | E37: =D37-B37 -> -3000 | G37: 2021 | H37: Podpora činnosti | I37: =A37 -> Oddílový den | J37: =G37&"_"&H37&"_"&I37 -> 2021_Podpora činnosti_Oddílový den
A38: Oddílové vánoce | B38: 3000 | C38: 3000 | D38: =-SUMIFS('Rozpočet - průběžný stav'!K:K,'Rozpočet - průběžný stav'!A:A,J38) -> 4252.57 | E38: =D38-B38 -> 1252.57 | G38: 2021 | H38: Podpora činnosti | I38: =A38 -> Oddílové vánoce | J38: =G38&"_"&H38&"_"&I38 -> 2021_Podpora činnosti_Oddílové vánoce
A39: Oddílová soutěž | B39: 4800 | C39: 4800 | D39: =-SUMIFS('Rozpočet - průběžný stav'!K:K,'Rozpočet - průběžný stav'!A:A,J39) -> 2600 | E39: =D39-B39 -> -2200 | G39: 2021 | H39: Podpora činnosti | I39: =A39 -> Oddílová soutěž | J39: =G39&"_"&H39&"_"&I39 -> 2021_Podpora činnosti_Oddílová soutěž
A40: Materiál | B40: 0 | C40: 0 | D40: =-SUMIFS('Rozpočet - průběžný stav'!K:K,'Rozpočet - průběžný stav'!A:A,J40) -> 0 | E40: =D40-B40 -> 0 | G40: 2021 | H40: Podpora činnosti | I40: =A40 -> Materiál | J40: =G40&"_"&H40&"_"&I40 -> 2021_Podpora činnosti_Materiál
A41: Hamerák výbor (večeře) | B41: 5000 | C41: 5000 | D41: =-SUMIFS('Rozpočet - průběžný stav'!K:K,'Rozpočet - průběžný stav'!A:A,J41) -> 5000 | E41: =D41-B41 -> 0 | G41: 2021 | H41: Hamerák-akce | I41: Výbor večeře | J41: =G41&"_"&H41&"_"&I41 -> 2021_Hamerák-akce_Výbor večeře
A42: Hamerák ostatní výdaje | B42: 0 | C42: 0 | D42: =-SUMIFS('Rozpočet - průběžný stav'!K:K,'Rozpočet - průběžný stav'!A:A,J42) -> 0 | E42: =D42-B42 -> 0 | G42: 2021 | H42: Hamerák-akce | I42: Náklady příprava | J42: =G42&"_"&H42&"_"&I42 -> 2021_Hamerák-akce_Náklady příprava | L42: Výsledek Hamerák: | M42: =D26-D41-D42 -> 39518.6
A43: Výdaje podpora činnosti celkem | B43: =sum(B33:B42) -> 31300 | C43: =sum(C33:C42) -> 31300 | D43: =sum(D33:D42) -> 16352.57 | E43: =D43-B43 -> -14947.43
A45: Bilance podpora činnosti | B45: =B30-B43 -> -27300 | C45: =C30-C43 -> -27300 | D45: =D30-D43 -> 28166.03 | E45: =D45-B45 -> 55466.03
...

Sheet Rozpočet 2020
A1: Rozpočet OVT 2020 | B1: Plán | C1: (2019 plán) | D1: Plnění | E1: Rozdíl
A2: Převod z roku 2019 | B2: 169424 | D2: automaticky z průběžného stavu
G3: Údaje pro automatické doplnění sloupce "Plnění" z listu "Rozpočet - průběžný stav"
