Workbook

Sheet Náklady 2025
A1: co | B1: kdo | C1: kdy | D1: kolik | E1: k zaplacení | F1: zaplaceno? | G1: do vyúčtování | I1: doklad?
A2: za cesty asi | B2: Lukáš Kopřiva | E2: 450 | F2: ano | G2: 0 | I2: n
B3: Lukáš Kopřiva | E3: 0 | G3: 1740 | I3: ve složce
A4: doprava Ham | B4: Ešus | C4: 45822 | D4: 3000 | E4: 3000 | F4: ano
B5: Jašek | C5: 45933 | D5: 540 | E5: 540 | F5: ano | G5: 2030 | I5: ve složce
B6: Gríša | E6: ? | G6: 2232 | I6: k tisku a podpisu
A7: cesťák | B7: Ešus | C7: 45936 | D7: 2793.6 | E7: 1024 | F7: ano | G7: =D7 -> 2793.6 | I7: ve složce
A8: ubytování | B8: Ratmírov | C8: 45985 | D8: 3000 | E8: =D8 -> 3000 | F8: ano | G8: =D8 -> 3000 | I8: ve složce
A10: přívěs | B10: Milan | C10: 45936 | D10: 971.03 | E10: =D10 -> 971.03 | F10: ano | G10: =D10 -> 971.03 | I10: ve složce
A11: schody materiál | B11: Milan | C11: 45936 | D11: 2007.11 | E11: =D11 -> 2007.11 | F11: ano | G11: =D11 -> 2007.11 | I11: ve složce
A12: dřevo schody | C12: 45933 | D12: 15125 | E12: =D12 -> 15125 | F12: ano | G12: =D12 -> 15125 | I12: ve složce
A13: barvy | C13: 45926 | D13: 4565 | E13: =D13 -> 4565 | F13: ano | G13: =D13 -> 4565 | I13: ve složce
A14: vruty | C14: 45930 | D14: 236.44 | E14: =D14 -> 236.44 | F14: ano | G14: =D14 -> 236.44 | I14: ve složce
A15: pošta | C15: 45847 | D15: 532 | E15: =D15 -> 532 | F15: ano | G15: =D15 -> 532 | I15: ve složce
A16: pošta | C16: 45847 | D16: 608 | E16: =D16 -> 608 | F16: ano | G16: =D16 -> 608 | I16: ve složce
A17: latě | C17: 45903 | D17: 1282.54 | E17: =D17 -> 1282.54 | F17: ano | G17: =D17 -> 1282.54 | I17: ve složce
E19: =SUM(E2:E15) -> 31450.58 | G19: =SUM(G2:G15) -> 35232.18

Sheet G25
A2: Vyúčtování pracovních cest
A3: Jméno zaměstnance: | B3: Griša | C3: Nákl. Středisko | E3: Tel linka | F3: 603195224
B4: Vodička | C4: TJ Bohemians, OVT
A6: Kapesné zahraničí | B6: Účel cesty | E6: Cíl cesty | G6: Dopravní prostředek
B7: Brigáda Hamerák | E7: Malý Ratmírov | G7: AUV
A9: Při použiti soukromého vozu: | B9: SPZ: | C9: Typ vozu | E9: Havarijní pojistka č. | G9: Pohonná látka | H9: Prům spotřeba
B10: 2AK4963 | C10: Ford Kuga | E10: 6337609142 | G10: diesel | H10: 7.5
A12: Počet spolucestujících | B12: Jména spolucestujících
B13: Kateřina Měrková, Miroslav Ptáček
A14: datum: | B14: Odjezd/Hod | C14: Příjezd/Hod | D14: Km - tuzemsko | E14: Km - zahraničí | F14: Jízda z místa (příp. hraniční přechod) - do místa
A15: 45934 | B15: 8.00 | C15: 10.00 | D15: 155 | F15: Praha – Malý Ratmírov
A16: 45935 | B16: 11.00 | C16: 13.00 | D16: 155 | F16: Malý Ratmírov – Praha
B24: Celkem ujeté km | D24: 310 | E24: 0
A26: Položka | F26: Tuzemsko Kč | G26: Zahraničí (….) | H26: Zahraničí Kč
A27: 1 | B27: Cestovné náklady - soukr. Vůz | D27: 2232
A28: 2 | B28: Náklady na služební vůz
A29: 3 | B29: Jízdenky zakoupené pracovníkem
A30: 4 | B30: Jízdenky zakoupené společností
A31: 5 | B31: Výdaje za metro, bus, taxi atd.
A32: 7 | B32: Stravné tuzemsko 5 - 12 hod
A33: 8 | B33: Stravné tuzemsko 12 - 18 hod
A34: 9 | B34: Stravné tuzemsko 18 - 24 hod
A35: 10 | B35: Stravné zahraničí 0 - 12 hod
A36: 11 | B36: Stravné zahraničí 12 - 24 hod
A37: 12 | B37: Kapesné zahraničí
A39: -1 | B39: Krácení snídaně
A40: -2 | B40: Krácení za pozvání
... A43: 14 | B43: Ostatní
A45: Celkové cestovní náklady v cizí měně | F45: Podpis zaměstnance
A46: Záloha v cizí měně
A47: K vyplacení / vrácení v cizí měně | F47: Datum | G47: 45936
A48: Celkové cestovní náklady v Kč | D48: 2232 | F48: Povoleno k vyúčtování:
A49: Záloha v Kč | D49: 0
A50: K vyplacení / vrácení v Kč | D50: 2232 | G50: podpis účetní

Sheet Rozpočet 2024
A1: VÝDAJE
A2: kategorie | B2: položka | C2: Návrh | D2: Skutečnost | E2: diff Y | F2: Y-1 | G2: diff Y-1
A3: doprava | B3: bus Jan Kukla | C3: 120000 | D3: =SUMIFS('Náklady 2024'!$L$2:$L$38,'Náklady 2024'!$E$2:$E$38,B3) -> 100600 | E3: =C3-D3 -> 19400 | F3: 102000 | G3: =F3-D3 -> 1400
A4: doprava | B4: vlak JHMD | C4: 0 | D4: =SUMIFS('Náklady 2024'!$L$2:$L$38,'Náklady 2024'!$E$2:$E$38,B4) -> 0 | E4: =C4-D4 -> 0 | F4: 0 | G4: =F4-D4 -> 0
A5: doprava | B5: permice tisk | C5: 6000 | D5: =SUMIFS('Náklady 2024'!$L$2:$L$38,'Náklady 2024'!$E$2:$E$38,B5) -> 10000 | E5: =C5-D5 -> -4000 | F5: 6000 | G5: =F5-D5 -> -4000
A6: doprava | B6: materiál náklady (igelity aj.) | C6: 3000 | D6: =SUMIFS('Náklady 2024'!$L$2:$L$38,'Náklady 2024'!$E$2:$E$38,B6) -> 4697 | E6: =C6-D6 -> -1697 | F6: 869 | G6: =F6-D6 -> -3828
A7: doprava | B7: obslužná vozidla | C7: 6000 | D7: =SUMIFS('Náklady 2024'!$L$2:$L$38,'Náklady 2024'!$E$2:$E$38,B7) -> 1000 | E7: =C7-D7 -> 5000 | F7: 4535 | G7: =F7-D7 -> 3535
A8: ceny | B8: hrnky potisk | C8: 7000 | D8: =SUMIFS('Náklady 2024'!$L$2:$L$38,'Náklady 2024'!$E$2:$E$38,B8) -> 8442 | E8: =C8-D8 -> -1442 | F8: 6500 | G8: =F8-D8 -> -1942
A9: závodní trať | B9: materiál branky | C9: 2500 | D9: =SUMIFS('Náklady 2024'!$L$2:$L$38,'Náklady 2024'!$E$2:$E$38,B9) -> 1689 | E9: =C9-D9 -> 811 | F9: 2389 | G9: =F9-D9 -> 700
A10: závodní trať | B10: schody pod hrází | D10: =SUMIFS('Náklady 2024'!$L$2:$L$38,'Náklady 2024'!$E$2:$E$38,B10) -> 1200 | E10: =C10-D10 -> -1200 | G10: =F10-D10 -> -1200
A11: místní poplatky | B11: Boček hráz vstup | C11: 2000 | D11: =SUMIFS('Náklady 2024'!$L$2:$L$38,'Náklady 2024'!$E$2:$E$38,B11) -> 1500 | E11: =C11-D11 -> 500 | F11: 1500 | G11: =F11-D11 -> 0
A12: místní poplatky | B12: Hrázný Fučík | C12: 700 | D12: =SUMIFS('Náklady 2024'!$L$2:$L$38,'Náklady 2024'!$E$2:$E$38,B12) -> 700 | E12: =C12-D12 -> 0 | F12: 700 | G12: =F12-D12 -> 0
A13: místní poplatky | B13: Feit - louka Dvoreček | C13: 2000 | D13: =SUMIFS('Náklady 2024'!$L$2:$L$38,'Náklady 2024'!$E$2:$E$38,B13) -> 2000 | E13: =C13-D13 -> 0 | F13: 1800 | G13: =F13-D13 -> -200
A14: vodohospodářství | B14: Rybáři | C14: =15000*1.21 -> 18150 | D14: =SUMIFS('Náklady 2024'!$L$2:$L$38,'Náklady 2024'!$E$2:$E$38,B14) -> 18150 | E14: =C14-D14 -> 0 | F14: 14520 | G14: =F14-D14 -> -3630
A15: občerstvení | B15: pivo Kamenice | C15: 5000 | D15: =SUMIFS('Náklady 2024'!$L$2:$L$38,'Náklady 2024'!$E$2:$E$38,B15) -> 3000 | E15: =C15-D15 -> 2000 | F15: 4000 | G15: =F15-D15 -> 1000
A16: občerstvení | B16: náklady občerstvení | C16: 4000 | D16: =SUMIFS('Náklady 2024'!$L$2:$L$38,'Náklady 2024'!$E$2:$E$38,B16) -> 6755 | E16: =C16-D16 -> -2755 | F16: 3005 | G16: =F16-D16 -> -3750
A17: příprava, zpracování | B17: materiál příprava | C17: 4000 | D17: =SUMIFS('Náklady 2024'!$L$2:$L$38,'Náklady 2024'!$E$2:$E$38,B17) -> 594 | E17: =C17-D17 -> 3406 | G17: =F17-D17 -> -594
A18: příprava, zpracování | B18: cesty příprava | D18: =SUMIFS('Náklady 2024'!$L$2:$L$38,'Náklady 2024'!$E$2:$E$38,B18) -> 3265 | E18: =C18-D18 -> -3265 | F18: 3577 | G18: =F18-D18 -> 312
A19: příprava, zpracování | B19: pošta | D19: =SUMIFS('Náklady 2024'!$L$2:$L$38,'Náklady 2024'!$E$2:$E$38,B19) -> 1020 | E19: =C19-D19 -> -1020 | G19: =F19-D19 -> -1020
A20: ubytování | B20: chatky | C20: 57000 | D20: =SUMIFS('Náklady 2024'!$L$2:$L$38,'Náklady 2024'!$E$2:$E$38,B20) -> 45600 | E20: =C20-D20 -> 11400 | F20: 50100 | G20: =F20-D20 -> 4500
A21: kelímky | B21: výroba kelímků | C21: 0 | D21: =SUMIFS('Náklady 2024'!$L$2:$L$38,'Náklady 2024'!$E$2:$E$38,B21) -> 0 | E21: =C21-D21 -> 0 | F21: 17726 | G21: =F21-D21 -> 17726
A22: CELKEM | C22: =SUM(C3:C21) -> 237350 | D22: =SUM(D3:D21) -> 210212 | E22: =SUM(E3:E21) -> 27138 | F22: =SUM(F3:F21) -> 219221 | G22: =SUM(G3:G21) -> 9009
C23: Rozdíl: | D23: =C22-D22 -> 27138
A24: PŘÍJMY
A25: Položka | B25: SUM | C25: Cena | D25: Příjem | G25: Z/Z | H25: Návrh | I25: Skutečnost
A26: Závod (čísel) | B26: 219 | C26: 0 | D26: =B26*C26 -> 0 | G26: Příjmy | H26: 239700 | I26: =D39 -> 237790
A27: Závod (lidi - podle tomboly) | B27: 253 | C27: 200 | D27: =B27*C27 -> 50600 | G27: Výdaje | H27: -237350 | I27: =-D22 -> -210212
A28: Splutí víkend | B28: 64 | C28: 200 | D28: =B28*C28 -> 12800 | G28: CELKEM | H28: =H26+H27 -> 2350 | I28: =I26+I27 -> 27578
A29: Splutí sobota | B29: 62 | C29: 150 | D29: =B29*C29 -> 9300
A30: Splutí neděle | B30: 125 | C30: 150 | D30: =B30*C30 -> 18750 | G30: Účty | H30: Příjem | I30: Výdaj | J30: Rozdíl | K30: vstup
A31: Permice víkend | B31: 123 | C31: 230 | D31: =B31*C31 -> 28290 | G31: hotovost | H31: =D37 -> 152790 | I31: =SUMIF('Náklady 2024'!$I$2:$I$38,G31,'Náklady 2024'!$L$2:$L$38) -> 176567 | J31: =H31-I31 -> -23777 | K31: 44500 | L31: =J31+K31 -> 20723
A32: Permice sobota | B32: 113 | C32: 170 | D32: =B32*C32 -> 19210 | G32: Air OVT | H32: 0 | I32: =SUMIF('Náklady 2024'!$I$2:$I$38,G32,'Náklady 2024'!$L$2:$L$38) -> 9895 | J32: =H32-I32 -> -9895
A33: Permice neděle | B33: 77 | C33: 170 | D33: =B33*C33 -> 13090 | G33: TJ účet | H33: =D38 -> 85000 | I33: =SUMIF('Náklady 2024'!$I$2:$I$38,G33,'Náklady 2024'!$L$2:$L$38) -> 23750 | J33: =H33-I33 -> 61250
A34: Kelímky | B34: 15 | C34: 50 | D34: =B34*C34 -> 750 | G34: SUM: | H34: =SUM(H31:H33) -> 237790 | I34: =SUM(I31:I33) -> 210212 | J34: =H34-I34 -> 27578
A35: Vrácené kelímky | B35: 0 | C35: -50 | D35: =B35*C35 -> 0
A36: Žetony na kelímky | B36: 0 | C36: 50 | D36: =B36*C36 -> 0
C37: Prodeje | D37: =SUM(D26:D36) -> 152790
C38: Dotace ČSK | D38: 85000 | E38: základní dotace 65k
C39: Příjmy celkem | D39: =D37+D38 -> 237790

Sheet Náklady 2024
A1: Popis | B1: Komu | C1: Platil | D1: Kolik | E1: Kategorie | G1: Platit? | H1: Zaplaceno? | I1: platba z | J1: Kdy | K1: fa? | L1: Platby | M1: Vyúčtování | N1: TODO / Poznámka
A2: Poštovné | B2: Pošta | C2: Milan | D2: 350 | E2: pošta | F2: =IF(ISNA(VLOOKUP(E2, 'Rozpočet 2024'!$B$3:$B$21, 1, FALSE)),"!",".") -> . | G2: ano | H2: ano | I2: hotovost | J2: sobota | K2: ano | L2: =IF(G2="ano",D2,0) -> 350 | M2: =IF(K2="ano",D2,0) -> 350 | N2: v papírech z H | O2: uct_posta_2.pdf
A3: Poštovné | B3: Pošta | C3: Milan | D3: 670 | E3: pošta | F3: =IF(ISNA(VLOOKUP(E3, 'Rozpočet 2024'!$B$3:$B$21, 1, FALSE)),"!",".") -> . | G3: ano | H3: ano | I3: hotovost | J3: sobota | K3: ano | L3: =IF(G3="ano",D3,0) -> 670 | M3: =IF(K3="ano",D3,0) -> 670 | N3: v papírech z H | O3: uct_posta_1.pdf
A4: Hrázný | B4: Fučík | C4: Milan | D4: 700 | E4: Hrázný Fučík | F4: =IF(ISNA(VLOOKUP(E4, 'Rozpočet 2024'!$B$3:$B$21, 1, FALSE)),"!",".") -> . | G4: ano | H4: ano | I4: hotovost | J4: sobota | K4: ne | L4: =IF(G4="ano",D4,0) -> 700 | M4: =IF(K4="ano",D4,0) -> 0 | N4: v papírech z H
A5: Feit | B5: Dvoreček | C5: Milan | D5: 2000 | E5: Feit - louka Dvoreček | F5: =IF(ISNA(VLOOKUP(E5, 'Rozpočet 2024'!$B$3:$B$21, 1, FALSE)),"!",".") -> . | G5: ano | H5: ano | I5: hotovost | J5: sobota | K5: ne | L5: =IF(G5="ano",D5,0) -> 2000 | M5: =IF(K5="ano",D5,0) -> 0 | N5: v papírech z H
A6: Hráz vstup | B6: Boček | C6: Milan | D6: 1500 | E6: Boček hráz vstup | F6: =IF(ISNA(VLOOKUP(E6, 'Rozpočet 2024'!$B$3:$B$21, 1, FALSE)),"!",".") -> . | G6: ano | H6: ano | I6: hotovost | J6: sobota | K6: ne | L6: =IF(G6="ano",D6,0) -> 1500 | M6: =IF(K6="ano",D6,0) -> 0 | N6: v papírech z H
A7: bus Kukla | C7: Kukla | D7: 5600 | E7: bus Jan Kukla | F7: =IF(ISNA(VLOOKUP(E7, 'Rozpočet 2024'!$B$3:$B$21, 1, FALSE)),"!",".") -> . | G7: ano | H7: ano | I7: TJ účet | J7: 45608 | K7: ano | L7: =IF(G7="ano",D7,0) -> 5600 | M7: =IF(K7="ano",D7,0) -> 5600 | N7: TODO: 1) částku, 2) zaplatit, 3) doklad | O7: fa_Kukla.xls
A8: bus Kukla | C8: Kukla | D8: 95000 | E8: bus Jan Kukla | F8: =IF(ISNA(VLOOKUP(E8, 'Rozpočet 2024'!$B$3:$B$21, 1, FALSE)),"!",".") -> . | G8: ano | H8: ano | I8: hotovost | J8: 45626 | K8: ne | L8: =IF(G8="ano",D8,0) -> 95000 | M8: =IF(K8="ano",D8,0) -> 0
A9: Permice | C9: Milan | D9: 8000 | E9: permice tisk | F9: =IF(ISNA(VLOOKUP(E9, 'Rozpočet 2024'!$B$3:$B$21, 1, FALSE)),"!",".") -> . | G9: ano | H9: ano | I9: hotovost | J9: 45626 | K9: ne | L9: =IF(G9="ano",D9,0) -> 8000 | M9: =IF(K9="ano",D9,0) -> 0
A10: Samolepky splutí | C10: Milan | D10: 2000 | E10: permice tisk | F10: =IF(ISNA(VLOOKUP(E10, 'Rozpočet 2024'!$B$3:$B$21, 1, FALSE)),"!",".") -> . | G10: ano | H10: ano | I10: hotovost | J10: 45626 | K10: ne | L10: =IF(G10="ano",D10,0) -> 2000 | M10: =IF(K10="ano",D10,0) -> 0
A11: Značky doprava | C11: Kukla | D11: 2000 | E11: materiál náklady (igelity aj.) | F11: =IF(ISNA(VLOOKUP(E11, 'Rozpočet 2024'!$B$3:$B$21, 1, FALSE)),"!",".") -> . | G11: ano | H11: ano | I11: hotovost | J11: 45626 | K11: ne | L11: =IF(G11="ano",D11,0) -> 2000 | M11: =IF(K11="ano",D11,0) -> 0 | N11: Honza potvrzoval
A12: Folie, nůž | B12: Hornbach | C12: Amos | D12: 1116 | E12: materiál náklady (igelity aj.) | F12: =IF(ISNA(VLOOKUP(E12, 'Rozpočet 2024'!$B$3:$B$21, 1, FALSE)),"!",".") -> . | G12: ano | H12: ano | I12: hotovost | J12: sobota | K12: ano | L12: =IF(G12="ano",D12,0) -> 1116 | M12: =IF(K12="ano",D12,0) -> 1116 | O12: uct_Hornbach.pdf
A13: Pytle, rukavice | B13: Hornbach | C13: Amos | D13: 1581 | E13: materiál náklady (igelity aj.) | F13: =IF(ISNA(VLOOKUP(E13, 'Rozpočet 2024'!$B$3:$B$21, 1, FALSE)),"!",".") -> . | G13: ano | H13: ano | I13: hotovost | J13: sobota | K13: ano | L13: =IF(G13="ano",D13,0) -> 1581 | M13: =IF(K13="ano",D13,0) -> 1581 | O13: uct_Hornbach.pdf
A14: Auto Milan | C14: Milan | D14: 1000 | E14: cesty příprava | F14: =IF(ISNA(VLOOKUP(E14, 'Rozpočet 2024'!$B$3:$B$21, 1, FALSE)),"!",".") -> . | G14: ano | H14: ano | I14: hotovost | J14: sobota | K14: ne | L14: =IF(G14="ano",D14,0) -> 1000 | M14: =IF(K14="ano",D14,0) -> 0 | N14: v papírech z H
A15: Auto Ešus | C15: Ešus | D15: 2265 | E15: cesty příprava | F15: =IF(ISNA(VLOOKUP(E15, 'Rozpočet 2024'!$B$3:$B$21, 1, FALSE)),"!",".") -> . | G15: ano | H15: ano | I15: Air OVT | J15: 45646 | K15: ne | L15: =IF(G15="ano",D15,0) -> 2265 | M15: =IF(K15="ano",D15,0) -> 0 | N15: posláno
A16: Cesťák | B16: Ešus | C16: N | D16: 4227 | E16: cesty příprava | F16: =IF(ISNA(VLOOKUP(E16, 'Rozpočet 2024'!$B$3:$B$21, 1, FALSE)),"!",".") -> . | G16: ne | K16: ano | L16: =IF(G16="ano",D16,0) -> 0 | M16: =IF(K16="ano",D16,0) -> 4227 | N16: TODO viz mail | O16: cest_2024_Hamerák_Pavel.pdf
A17: Cesťák | B17: Bundáš | C17: N | E17: obslužná vozidla | F17: =IF(ISNA(VLOOKUP(E17, 'Rozpočet 2024'!$B$3:$B$21, 1, FALSE)),"!",".") -> . | G17: ne | L17: =IF(G17="ano",D17,0) -> 0 | M17: =IF(K17="ano",D17,0) -> 0
A18: Cesťák | B18: Štěpán | C18: N | E18: obslužná vozidla | F18: =IF(ISNA(VLOOKUP(E18, 'Rozpočet 2024'!$B$3:$B$21, 1, FALSE)),"!",".") -> . | G18: ne | L18: =IF(G18="ano",D18,0) -> 0 | M18: =IF(K18="ano",D18,0) -> 0
A19: Cesťák | B19: Adam | C19: N | D19: 2328 | E19: obslužná vozidla | F19: =IF(ISNA(VLOOKUP(E19, 'Rozpočet 2024'!$B$3:$B$21, 1, FALSE)),"!",".") -> . | G19: ne | K19: ano | L19: =IF(G19="ano",D19,0) -> 0 | M19: =IF(K19="ano",D19,0) -> 2328 | O19: cest_2024_Hamerák_Adam.pdf
A20: Cesťák | B20: Jáchym | C20: N | D20: 1740 | E20: obslužná vozidla | F20: =IF(ISNA(VLOOKUP(E20, 'Rozpočet 2024'!$B$3:$B$21, 1, FALSE)),"!",".") -> . | G20: ne | K20: ne | L20: =IF(G20="ano",D20,0) -> 0 | M20: =IF(K20="ano",D20,0) -> 0 | N20: TBD podpis | O20: cest_2024_Hamerák_Jachym.xlsx
A21: Cesťák | B21: Off | C21: N | E21: obslužná vozidla | F21: =IF(ISNA(VLOOKUP(E21, 'Rozpočet 2024'!$B$3:$B$21, 1, FALSE)),"!",".") -> . | G21: ne | L21: =IF(G21="ano",D21,0) -> 0 | M21: =IF(K21="ano",D21,0) -> 0
A22: Cesťák | B22: Hanka Riedlová | C22: N | D22: 1896 | E22: obslužná vozidla | F22: =IF(ISNA(VLOOKUP(E22, 'Rozpočet 2024'!$B$3:$B$21, 1, FALSE)),"!",".") -> . | G22: ne | K22: ano | L22: =IF(G22="ano",D22,0) -> 0 | M22: =IF(K22="ano",D22,0) -> 1896 | O22: cest_2024_Hamerák_Riedl.pdf
A23: Cesťák | B23: Libor | C23: N | D23: 1836 | E23: obslužná vozidla | F23: =IF(ISNA(VLOOKUP(E23, 'Rozpočet 2024'!$B$3:$B$21, 1, FALSE)),"!",".") -> . | G23: ne | K23: ano | L23: =IF(G23="ano",D23,0) -> 0 | M23: =IF(K23="ano",D23,0) -> 1836 | O23: cest_2024_Hamerák_Libor.pdf
A24: Auto Libor | B24: Libor | C24: Libor | D24: 1000 | E24: obslužná vozidla | F24: =IF(ISNA(VLOOKUP(E24, 'Rozpočet 2024'!$B$3:$B$21, 1, FALSE)),"!",".") -> . | G24: ano | H24: ano | I24: Air OVT | J24: 45600 | K24: ne | L24: =IF(G24="ano",D24,0) -> 1000 | M24: =IF(K24="ano",D24,0) -> 0
C25: ? | E25: obslužná vozidla | F25: =IF(ISNA(VLOOKUP(E25, 'Rozpočet 2024'!$B$3:$B$21, 1, FALSE)),"!",".") -> . | G25: ne | H25: ne | L25: =IF(G25="ano",D25,0) -> 0 | M25: =IF(K25="ano",D25,0) -> 0
A26: Hrnky potisk | C26: Milan | D26: 8442 | E26: hrnky potisk | F26: =IF(ISNA(VLOOKUP(E26, 'Rozpočet 2024'!$B$3:$B$21, 1, FALSE)),"!",".") -> . | G26: ano | H26: ano | I26: hotovost | J26: 45626 | K26: ne | L26: =IF(G26="ano",D26,0) -> 8442 | M26: =IF(K26="ano",D26,0) -> 0 | N26: Milan musí zjistit, řešil jsem s ním 19.10
A27: Motouz, provaz | B27: Kutil, provaznictví | C27: Dora | D27: =264+180 -> 444 | E27: materiál branky | F27: =IF(ISNA(VLOOKUP(E27, 'Rozpočet 2024'!$B$3:$B$21, 1, FALSE)),"!",".") -> . | G27: ano | H27: ano | I27: Air OVT | J27: 45586 | K27: ano | L27: =IF(G27="ano",D27,0) -> 444 | M27: =IF(K27="ano",D27,0) -> 444 | O27: uct_provazy_motouz.pdf
A28: Kroužek | C28: Lukáš? | D28: 120 | E28: materiál branky | F28: =IF(ISNA(VLOOKUP(E28, 'Rozpočet 2024'!$B$3:$B$21, 1, FALSE)),"!",".") -> . | G28: ano | H28: ano | I28: Air OVT | J28: 45600 | K28: ano | L28: =IF(G28="ano",D28,0) -> 120 | M28: =IF(K28="ano",D28,0) -> 120 | O28: uct_krouzek.jpg
A29: Motouz | C29: Lukáš? | D29: 1125 | E29: materiál branky | F29: =IF(ISNA(VLOOKUP(E29, 'Rozpočet 2024'!$B$3:$B$21, 1, FALSE)),"!",".") -> . | G29: ano | H29: ano | I29: Air OVT | J29: 45600 | K29: ano | L29: =IF(G29="ano",D29,0) -> 1125 | M29: =IF(K29="ano",D29,0) -> 1125 | O29: uct_motouz.jpg
A30: Rybáři | C30: TJ | D30: =15000*1.21 -> 18150 | E30: Rybáři | F30: =IF(ISNA(VLOOKUP(E30, 'Rozpočet 2024'!$B$3:$B$21, 1, FALSE)),"!",".") -> . | G30: ano | H30: ano | I30: TJ účet | J30: 45608 | K30: ano | L30: =IF(G30="ano",D30,0) -> 18150 | M30: =IF(K30="ano",D30,0) -> 18150 | N30: vloni posílali až v listopadu.. | O30: fa_Rybari.pdf
A31: Pivo | C31: Milan | D31: 3000 | E31: pivo Kamenice | F31: =IF(ISNA(VLOOKUP(E31, 'Rozpočet 2024'!$B$3:$B$21, 1, FALSE)),"!",".") -> . | G31: ano | H31: ano | I31: hotovost | J31: sobota | K31: ne | L31: =IF(G31="ano",D31,0) -> 3000 | M31: =IF(K31="ano",D31,0) -> 0 | N31: v papírech z H
A32: Chleba | B32: Pekárna Velíšek | C32: Milan | D32: 2408 | E32: náklady občerstvení | F32: =IF(ISNA(VLOOKUP(E32, 'Rozpočet 2024'!$B$3:$B$21, 1, FALSE)),"!",".") -> . | G32: ano | H32: ano | I32: hotovost | J32: sobota | K32: ano | L32: =IF(G32="ano",D32,0) -> 2408 | M32: =IF(K32="ano",D32,0) -> 2408 | N32: v papírech z H | O32: uct_chleb.pdf
A33: Občerstvení | B33: Makro | C33: Katka Křížová | D33: 4347 | E33: náklady občerstvení | F33: =IF(ISNA(VLOOKUP(E33, 'Rozpočet 2024'!$B$3:$B$21, 1, FALSE)),"!",".") -> . | G33: ano | H33: ano | I33: Air OVT | J33: 45593 | K33: ne | L33: =IF(G33="ano",D33,0) -> 4347 | M33: =IF(K33="ano",D33,0) -> 0
A34: Dřevo schody | C34: Milan | D34: 1200 | E34: schody pod hrází | F34: =IF(ISNA(VLOOKUP(E34, 'Rozpočet 2024'!$B$3:$B$21, 1, FALSE)),"!",".") -> . | G34: ano | H34: ano | I34: hotovost | J34: sobota | K34: ne | L34: =IF(G34="ano",D34,0) -> 1200 | M34: =IF(K34="ano",D34,0) -> 0
A35: Papírnictví | B35: Eso Lety | C35: Bundáš | D35: 396 | E35: materiál příprava | F35: =IF(ISNA(VLOOKUP(E35, 'Rozpočet 2024'!$B$3:$B$21, 1, FALSE)),"!",".") -> . | G35: ano | H35: ano | I35: Air OVT | J35: 45590 | K35: ano | L35: =IF(G35="ano",D35,0) -> 396 | M35: =IF(K35="ano",D35,0) -> 396 | O35: uct_Eso.pdf
A36: Baterie do comba | B36: Datart | C36: Zbyněk Herynek | D36: 198 | E36: materiál příprava | F36: =IF(ISNA(VLOOKUP(E36, 'Rozpočet 2024'!$B$3:$B$21, 1, FALSE)),"!",".") -> . | G36: ano | H36: ano | I36: Air OVT | J36: 45586 | K36: ne | L36: =IF(G36="ano",D36,0) -> 198 | M36: =IF(K36="ano",D36,0) -> 0
A37: Ubytování Ratmírov | C37: Bundáš | D37: 45600 | E37: chatky | F37: =IF(ISNA(VLOOKUP(E37, 'Rozpočet 2024'!$B$3:$B$21, 1, FALSE)),"!",".") -> . | G37: ano | H37: ano | I37: hotovost | J37: neděle | K37: ano | L37: =IF(G37="ano",D37,0) -> 45600 | M37: =IF(K37="ano",D37,0) -> 45600 | N37: v papírech z H
A38: Kelímky letos nebyly | D38: 0 | E38: výroba kelímků | F38: =IF(ISNA(VLOOKUP(E38, 'Rozpočet 2024'!$B$3:$B$21, 1, FALSE)),"!",".") -> . | G38: ne | K38: ne | L38: =IF(G38="ano",D38,0) -> 0
K40: SUM: | L40: =SUM(L2:L38) -> 210212 | M40: =SUM(M2:M38) -> 87847
I41: hotovost | J41: =SUMIF($I$2:$I$38,I41,$L$2:$L$38) -> 176567
...

Sheet Náklady 2023
A1: Popis | B1: Komu | C1: Platil | D1: Kolik | E1: Zaplaceno? | F1: Kdy | G1: Účtenka? | H1: Vyúčtování
A2: Poštovné | B2: Pošta | C2: Milan | D2: 1020 | E2: Ano, hot | F2: 45209 | G2: Ne | H2: 0
A3: Hrázný | B3: Fučík? | C3: Milan | D3: 500 | E3: Ano, hot | F3: Sobota | G3: Ne | H3: 0
A4: Ing | C4: Milan | D4: 1500 | E4: Ano, hot | F4: Sobota | G4: Ne | H4: 0
A5: Kemp parking | B5: Kemp | C5: Milan | D5: 3000 | E5: Ano, hot | F5: Sobota | G5: Ne | H5: 0
A6: Statek (Dvoreček) | C6: Milan | D6: 1500 | E6: Ano, hot | F6: Sobota | G6: Ne | H6: 0
A7: Účet | C7: Mára | D7: 800 | E7: Ano, hot | F7: Sobota | G7: Ano, fyz | H7: 790
A8: Účet | C8: Kukla | D8: 1200 | E8: Ano, hot | F8: Sobota | G8: Ano, fyz | H8: 1208
A9: Účet | C9: Milan | D9: 200 | E9: Ano, hot | F9: Sobota | G9: Ano, fyz | H9: 194.7
A10: Dřevo schody | C10: Milan | D10: 800 | E10: Ano, hot | F10: Sobota | G10: Ano, složka | H10: 796
A11: Voda manipulace | B11: Rybáři | C11: Bohemka | D11: 6050 | E11: Ano, TJ | F11: 45250 | G11: Ano, složka | H11: 6050
A12: Samolepky | B12: Samolepky | C12: Bude Milan | D12: 1100 | E12: Zatím ne | I12: počítám jako výdaj z účtu
A13: Cesťák | B13: Ešus | C13: N/A | D13: 0 | E13: Nebude | F13: 45244 | G13: Ano, složka | H13: 2863
A14: fošna hráz | B14: truhlář + kovář | C14: Milan | D14: 1500 | E14: Zatím ne | G14: ne | I14: počítám jako výdaj z účtu
A15: Autobusy | B15: Doprava Kukla | C15: Kukla | D15: 21200 | E15: Ano, TJ | G15: Ano, složka | H15: 21200
A16: Autobusy | B16: Doprava Kukla | D16: 35074 | E16: Ano, T z Air OVT
C18: sum náklady | D18: =SUM(D2:D16) -> 75444 | G18: sum náklady účt | H18: =SUM(H3:H16) -> 33101.7
C20: příjem Hamerák | D20: 61075 | G20: dotace | H20: 33000
C21: příjem dotace | D21: 33000 | G21: zbývá | H21: =H20-H18 -> -101.7 | I21: záporné OK
C22: SUM příjmy | D22: =D20+D21 -> 94075
C24: zz | D24: =D22-D18 -> 18631
