Workbook

Sheet Rozpočet H22
A2: PŘÍJMY 2022 | G2: VÝDAJE 2022
B3: Návrh pro 2022 | D3: Skutečnost v 2021 | G3: kategorie | H3: položka | J3: Návrh pro 2022 | K3: Skutečnost v 2021
B4: Příjem | C4: počet | D4: Příjem | E4: počet | G4: doprava | H4: bus Jan Kukla | I4: 102000 | J4: 105000 | K4: 95000 | L4: příjmy z dopravy + dotace 25k by měla pokrýt náklady
A5: Startovné | B5: =F26 -> 40000 | C5: =D26 -> 250 | D5: 38400 | E5: 256 | G5: doprava | H5: vlak JHMD | I5: =J5 -> 0 | J5: 0 | K5: 0 | L5: vlaky budou o cca 22000 dražší
A6: Splutí | B6: =F29 -> 58800 | C6: =SUM(D27:D29) -> 420 | D6: 51560 | E6: 419 | G6: doprava | H6: permice tisk | I6: =J6 -> 6000 | J6: 6000 | K6: 5500 | M6: ? Zaplaceno Milanovi?
A7: Permice | B7: =F32 -> 72800 | C7: =SUM(D30:D32) -> 380 | D7: 68900 | E7: 465 | G7: doprava | H7: materiál náklady (igelity aj.) | I7: =570+299 -> 869 | J7: 3000 | K7: 2000 | L7: igelity a také desinfekční prostředky
A8: Dotace ČSK | B8: =E35 -> 65000 | D8: 85000 | G8: doprava | H8: obslužná vozidla | I8: =1955+1134+1445.5 -> 4534.5 | J8: 3000 | K8: 2500
A9: Jan Kukla sponzoring | B9: 0 | D9: 0 | G9: ceny | H9: hrnky potisk | I9: 6500 | J9: 9000 | K9: 8500 | M9: ? Zaplaceno Milanovi?
A10: CELKEM | B10: =SUM(B5:B9) -> 236600 | D10: =SUM(D5:D9) -> 243860 | G10: branky | H10: materiál | I10: 2389 | J10: 1500 | K10: 1500
G11: místní poplatky | H11: Boček/kokta vstup | I11: =J11 -> 1500 | J11: 1500 | K11: 1500
G12: místní poplatky | H12: Hrázný Fučík | I12: 700 | J12: 500 | K12: 500
G13: místní poplatky | H13: Feit - louka Dvoreček | I13: 1800 | J13: 1500 | K13: 1500
G14: vodohospodářství | H14: Rybáři | I14: 14520 | J14: 16000 | K14: 14520
G15: občerstvení | H15: pivo Kamenice | I15: 4000 | J15: 5000 | K15: 5000
G16: občerstvení | H16: náklady | I16: 3005 | J16: 4000 | K16: 3000
C17: Návrh pro 2022 | D17: Skutečnost v 2021 | G17: příprava, zpracování | H17: materiál, cesty, pošta | I17: =279+179+161+139+364+500+1955 -> 3577 | J17: 9000 | K17: 10000 | M17: Toto je nejvíc aktuální tabulka pro rok 2022
B18: Příjmy | C18: =B10 -> 236600 | D18: =D10 -> 243860 | G18: ubytování | H18: chatky | I18: 50100 | J18: 48000 | K18: 45000
B19: Výdaje | C19: =-J20 -> -213000 | D19: =-K20 -> -196020 | G19: kelímky | I19: 17726
B20: CELKEM | C20: =SUM(C18:C19) -> 23600 | D20: =SUM(D18:D19) -> 47840 | G20: CELKEM | I20: =SUM(I4:I19) -> 219220.5 | J20: =SUM(J4:J18) -> 213000 | K20: =SUM(K4:K18) -> 196020
H22: změna nákladů | J22: =J20/K20-1 -> 0.086623814 | K22: =I20-K20 -> 23200.5
A25: Odhad počtu lidí | B25: Hamerák 2022 | C25: Cena 2022 | D25: Počet | E25: Součet řádek Kč | F25: Součet skupina Kč | I25: Hamerák 2022 | J25: Cena 2022 | K25: Cena 2021 | L25: Navýšení ceny 2022
A26: podle roku 2021 | B26: Závod (lidi) | C26: 160 | D26: 250 | E26: =D26*C26 -> 40000 | F26: =E26 -> 40000 | G26: závod | I26: Závod (lidi) | J26: =C26 -> 160 | K26: 150 | L26: =J26/K26-1 -> 0.066666667
B27: Splutí víkend | C27: 160 | D27: 140 | E27: =D27*C27 -> 22400 | I27: Splutí víkend | J27: =C27 -> 160 | K27: 150 | L27: =J27/K27-1 -> 0.066666667
B28: Splutí sobota | C28: 120 | D28: 140 | E28: =D28*C28 -> 16800 | I28: Splutí sobota | J28: =C28 -> 120 | K28: 100 | L28: =J28/K28-1 -> 0.2
A29: podle roku 2021 | B29: Splutí neděle | C29: 140 | D29: 140 | E29: =D29*C29 -> 19600 | F29: =SUM(E27:E29) -> 58800 | G29: splutí | I29: Splutí neděle | J29: =C29 -> 140 | K29: 120 | L29: =J29/K29-1 -> 0.16666667
B30: Permice víkend | C30: 220 | D30: 200 | E30: =D30*C30 -> 44000 | I30: Permice víkend | J30: =C30 -> 220 | K30: 200 | L30: =J30/K30-1 -> 0.1
B31: Permice sobota | C31: 160 | D31: 110 | E31: =D31*C31 -> 17600 | I31: Permice sobota | J31: =C31 -> 160 | K31: 150 | L31: =J31/K31-1 -> 0.066666667
A32: podle roku 2021 | B32: Permice neděle | C32: 160 | D32: 70 | E32: =D32*C32 -> 11200 | F32: =SUM(E30:E32) -> 72800 | G32: permice | I32: Permice neděle | J32: =C32 -> 160 | K32: 150 | L32: =J32/K32-1 -> 0.066666667
I33: Splutí a permice víkend | J33: =J27+J30 -> 380 | K33: =K27+K30 -> 350 | L33: =J33/K33-1 -> 0.085714286
D34: Prodeje | E34: =SUM(E26:E32) -> 171600 | I34: Splutí a permice sobota | J34: =J28+J31 -> 280 | K34: =K28+K31 -> 250 | L34: =J34/K34-1 -> 0.12
D35: Dotace ČSK | E35: 65000 | F35: základní dotace 65k | I35: Splutí a permice neděle | J35: =J29+J32 -> 300 | K35: =K29+K32 -> 270 | L35: =J35/K35-1 -> 0.11111111
D36: Příjmy | E36: =E34+E35 -> 236600
D37: Náklady | E37: =$J$20 -> 213000
D38: Z/Z 2022 plán | E38: =E36-E37 -> 23600
B41: REALITA
A43: Odhad počtu lidí | B43: Hamerák 2022 | C43: Cena 2022 | D43: Počet | E43: Součet řádek Kč | F43: Součet skupina Kč
A44: podle roku 2021 | B44: Závod (lidi) | C44: 160 | D44: 275 | E44: =D44*C44 -> 44000 | F44: =E44 -> 44000 | G44: závod
B45: Splutí víkend | C45: 160 | D45: 86 | E45: =D45*C45 -> 13760
B46: Splutí sobota | C46: 120 | D46: 81 | E46: =D46*C46 -> 9720
A47: podle roku 2021 | B47: Splutí neděle | C47: 140 | D47: 114 | E47: =D47*C47 -> 15960 | F47: =SUM(E45:E47) -> 39440 | G47: splutí
...

Sheet Rozpočet H21, verze 11.8.2021
A2: PŘÍJMY 2020 | G2: VÝDAJE 2020
B3: Návrh pro 2021 | D3: Skutečnost v 2019 | G3: kategorie | H3: položka | I3: Návrh pro 2021 | J3: Skutečnost v 2019
B4: Příjem | C4: počet | D4: Příjem | E4: počet | G4: doprava | H4: bus Jan Kukla | I4: 105000 | J4: 78500 | K4: příjmy z dopravy + dotace 25k by měla pokrýt náklady
A5: Startovné | B5: =F26 -> 60000 | C5: =D26 -> 300 | D5: 36000 | E5: 300 | G5: doprava | H5: vlak JHMD | I5: 30000 | J5: 8000 | K5: vlaky budou o cca 22000 dražší
A6: Splutí | B6: =F32 -> 71850 | C6: =SUM(D27:D29) -> 465 | D6: 44340 | E6: 458 | G6: doprava | H6: permice tisk | I6: 6500 | J6: 5900
A7: Permice | B7: =F29 -> 80550 | C7: =SUM(D30:D32) -> 435 | D7: 45840 | E7: 465 | G7: doprava | H7: materiál náklady (igelity aj.) | I7: 3000 | J7: 1281 | K7: igelity a také desinfekční prostředky
A8: Dotace ČSK | B8: =E34 -> 90000 | D8: 75000 | G8: doprava | H8: obslužná vozidla | I8: 3000 | J8: 2858
A9: Jan Kukla sponzoring | B9: 0 | D9: 10000 | G9: ceny | H9: hrnky potisk | I9: 6000 | J9: 6100
A10: CELKEM | B10: =SUM(B5:B9) -> 302400 | D10: =SUM(D5:D9) -> 211180 | G10: branky | H10: materiál | I10: 1000 | J10: 1029
G11: místní poplatky | H11: Boček/kokta vstup | I11: 1500 | J11: 1500
G12: místní poplatky | H12: Hrázný Fučík | I12: 500 | J12: 500
G13: místní poplatky | H13: Feit - louka Dvoreček | I13: 1500 | J13: 1500
G14: vodohospodářství | H14: Rybáři | I14: 12100 | J14: 12100
G15: občerstvení | H15: pivo Kamenice | I15: 5000 | J15: 5000
G16: občerstvení | H16: náklady | I16: 4000 | J16: 3618
C17: Návrh pro 2021 | D17: Skutečnost v 2019 | G17: příprava, zpracování | H17: materiál, cesty, pošta | I17: 9000 | J17: =10798+418+1946 -> 13162
B18: Příjmy | C18: =B10 -> 302400 | D18: =D10 -> 211180 | G18: ubytování | H18: chatky | I18: 45000 | J18: 37600
B19: Výdaje | C19: =-I20 -> -233100 | D19: =-J20 -> -178648
B20: CELKEM | C20: =SUM(C18:C19) -> 69300 | D20: =SUM(D18:D19) -> 32532 | G20: CELKEM | I20: =SUM(I4:I18) -> 233100 | J20: =SUM(J4:J18) -> 178648
A25: Odhad počtu lidí | B25: Hamerák 2021 | C25: Cena | D25: Počet | E25: Součet řádek Kč | F25: Součet skupina Kč
A26: podle roku 2019 | B26: Závod (lidi) | C26: 200 | D26: 300 | E26: =D26*C26 -> 60000 | F26: =E26 -> 60000 | G26: závod
B27: Permice víkend | C27: 200 | D27: 216 | E27: =D27*C27 -> 43200
B28: Permice sobota | C28: 150 | D28: 117 | E28: =D28*C28 -> 17550
A29: podle roku 2019 | B29: Permice neděle | C29: 150 | D29: 132 | E29: =D29*C29 -> 19800 | F29: =SUM(E27:E29) -> 80550 | G29: permice | H29: cílem je mít příjmy z dopravy > 80.000,- Kč (105k náklady autobusy mínus 25k dotace)
B30: Splutí víkend | C30: 200 | D30: 132 | E30: =D30*C30 -> 26400
B31: Splutí sobota | C31: 150 | D31: 90 | E31: =D31*C31 -> 13500
A32: podle roku 2019 | B32: Splutí neděle | C32: 150 | D32: 213 | E32: =D32*C32 -> 31950 | F32: =SUM(E30:E32) -> 71850 | G32: splutí
D33: Prodeje | E33: =SUM(E26:E32) -> 212400
D34: Dotace ČSK | E34: =65000+25000 -> 90000 | F34: základní dotace 65k, navíc dotace na dopravu 25k
D35: Příjmy | E35: =E33+E34 -> 302400
D36: Náklady | E36: =I20 -> 233100
D37: Z/Z 2021 plán | E37: =E35-E36 -> 69300

Sheet Návrh rozpočtu, verze 2.6.2021
A2: PŘÍJMY 2020 | G2: VÝDAJE 2020
B3: Návrh pro 2021 | D3: Skutečnost v 2019 | G3: kategorie | H3: položka | I3: Návrh pro 2021 | J3: Skutečnost v 2019
B4: Příjem | C4: počet | D4: Příjem | E4: počet | G4: doprava | H4: bus Jan Kukla | I4: 120000 | J4: 78500
A5: Startovné | B5: ='Ceny Hamerák 2019 vs 2020'!N3 -> 59400 | C5: ='Ceny Hamerák 2019 vs 2020'!K3 -> 330 | D5: 36000 | E5: 300 | G5: doprava | H5: vlak JHMD | I5: 30000 | J5: 8000
A6: Splutí | B6: ='Ceny Hamerák 2019 vs 2020'!N9 -> 66132 | C6: ='Ceny Hamerák 2019 vs 2020'!K7+'Ceny Hamerák 2019 vs 2020'!K8+'Ceny Hamerák 2019 vs 2020'!K9 -> 478.5 | D6: 44340 | E6: 458 | G6: doprava | H6: permice tisk | I6: 6000 | J6: 5900
A7: Permice | B7: ='Ceny Hamerák 2019 vs 2020'!N6 -> 61884 | C7: ='Ceny Hamerák 2019 vs 2020'!K4+'Ceny Hamerák 2019 vs 2020'!K5+'Ceny Hamerák 2019 vs 2020'!K6 -> 418.5 | D7: 45840 | E7: 465 | G7: doprava | H7: materiál náklady (igelity aj.) | I7: 1200 | J7: 1281
A8: Dotace ČSK | B8: 65000 | D8: 75000 | G8: doprava | H8: obslužná vozidla | I8: 3000 | J8: 2858
A9: Jan Kukla sponzoring | B9: 0 | D9: 10000 | G9: ceny | H9: hrnky potisk | I9: 6000 | J9: 6100
A10: CELKEM | B10: =SUM(B5:B9) -> 252416 | D10: =SUM(D5:D9) -> 211180 | G10: branky | H10: materiál | I10: 1000 | J10: 1029
G11: místní poplatky | H11: Boček/kokta vstup | I11: 1500 | J11: 1500
G12: místní poplatky | H12: Hrázný Fučík | I12: 500 | J12: 500
G13: místní poplatky | H13: Feit - louka Dvoreček | I13: 1500 | J13: 1500
G14: vodohospodářství | H14: Rybáři | I14: 12100 | J14: 12100
G15: občerstvení | H15: pivo Kamenice | I15: 5000 | J15: 5000
G16: občerstvení | H16: náklady | I16: 4000 | J16: 3618
C17: Návrh pro 2021 | D17: Skutečnost v 2019 | G17: příprava, zpracování | H17: materiál, cesty, pošta | I17: 9000 | J17: =10798+418+1946 -> 13162
B18: Příjmy | C18: =B10 -> 252416 | D18: =D10 -> 211180 | G18: ubytování | H18: chatky | I18: 45000 | J18: 37600
B19: Výdaje | C19: =-I20 -> -245800 | D19: =-J20 -> -178648
B20: CELKEM | C20: =SUM(C18:C19) -> 6616 | D20: =SUM(D18:D19) -> 32532 | G20: CELKEM | I20: =SUM(I4:I18) -> 245800 | J20: =SUM(J4:J18) -> 178648

Sheet Návrh rozpočtu, verze 23.6.2020
A2: PŘÍJMY 2020 | G2: VÝDAJE 2020
B3: Návrh pro 2020 | D3: Skutečnost v 2019 | G3: kategorie | H3: položka | I3: Návrh pro 2020 | J3: Skutečnost v 2019
B4: Příjem | C4: počet | D4: Příjem | E4: počet | G4: doprava | H4: bus Jan Kukla | I4: 80000 | J4: 78500
A5: Startovné | B5: ='Ceny Hamerák 2019 vs 2020'!N3 -> 59400 | C5: ='Ceny Hamerák 2019 vs 2020'!K3 -> 330 | D5: 36000 | E5: 300 | G5: doprava | H5: vlak JHMD | I5: 30000 | J5: 8000
A6: Splutí | B6: ='Ceny Hamerák 2019 vs 2020'!N9 -> 66132 | C6: ='Ceny Hamerák 2019 vs 2020'!K7+'Ceny Hamerák 2019 vs 2020'!K8+'Ceny Hamerák 2019 vs 2020'!K9 -> 478.5 | D6: 44340 | E6: 458 | G6: doprava | H6: permice tisk | I6: 6000 | J6: 5900
A7: Permice | B7: ='Ceny Hamerák 2019 vs 2020'!N6 -> 61884 | C7: ='Ceny Hamerák 2019 vs 2020'!K4+'Ceny Hamerák 2019 vs 2020'!K5+'Ceny Hamerák 2019 vs 2020'!K6 -> 418.5 | D7: 45840 | E7: 465 | G7: doprava | H7: materiál náklady (igelity aj.) | I7: 1200 | J7: 1281
A8: Dotace ČSK | B8: 65000 | D8: 75000 | G8: doprava | H8: obslužná vozidla | I8: 3000 | J8: 2858
A9: Jan Kukla sponzoring | B9: 0 | D9: 10000 | G9: ceny | H9: hrnky potisk | I9: 6000 | J9: 6100
A10: CELKEM | B10: =SUM(B5:B9) -> 252416 | D10: =SUM(D5:D9) -> 211180 | G10: branky | H10: materiál | I10: 1000 | J10: 1029
G11: místní poplatky | H11: Boček/kokta vstup | I11: 1500 | J11: 1500
G12: místní poplatky | H12: Hrázný Fučík | I12: 500 | J12: 500
G13: místní poplatky | H13: Feit - louka Dvoreček | I13: 1500 | J13: 1500
G14: vodohospodářství | H14: Rybáři | I14: 12100 | J14: 12100
G15: občerstvení | H15: pivo Kamenice | I15: 5000 | J15: 5000
G16: občerstvení | H16: náklady | I16: 4000 | J16: 3618
C17: Návrh pro 2020 | D17: Skutečnost v 2019 | G17: příprava, zpracování | H17: materiál, cesty, pošta | I17: 9000 | J17: =10798+418+1946 -> 13162
B18: Příjmy | C18: =B10 -> 252416 | D18: =D10 -> 211180 | G18: ubytování | H18: chatky | I18: 40000 | J18: 37600
B19: Výdaje | C19: =-I20 -> -200800 | D19: =-J20 -> -178648
B20: CELKEM | C20: =SUM(C18:C19) -> 51616 | D20: =SUM(D18:D19) -> 32532 | G20: CELKEM | I20: =SUM(I4:I18) -> 200800 | J20: =SUM(J4:J18) -> 178648

Sheet Ceny Hamerák 2019 vs 2020
B2: Hamerák 2019 | C2: Počet | D2: Cena | E2: Součet Kč | I2: Odhad počtu lidí | J2: Hamerák 2021 | K2: Počet | L2: Cena | M2: Součet Kč
B3: Závod (lidi) | C3: 300 | D3: 120 | E3: =C3*D3 -> 36000 | F3: =E3 -> 36000 | G3: závod | I3: +10% | J3: Závod (lidi) | K3: =C3*1.1 -> 330 | L3: 180 | M3: =K3*L3 -> 59400 | N3: =M3 -> 59400 | O3: závod
B4: Permice víkend | C4: 216 | D4: 120 | E4: =C4*D4 -> 25920 | J4: Permice víkend | K4: =C4*0.9 -> 194.4 | L4: 180 | M4: =K4*L4 -> 34992
B5: Permice sobota | C5: 117 | D5: 80 | E5: =C5*D5 -> 9360 | J5: Permice sobota | K5: =C5*0.9 -> 105.3 | L5: 120 | M5: =K5*L5 -> 12636
B6: Permice neděle | C6: 132 | D6: 80 | E6: =C6*D6 -> 10560 | F6: =E4+E5+E6 -> 45840 | G6: permice | I6: -0.1 | J6: Permice neděle | K6: =C6*0.9 -> 118.8 | L6: 120 | M6: =K6*L6 -> 14256 | N6: =M4+M5+M6 -> 61884 | O6: permice
B7: Splutí víkend | C7: 132 | D7: 120 | E7: =C7*D7 -> 15840 | J7: Splutí víkend | K7: =C7*1.1 -> 145.2 | L7: 180 | M7: =K7*L7 -> 26136
B8: Splutí sobota | C8: 90 | D8: 80 | E8: =C8*D8 -> 7200 | J8: Splutí sobota | K8: =C8*1.1 -> 99 | L8: 120 | M8: =K8*L8 -> 11880
B9: Splutí neděle | C9: 213 | D9: 100 | E9: =C9*D9 -> 21300 | F9: =E7+E8+E9 -> 44340 | G9: splutí | I9: +10% | J9: Splutí neděle | K9: =C9*1.1 -> 234.3 | L9: 120 | M9: =K9*L9 -> 28116 | N9: =M7+M8+M9 -> 66132 | O9: splutí
D10: prodeje | E10: =SUM(E3:E9) -> 126180 | L10: prodeje | M10: =SUM(M3:M9) -> 187416
D11: dotace+spo | E11: 85000 | L11: dotace+spo | M11: 65000 | N11: základní dotace 65k a není sponzoring J. Kukla
D12: příjmy | E12: =E10+E11 -> 211180 | L12: příjmy | M12: =M10+M11 -> 252416
D13: náklady | E13: 178648 | L13: náklady | M13: ='Návrh rozpočtu, verze 23.6.2020'!I20 -> 200800 | N13: vlaky budou o cca 22000 dražší
D14: Z/Z 2019 | E14: =E12-E13 -> 32532 | L14: Z/Z 2020 plán | M14: =M12-M13 -> 51616
B19: Náklady | I19: Odhad počtu lidí | J19: Hamerák splutí 2020 | K19: Počet | L19: Cena | M19: Součet Kč
B20: Var. 2020 bez závodu | C20: Účel | D20: Kategorie | I20: +10% | J20: Závod (lidi) | K20: 0 | L20: 150 | M20: =K20*L20 -> 0 | N20: 49500 | O20: závod
B21: 4000 | C21: Ubytování v kempu - chatky | D21: Ubytování | J21: Permice víkend | K21: 200 | L21: 150 | M21: =K21*L21 -> 30000
B22: 3000 | C22: úklid autobusů, ochrana sedaček, atd. | D22: Doprava | J22: Permice sobota | K22: 100 | L22: 100 | M22: =K22*L22 -> 10000
B23: 1500 | C23: Boček/Kokta pronájem kolem vstupu | D23: Místní | I23: -0.15 | J23: Permice neděle | K23: 100 | L23: 100 | M23: =K23*L23 -> 10000 | N23: 48705 | O23: permice
B24: 500 | C24: Hrázný Fučík | D24: Místní | J24: Splutí víkend | K24: 200 | L24: 150 | M24: =K24*L24 -> 30000
B25: 1500 | C25: Feit - Louka na výstupu Dvoreček | D25: Místní | J25: Splutí sobota | K25: 100 | L25: 100 | M25: =K25*L25 -> 10000
B26: 60000 | C26: Doprava, 2 autobusy pro obsluhu Dvoreček a Jindřiš v sobotu a neděli | D26: Doprava | I26: +10% | J26: Splutí neděle | K26: 100 | L26: 100 | M26: =K26*L26 -> 10000 | N26: 59796 | O26: splutí
B27: 12100 | C27: Rybáři | D27: Místní | L27: prodeje | M27: =SUM(M20:M26) -> 100000
B28: 5000 | C28: Tisk permice | D28: Doprava | L28: dotace+spo | M28: 65000 | N28: základní dotace 65k a není sponzoring J. Kukla
B29: 2000 | C29: Další náklady (+ rezerva) | D29: Příprava | L29: příjmy | M29: 223001
B30: =SUM(B21:B29) -> 89600 | C30: Celkem | L30: náklady | M30: 200800 | N30: vlaky budou o cca 22000 dražší
C31: případně doprava 3 busy za 80 tisíc, tedy + 20.000,- Kč (nutno potvrdit s Honzou) | L31: Z/Z 2020 plán | M31: 22201

Sheet Prodeje závod, permice a splutí
A2: Pokladna 1 - Závod a splutí | G2: Pokladna 2 - permice
B3: Sobota | H3: Sobota
B4: Otevření | D4: Prodáno | H4: Otevření | J4: Prodáno
A5: Závod | D5: 300 | G5: Permice víkend: | H5: 200 | J5: 118
G6: Permice sobota: | H6: 200 | J6: 65
A7: Splutí víkend: | D7: 10 | G7: Splutí víkend: | H7: 0 | J7: 0
A8: Splutí sobota: | D8: 21 | G8: Splutí sobota: | H8: 0 | J8: 0
A10: Pokladna 3 - Hráz
B11: Sobota | G11: Neděle
B12: Otevření | C12: Během dne doplněno | D12: Prodáno | E12: Oprávky | H12: Otevření | I12: Během dne doplněno | J12: Prodáno | K12: Oprávky
A13: Permice víkend: | B13: 100 | C13: 80 | D13: 98 | G13: Permice víkend: | H13: 82 | I13: 100 | J13: 132
A14: Permice sobota: | B14: 100 | C14: 0 | D14: 52 | G14: Permice sobota: | H14: 48
A15: Splutí víkend: | B15: 257 | C15: 120 | D15: 132 | E15: 10 | G15: Splutí víkend: | H15: 245 | I15: 108 | J15: 226 | K15: 13
A16: Splutí sobota: | B16: 180 | C16: 120 | D16: 69 | G16: Splutí sobota: | H16: 231
