Workbook

Sheet Příjmy old
A1: Ceny - nastavení | E1: Hotovost | J1: Dotace & sponzoring
B2: Sobota | C2: Neděle | E2: Vstupní hotovost | H2: =40000+15000 -> 55000 | J2: ČPV Hamerák | L2: 65000
A3: Závod | B3: 150 | E3: Výstupní hotovost z pokladen | H3: =G12-B12+N12-I12+G23-B23+M23-H23 -> 158947 | J3: ČPV Hameráček | L3: 25000 | M3: část do Hradce
A4: Permice víkend: | B4: 200 | C4: 150 | E4: Příjem z prodeje | H4: =G12-C12-B12+N12-J12-I12+G23-C23-B23+M23-I23-H23+B42 -> 158947 | J4: Kukabus | L4: 0
A5: Permice sobota: | B5: 150 | E5: Celkem hotovost | H5: =H2+H4 -> 213947
A6: Splutí víkend: | B6: 150 | C6: 120
A7: Splutí sobota: | B7: 100
A9: Pokladna 1 - Závod a splutí | D9: Modrá | F9: Milan a Klem | H9: Pokladna 2 - permice | K9: Červená stará | M9: Jana Bau | O9: Pokladna 3 - kelímky | R9: Červená nová | T9: Bára a Terka
B10: Modrá | I10: Červená stará | P10: Červená nová
B11: Otevření | C11: Během dne | D11: Prodáno | E11: Oprávky | F11: Výdělek | G11: Uzavření | I11: Otevření | J11: Během dne | K11: Prodáno | L11: Oprávky | M11: Výdělek | N11: Uzavření | P11: Otevření | Q11: Během dne | R11: Prodáno | S11: Oprávky | T11: Výdělek | U11: Uzavření
A12: Peníze: | B12: 10000 | C12: 0 | G12: 57950 | H12: Peníze: | I12: 5000 | J12: 0 | N12: =43250+1200 -> 44450 | O12: Peníze: | P12: 5000 | Q12: 0 | U12: 12750
A13: Závod | B13: 0 | C13: 0 | D13: 256 | F13: =(D13-E13)*$B$3 -> 38400 | H13: Permice víkend: | I13: 200 | J13: 0 | K13: 149 | M13: =(K13-L13)*$B$4 -> 29800 | N13: 82 | O13: Kelímky | P13: 143 | Q13: 0 | R13: =143-73 -> 70 | S13: 3 | T13: =(R13-S13)*50 -> 3350 | U13: 82
H14: Permice sobota: | I14: 200 | J14: 0 | K14: 64 | M14: =(K14-L14)*$B$5 -> 9600 | N14: 135 | O14: Žetony | P14: 400 | Q14: 0 | R14: =400-312 -> 88 | T14: =(R14-S14)*50 -> 4400 | U14: 135
A15: Splutí víkend: | B15: 0 | C15: 0 | D15: =309-D13 -> 53 | E15: 6 | F15: =(D15-E15)*$B$6 -> 7050 | G15: 0 | H15: Splutí víkend: | I15: 0 | J15: 0 | K15: =I15-N15 -> 0 | M15: =(K15-L15)*$B$6 -> 0 | N15: 0 | P15: 0 | Q15: 0 | R15: =P15-U15 -> 0 | T15: =(R15-S15)*$B$6 -> 0 | U15: 0
A16: Splutí sobota: | B16: 0 | C16: 0 | D16: 25 | F16: =(D16-E16)*$B$7 -> 2500 | G16: 0 | H16: Splutí sobota: | I16: 0 | J16: 0 | K16: =I16-N16 -> 0 | M16: =(K16-L16)*$B$7 -> 0 | N16: 0 | P16: 0 | Q16: 0 | R16: =P16-U16 -> 0 | T16: =(R16-S16)*$B$7 -> 0 | U16: 0
A17: Součet: | E17: =D17+SUM(E12:E16) -> 6 | F17: =SUM(F13:F16) -> 47950 | G17: =B12+C12+F17 -> 57950 | H17: Součet: | M17: =SUM(M13:M16) -> 39400 | N17: =I12+J12+M17 -> 44400 | O17: Součet: | T17: =SUM(T13:T16) -> 7750 | U17: =P12+Q12+T17 -> 12750
A18: Rozdíl: | G18: =G12-G17 -> 0 | H18: Rozdíl: | N18: =N12-N17 -> 50 | O18: Rozdíl: | U18: =U12-U17 -> 0
A20: Pokladna 3 - Hráz | D20: Modrá | F20: Bundáš | L20: Bundáš
B21: Sobota | H21: Neděle
B22: Otevření | C22: Během dne | D22: Prodáno | E22: Oprávky | F22: Výdělek | G22: Uzavření | H22: Otevření | I22: Během dne | J22: Prodáno | K22: Oprávky | L22: Výdělek | M22: Uzavření
A23: Peníze: | B23: 10000 | G23: =51780+2070 -> 53850 | H23: 10000 | I23: 0 | M23: 37697
A24: Permice víkend: | B24: 200 | D24: 56 | F24: =(D24-E24)*$B$4 -> 11200 | G24: =B24+C24-D24 -> 144 | H24: 200 | J24: 74 | L24: =(J24-K24)*$C$4 -> 11100 | M24: =H24+I24-J24 -> 126
A25: Permice sobota: | B25: 200 | D25: 48 | F25: =(D25-E25)*$B$5 -> 7200 | G25: =B25+C25-D25 -> 152 | L25: =(J25-K25)*$C$5 -> 0 | M25: =H25+I25-J25 -> 0
A26: Splutí víkend: | B26: 200 | D26: 93 | E26: 2 | F26: =(D26-E26)*$B$6 -> 13650 | G26: =B26+C26-D26 -> 107 | H26: 400 | J26: 154 | K26: 16 | L26: =(J26-K26)*$C$6 -> 16560 | M26: =H26+I26-J26-K26 -> 230
A27: Splutí sobota: | B27: 200 | D27: 119 | E27: 1 | F27: =D27*$B$7 -> 11900 | G27: =B27+C27-D27 -> 81 | L27: =J27*$C$7 -> 0 | M27: =H27+I27-J27 -> 0
A28: Součet: | F28: =SUM(F24:F27) -> 43950 | G28: =B23+C23+F28 -> 53950 | K28: =J28+SUM(K23:K27) -> 16 | L28: =SUM(L24:L27) -> 27660 | M28: =H23+I23+L28 -> 37660
A29: Rozdíl: | G29: =G23-G28 -> -100 | M29: =M23-M28 -> 37
A39: Ostatní příjmy
A40: Revizor 1 - Jana | B40: 0
A41: Revizor 2 - Evka | B41: 0
A42: Celkem ostatní | B42: =B40+B41 -> 0
A44: Prodeje - součty | F44: Příjmy - kategorie | J44: Příjmy 2019 | N44: Rozdíl
A45: Závod (lidi) | B45: =D13 -> 256 | F45: Startovné | H45: =F13 -> 38400 | J45: Startovné | L45: 36000 | N45: =H45-L45 -> 2400
A46: Permice víkend | B46: =K13+D24 -> 205 | C46: Splutí víkend | D46: =D15+D26 -> 146 | F46: Permice | H46: =M13+M14+F24+F25+L24 -> 68900 | J46: Permice | L46: 45840 | N46: =H46-L46 -> 23060
A47: Permice sobota | B47: =K14+D25 -> 112 | C47: Splutí sobota | D47: =D16+D27 -> 144 | F47: Splutí | H47: =F15+F16+F26+F27+L26 -> 51660 | J47: Splutí | L47: 44340 | N47: =H47-L47 -> 7320
A48: Permice neděle | B48: =J24 -> 74 | C48: Splutí neděle | D48: =J26 -> 154 | F48: Dotace a sponzoring | H48: =SUM(L2:L5) -> 90000 | J48: Dotace a sponzoring | L48: 90000 | N48: =H48-L48 -> 0
F49: Celkem | H49: =SUM(H45:H48) -> 248960 | J49: Celkem | L49: 216180 | N49: =H49-L49 -> 32780
A53: Hamerák 19 | B53: Počet | C53: Cena | D53: Součet Kč
A54: Závod (lidi) | B54: 300 | C54: 120 | D54: 36000
A55: Permice víkend | B55: 216 | C55: 120 | D55: 25920
...

Sheet Výdaje old
A1: ID | B1: Datum | C1: Čas | D1: Kategorie | E1: Osoba | F1: Účel | G1: Doklad | H1: Částka | I1: Forma | J1: Zdroj | K1: Vyplaceno | L1: Záloha | M1: Zůstatek | N1: Poznámka pro Pavelkovou | O1: Sken/dokument | P1: Celkové vyúčtování
A2: 1 | B2: 43743 | C2: 0.6875 | D2: Místní | E2: Ešus | F2: Záloha na místní poplatky | G2: ne | I2: Hotově | J2: Hamerák | K2: Ano | L2: 4000 | M2: ='Příjmy old'!H5-IF(AND(I2="Hotově",J2="Hamerák"),H2+L2) -> 209947 | P2: Y - hotově
A3: 2 | B3: 43743 | C3: 0.70833333 | D3: Ubytování | E3: Bundáš | F3: Ubytování v kempu - chatky | G3: ano | H3: 37600 | I3: Hotově | J3: Hamerák | K3: Ano | M3: =M2-IF(AND(I3="Hotově",J3="Hamerák"),H3+L3) -> 172347 | N3: Ubytování | P3: Y - hotově
A4: 3 | B4: 43744 | C4: 0.625 | D4: Doprava | E4: Amos | F4: Igelity do autobusu | G4: ano | H4: 1281 | I4: Hotově | J4: Hamerák | K4: Ano | M4: =M3-IF(AND(I4="Hotově",J4="Hamerák"),H4+L4) -> 171066 | N4: Nákup materiálu pro ČPV Hamercký potok | P4: Y - hotově
A5: 4 | B5: 43744 | C5: 0.625 | D5: Místní | E5: Ešus | F5: Vyúčtování zálohy na místní poplatky | G5: ne | I5: Hotově | J5: Hamerák | K5: Ano | L5: -4000 | M5: =M4-IF(AND(I5="Hotově",J5="Hamerák"),H5+L5) -> 175066 | P5: Y - hotově
A6: 5 | B6: 43744 | C6: 0.625 | D6: Místní | E6: Ešus | F6: Boček/Kokta pronájem kolem vstupu | G6: ne | H6: 1500 | I6: Hotově | J6: Hamerák | K6: Ano | M6: =M5-IF(AND(I6="Hotově",J6="Hamerák"),H6+L6) -> 173566 | P6: Y - hotově
A7: 6 | B7: 43744 | C7: 0.625 | D7: Místní | E7: Ešus | F7: Hrázný Fučík | G7: ne | H7: 500 | I7: Hotově | J7: Hamerák | K7: Ano | M7: =M6-IF(AND(I7="Hotově",J7="Hamerák"),H7+L7) -> 173066 | P7: Y - hotově
A8: 7 | B8: 43744 | C8: 0.625 | D8: Místní | E8: Ešus | F8: Feit - Louka na výstupu Dvoreček | G8: ne | H8: 1500 | I8: Hotově | J8: Hamerák | K8: Ano | M8: =M7-IF(AND(I8="Hotově",J8="Hamerák"),H8+L8) -> 171566 | P8: Y - hotově
A9: 8 | B9: 43744 | C9: 0.625 | D9: Příprava | E9: Ešus | F9: Nafta do auta (2x) | G9: ano-vyřaď | H9: 2572 | I9: Hotově | J9: Hamerák | K9: Ano | M9: =M8-IF(AND(I9="Hotově",J9="Hamerák"),H9+L9) -> 168994 | N9: Nákup materiálu pro ČPV Hamercký potok | P9: Y - hotově
A10: 9 | B10: 43744 | C10: 0.625 | D10: Dotace | E10: Ešus | F10: Část dotace pro Hradečáky | G10: ne | H10: 4500 | I10: Hotově | J10: Hamerák | K10: Ano | M10: =M9-IF(AND(I10="Hotově",J10="Hamerák"),H10+L10) -> 164494 | P10: Y - hotově
A11: 10 | B11: 43744 | C11: 0.625 | D11: Občerstvení | E11: Milan | F11: Chleba | G11: ano | H11: 1811 | I11: Hotově | J11: Hamerák | K11: Ano | M11: =M10-IF(AND(I11="Hotově",J11="Hamerák"),H11+L11) -> 162683 | N11: Stravování | P11: Y - hotově
A12: 11 | B12: 43744 | C12: 0.625 | D12: Občerstvení | E12: Milan | F12: Pivovar Kamenice | G12: ne | H12: 5000 | I12: Hotově | J12: Hamerák | K12: Ano | M12: =M11-IF(AND(I12="Hotově",J12="Hamerák"),H12+L12) -> 157683 | P12: Y - hotově
A13: 12 | B13: 43744 | C13: 0.625 | D13: Ceny | E13: Milan | F13: Záloha Hrnky | G13: ne | I13: Hotově | J13: Hamerák | K13: Ano | L13: 7000 | M13: =M12-IF(AND(I13="Hotově",J13="Hamerák"),H13+L13) -> 150683 | P13: Y - hotově
A14: 13 | B14: 43744 | C14: 0.625 | D14: Doprava | E14: Milan | F14: Záloha Permice | G14: ne | I14: Hotově | J14: Hamerák | K14: Ano | L14: 5000 | M14: =M13-IF(AND(I14="Hotově",J14="Hamerák"),H14+L14) -> 145683 | P14: Y - hotově
A15: 14 | B15: 43744 | C15: 0.625 | D15: Občerstvení | E15: Štěpán | F15: Občerstvení náklady (Makro) | G15: ano-vyřaď | H15: 1507.17 | I15: Hotově | J15: Hamerák | K15: Ano | M15: =M14-IF(AND(I15="Hotově",J15="Hamerák"),H15+L15) -> 144175.83 | N15: Nákup materiálu pro ČPV Hamercký potok | P15: Y - hotově
A16: 15 | B16: 43744 | C16: 0.625 | D16: Občerstvení | E16: Štěpán | F16: Občerstvení náklady (Albert) | G16: ano | H16: 171.5 | I16: Hotově | J16: Hamerák | K16: Ano | M16: =M15-IF(AND(I16="Hotově",J16="Hamerák"),H16+L16) -> 144004.33 | N16: Nákup materiálu pro ČPV Hamercký potok | P16: Y - hotově
A17: 16 | B17: 43744 | C17: 0.625 | D17: Občerstvení | E17: Štěpán | F17: Občerstvení náklady | G17: x | H17: =1806.67-1507.17-171.5 -> 128 | I17: Hotově | J17: Hamerák | K17: Ano | M17: =M16-IF(AND(I17="Hotově",J17="Hamerák"),H17+L17) -> 143876.33 | N17: Nákup materiálu pro ČPV Hamercký potok | P17: Y - hotově
A18: 17 | B18: 43744 | C18: 0.625 | D18: Doprava | E18: Mára | F18: Vlak jízdenky | G18: ne | H18: 2000 | I18: Hotově | J18: Hamerák | K18: Ano | M18: =M17-IF(AND(I18="Hotově",J18="Hamerák"),H18+L18) -> 141876.33 | P18: Y - hotově
A19: 18 | B19: 43744 | C19: 0.625 | D19: Doprava | E19: Mára | F19: Vlak jízdenky | G19: ano | H19: 1680 | I19: Doklad | J19: Hamerák | K19: Ne | M19: =M18-IF(AND(I19="Hotově",J19="Hamerák"),H19+L19) -> 141876.33 | N19: Náklady JHMD, pronájem vlaku
A20: 19 | B20: 43746 | C20: 0.45833333 | D20: Doprava | E20: J.Kukla | F20: Autobusy | G20: ne | H20: 68500 | I20: Hotově | J20: Hamerák | K20: Ano | M20: =M19-IF(AND(I20="Hotově",J20="Hamerák"),H20+L20) -> 73376.33 | P20: Y - hotově
A21: 20 | B21: 43746 | C21: 0.45833333 | D21: Dotace | E21: J.Kukla | F21: Autobusy | G21: ne | H21: 10000 | I21: Dotace | J21: Dotace | K21: Ano | M21: =M20-IF(AND(I21="Hotově",J21="Hamerák"),H21+L21) -> 73376.33 | P21: Y - sleva na hotovosti J. Kukla
A22: 21 | B22: 43675 | D22: Příprava | E22: Ešus | F22: Poštovné | G22: ne | H22: 247 | I22: Převod | J22: Air OVT | K22: Ano | M22: =M21-IF(AND(I22="Hotově",J22="Hamerák"),H22+L22) -> 73376.33 | P22: Y - 29.7.
A23: 22 | B23: 43675 | D23: Příprava | E23: Ešus | F23: Tričko pro rybáře | G23: ne | H23: 114 | I23: Převod | J23: Air OVT | K23: Ano | M23: =M22-IF(AND(I23="Hotově",J23="Hamerák"),H23+L23) -> 73376.33 | P23: Y - 29.7.
A24: 23 | B24: 43675 | D24: Příprava | E24: Bundáš | F24: Papírnictví | G24: ano | H24: 443 | I24: Převod | J24: Air OVT | K24: Ano | M24: =M23-IF(AND(I24="Hotově",J24="Hamerák"),H24+L24) -> 73376.33 | N24: Nákup materiálu pro ČPV Hamercký potok | P24: Y - 27.9.
A25: 24 | B25: 43675 | D25: Příprava | E25: Tomík | F25: Nůžkový stan | G25: ne | H25: 3033 | I25: Převod | J25: Air OVT | K25: Ano | M25: =M24-IF(AND(I25="Hotově",J25="Hamerák"),H25+L25) -> 73376.33 | P25: Y - 27.9.
A26: 25 | B26: 43675 | D26: Doprava | E26: N/A | F26: JHMD faktura | G26: ano | H26: 6000 | I26: Převod | J26: TJ | K26: Ano | M26: =M25-IF(AND(I26="Hotově",J26="Hamerák"),H26+L26) -> 73376.33 | N26: Náklady JHMD, pronájem vlaku | P26: Y - 4.10.
A27: 26 | B27: 43675 | D27: Místní | E27: N/A | F27: Rybáři | G27: ano | H27: 12100 | I27: Převod | J27: TJ | K27: Ano | M27: =M26-IF(AND(I27="Hotově",J27="Hamerák"),H27+L27) -> 73376.33 | N27: Manipulace na vodních dílech ryb. Ratmírovský | P27: Y - 24.10.
A28: 27 | B28: 43752 | D28: Sponzoři | E28: Ešus | F28: poslání bannerů do Brna a do Č. Budějovic | G28: ? | H28: 418 | I28: Převod | J28: Air OVT | K28: Ano | M28: =M27-IF(AND(I28="Hotově",J28="Hamerák"),H28+L28) -> 73376.33 | P28: Y - 14.10.
A29: 28 | B29: 43752 | D29: Branky | E29: Roman | F29: Kondor - vázací drát | G29: ano | H29: 662 | I29: Převod | J29: Air OVT | K29: Ano | M29: =M28-IF(AND(I29="Hotově",J29="Hamerák"),H29+L29) -> 73376.33 | N29: Nákup materiálu pro ČPV Hamercký potok | P29: Y - 11.11.
A30: 29 | B30: 43752 | D30: Branky | E30: Roman | F30: Globus - kroužky, provaz | G30: ano | H30: 366.9 | I30: Převod | J30: Air OVT | K30: Ano | M30: =M29-IF(AND(I30="Hotově",J30="Hamerák"),H30+L30) -> 73376.33 | N30: Nákup materiálu pro ČPV Hamercký potok | P30: Y - 11.11.
A31: 30 | B31: 43767 | D31: Doprava | E31: Ešus | F31: Cesťák Hamerák | G31: ano | H31: 5340.72 | I31: Doklad | K31: Ne | M31: =M30-IF(AND(I31="Hotově",J31="Hamerák"),H31+L31) -> 73376.33 | N31: Cestovné
A32: 31 | B32: 43767 | D32: Doprava | E32: Roman | F32: Cesťák Hamerák | G32: ano | H32: 2671.1 | I32: Doklad | K32: Ne | M32: =M31-IF(AND(I32="Hotově",J32="Hamerák"),H32+L32) -> 73376.33 | N32: Cestovné
A33: 32 | B33: 43767 | D33: Doprava | E33: Simona Kl. | F33: Cesťák Hamerák | G33: ano | H33: 1883 | I33: Doklad | K33: Ne | M33: =M32-IF(AND(I33="Hotově",J33="Hamerák"),H33+L33) -> 73376.33 | N33: Cestovné
A34: 33 | B34: 43767 | D34: Doprava | E34: Jáchym | F34: Cesťák Hamerák | G34: ano | H34: 1665 | I34: Doklad | K34: Ne | M34: =M33-IF(AND(I34="Hotově",J34="Hamerák"),H34+L34) -> 73376.33 | N34: Cestovné
A35: 34 | B35: 43767 | D35: Doprava | E35: Amos | F35: Cesťák Hamerák | G35: ano | H35: 2446.4 | I35: Doklad | K35: Ne | M35: =M34-IF(AND(I35="Hotově",J35="Hamerák"),H35+L35) -> 73376.33 | N35: Cestovné
A36: 35 | B36: 43767 | D36: Doprava | E36: Amos | F36: Doprava náklady | G36: ne | H36: 750 | I36: Převod | J36: Air OVT | K36: Ano | M36: =M35-IF(AND(I36="Hotově",J36="Hamerák"),H36+L36) -> 73376.33 | P36: Y - 30.10.
A37: 36 | B37: 43767 | D37: Doprava | E37: Milan | F37: Doprava náklady | G37: ne | H37: 500 | I37: Převod | J37: Air OVT | K37: Ano | M37: =M36-IF(AND(I37="Hotově",J37="Hamerák"),H37+L37) -> 73376.33 | P37: Y - 30.10.
A38: 37 | B38: 43769 | D38: Doprava | E38: Milan | F38: Tisk permice (vyúčtování zálohy) | G38: ano | I38: Doklad | K38: Ano | L38: -5900
A39: 38 | B39: 43769 | D39: Doprava | E39: Milan | F39: Tisk permice | G39: ano | H39: 5900 | I39: Doklad | K39: Ano | M39: =M37-IF(AND(I39="Hotově",J39="Hamerák"),H39+L39) -> 73376.33 | N39: Nákup materiálu pro ČPV Hamercký potok
A40: 39 | B40: 43781 | D40: Doprava | E40: Simona Kl. | F40: Doprava náklady | G40: ne | H40: 651 | I40: Převod | J40: Air OVT | K40: Ano
...

Sheet Přehled tabulky
A1: Vyplaceno | B1: Ano
A3: Popisky řádků | B3: Součet z Částka
A4: Branky | B4: 1028.9 | F4: Příjmy 2019
A5: Ceny | B5: 6100 | F5: Startovné | H5: 36000
A6: Doprava | B6: 86539 | F6: Permice | H6: 45840
A7: Dotace | B7: 14500 | F7: Splutí | H7: 44340
A8: Místní | B8: 15600 | F8: Dotace a sponzoring | H8: 90000
A9: Občerstvení | B9: 8617.67 | F9: Celkem | H9: 216180
A10: Příprava | B10: 10798
A11: Sponzoři | B11: 418
A12: Ubytování | B12: 37600
A13: Celkový součet | B13: 181201.57

Sheet Přehled ZZ
A1: Celkové přehledy | F1: Vyplaceno | G1: Ano
A2: Zisk / ztráta: | B2: =B3-B4 -> 67758.43
A3: Přímy: | B3: ='Příjmy old'!H49 -> 248960 | F3: Popisky řádků | G3: Součet z Částka
A4: Výdaje: | B4: 181201.57 | F4: Branky | G4: 1028.9
F5: Ceny | G5: 6100
F6: Doprava | G6: 96539
F7: Dotace | G7: 4500
F8: Místní | G8: 15600
F9: Občerstvení | G9: 8617.67
F10: Příprava | G10: 10798
F11: Sponzoři | G11: 418
F12: Ubytování | G12: 37600
F13: Celkový součet | G13: 181201.57

Sheet Přehled
A1: Ceny Hamerák 2021 | F1: Hotovost | K1: Dotace & sponzoring
A2: Položka | B2: Cena | C2: Počet | D2: Příjem | F2: Vstupní hotovost | I2: =40000+15000 -> 55000 | K2: ČPV Hamerák | M2: 65000
A3: Závod | B3: 150 | C3: =Pokladny!P2 -> 256 | D3: =B3*C3 -> 38400 | F3: Výstupní hotovost z pokladen | I3: =Pokladny!N2 -> 169767 | K3: ČPV Hameráček | N3: 5k část do Hradce
A4: Splutí víkend | B4: 150 | C4: =Pokladny!Q2 -> 138 | D4: =B4*C4 -> 20700 | F4: Příjem z prodeje | I4: =Pokladny!I2 -> 169610 | K4: Kukabus | M4: 0
A5: Splutí sobota | B5: 100 | C5: =Pokladny!R2 -> 143 | D5: =B5*C5 -> 14300 | F5: Rozdíl v součtech | I5: =Pokladny!O2 -> 157 | K5: Celkem | M5: =SUM(M2:M4) -> 65000
A6: Splutí neděle | B6: 120 | C6: =Pokladny!S2 -> 138 | D6: =B6*C6 -> 16560 | F6: Náklady hotově | I6: =-C28 -> -163105
A7: Permice víkend | B7: 200 | C7: =Pokladny!T2 -> 205 | D7: =B7*C7 -> 41000 | F7: Celkem hotovost | I7: =I2+I3+I6 -> 61662
A8: Permice sobota | B8: 150 | C8: =Pokladny!U2 -> 112 | D8: =B8*C8 -> 16800 | F8: Výstupní hotovost (převod účet) | I8: =I2+I4+I6 -> 61505
A9: Permice neděle | B9: 150 | C9: =Pokladny!V2 -> 74 | D9: =B9*C9 -> 11100 | K9: Hospodářský výsledek
A10: Kelímek | B10: 50 | C10: =Pokladny!W2 -> 150 | D10: =B10*C10 -> 7500 | K10: Příjmy na Hameráku | N10: 153170
A11: Kelímek prodej | B11: 50 | D11: =B11*C11 -> 0 | K11: Dotace | N11: =M5 -> 65000
A12: Kelímek výkup | B12: 50 | D12: =B12*C12 -> 0 | K12: Náklady | N12: =-C33 -> -223139.9
A13: Žeton na kelímek | B13: 50 | C13: =Pokladny!X2 -> 65 | D13: =B13*C13 -> 3250 | K13: Výsledek | N13: =SUM(N10:N12) -> -4969.9
D16: =SUM(D3:D13) -> 169610
A18: Příjmy - kategorie | E18: Příjmy 2019 | I18: Rozdíl
A19: Startovné | C19: =D3 -> 38400 | E19: Startovné | G19: 36000 | I19: =C19-G19 -> 2400
A20: Splutí | C20: =SUM(D4:D6) -> 51560 | E20: Splutí | G20: 44340 | I20: =C20-G20 -> 7220
A21: Permice | C21: =SUM(D7:D9) -> 68900 | E21: Permice | G21: 45840 | I21: =C21-G21 -> 23060
A22: Kelímky | C22: =SUM(D10:D13) -> 10750 | E22: Kelímky | G22: 0 | I22: =C22-G22 -> 10750
A23: Dotace a sponzoring | C23: =M5 -> 65000 | E23: Dotace a sponzoring | G23: 90000 | I23: =C23-G23 -> -25000
A24: Celkem | C24: =SUM(C19:C23) -> 234610 | E24: Celkem | G24: 216180 | I24: =C24-G24 -> 18430
A27: Výdaje - forma | F27: Výdaje - kategorie
A28: Hotovost | C28: =SUM('Výdaje hotově'!$I$2:$I$10) -> 163105
A29: Účet TJ | C29: =SUMIF('Výdaje účet'!$K$2:$K$23,"TJ",'Výdaje účet'!$I$2:$I$53) -> 33800
A30: Účet Air | C30: =SUMIF('Výdaje účet'!$K$2:$K$23,"Air",'Výdaje účet'!$I$2:$I$53) -> 13734.9
A31: Účet Fio | C31: =SUMIF('Výdaje účet'!$K$2:$K$23,"Fio",'Výdaje účet'!$I$2:$I$53) -> 0
A32: Bez účtu | C32: =SUMIF('Výdaje účet'!$K$2:$K$23,"",'Výdaje účet'!$I$2:$I$53) -> 12500
A33: Celkem | C33: =SUM(C28:C32) -> 223139.9

Sheet Výdaje účet
A1: ID | B1: Datum | C1: Čas | D1: Skupina | E1: Kategorie | F1: Komu | G1: Účel | H1: Doklad (použitelný pro vyúčtování) | I1: Částka | J1: Forma | K1: Zdroj | L1: Vyplaceno | M1: Záloha | N1: Zůstatek | O1: Poznámka pro Pavelkovou | P1: Sken/dokument | Q1: Celkové vyúčtování
A2: 1 | D2: Splutí | E2: Místní | F2: Rybáři | G2: Puštění vody na splutí | H2: ano | I2: 14520 | J2: Účet | K2: TJ | L2: Ano | O2: Bude zaplaceno z TJ Bohemians
A3: 2 | B3: 44819 | D3: Kelímky | E3: Kelímky | F3: NickNack | G3: Výroba kelímků | H3: ano | I3: 17726 | J3: Účet | K3: TJ | L3: Ano | O3: Předáno 15.9. k zaplacení TJ
B4: 44846 | D4: Doprava | E4: Materiál | F4: Ondřej Racek | G4: Pytle autobus | H4: ano | I4: 570 | J4: Účet | K4: Air | L4: Ano
B5: 44835 | D5: Doprava | E5: Materiál | F5: Michal Menčík | G5: Pytle autobus | H5: asi ano | I5: 299.4 | J5: Účet | K5: Air | L5: Ano | O5: účtenka asi v papírové podobě v pokladně
D6: Branky | E6: Materiál | F6: Lukáš Kopřiva | G6: Materiál branky | H6: ano | I6: 2389 | J6: Účet | K6: Air | L6: Ano
E7: Doprava | F7: Ešus | G7: Nafta do auta | H7: ne | I7: 1955 | J7: Účet | K7: Air | L7: Ano | O7: společně 3577 platba 28.11. z Air
F8: Ešus | G8: lahev úplatku dolů do Jindřiše tomu chlapovi, co nám odstřihl posledně xylofon | H8: ne | I8: 279 | J8: Účet | K8: Air | L8: Ano | O8: společně 3577 platba 28.11. z Air
F9: Ešus | G9: Doprava PPL - bannery asi | H9: ano, ale ne dotace | I9: 179 | J9: Účet | K9: Air | L9: Ano | O9: společně 3577 platba 28.11. z Air
F10: Ešus | G10: Doprava GLS - bannery | H10: ano, ale ne dotace | I10: 161 | J10: Účet | K10: Air | L10: Ano | O10: společně 3577 platba 28.11. z Air
F11: Ešus | G11: Doprava GLS - bannery TNP | H11: ano, ale ne dotace | I11: 139 | J11: Účet | K11: Air | L11: Ano | O11: společně 3577 platba 28.11. z Air
F12: Ešus | G12: Benzín do centrály | H12: ne | I12: 364 | J12: Účet | K12: Air | L12: Ano | O12: společně 3577 platba 28.11. z Air
F13: Ešus | G13: Oprava centrály | H13: ne | I13: 500 | J13: Účet | K13: Air | L13: Ano | O13: společně 3577 platba 28.11. z Air
F14: Tomáš Bauer | G14: Papírnictví - potřeby | H14: ano | I14: 1955 | J14: Účet | K14: Air | L14: Ano | O14: platba 27.11. z Air
E15: Doprava | F15: Martin Topol | G15: Nafta do auta | H15: cesťák | I15: 1134 | J15: Účet | K15: Air | L15: Ano | O15: platba 28.11. z Air
E16: Doprava | F16: Libor | G16: Nafta do auta | H16: ne | I16: 1445.5 | J16: Účet | K16: Air | L16: Ano | O16: platba 28.11. z Air
B17: 44926 | G17: Propagace | I17: 1554 | J17: Účet | K17: TJ | L17: Ano
G18: Ondráčková | I18: 2365 | J18: Účet | K18: Air
G20: permice | I20: 6000
G21: hrnky | I21: 6500
H24: SUMA | I24: =SUM(I2:I23) -> 60034.9
A28: 4 | B28: 44448 | D28: Splutí | E28: Příprava | F28: Ešus | G28: Poštovné a jiná příprava | H28: ne | I28: 1012 | J28: Účet | K28: Air | L28: Ano
A29: 5 | B29: 44473 | D29: Kelímky | E29: Kelímky | F29: Nina Šálková | G29: Převod za hotovost 50 mince | H29: ne | I29: 0 | J29: Účet | K29: Air | L29: Ano | M29: 15000 | O29: Příjem do hotovosti 15 tisíc v 50 mincích na Hameráku
A30: 6 | B30: 44468 | C30: 0.79166667 | D30: Splutí | E30: Finance | F30: Tomáš Bauer | G30: Papírnictví - potřeby | H30: ano | I30: 809 | J30: Účet | K30: Air | L30: Ano | O30: Zaplaceno 6.3.2022
A31: 7 | B31: 44469 | C31: 0.625 | D31: Splutí | E31: Finance | F31: Tomáš Bauer | G31: Nové pokladny | H31: ano | I31: 768 | J31: Účet | K31: Air | L31: Ano | O31: Zaplaceno 6.3.2022
A32: 8 | B32: 44477 | D32: MHD | E32: Permice | F32: Milan Hrabák | G32: Permice výroba | H32: ne | I32: 5500 | J32: Účet | K32: Air | L32: Ano | O32: Zaplaceno 27.10.
A33: 9 | B33: 44477 | D33: Splutí | E33: Ceny | F33: Milan Hrabák | G33: Hrnky (část s dokladem) | H33: ano | I33: 7000 | J33: Účet | K33: Air | L33: Ano | O33: Zaplaceno 27.10.
A34: 10 | B34: 44477 | D34: Splutí | E34: Ceny | F34: Milan Hrabák | G34: Hrnky (část bez dokladu) | H34: ne | I34: 1525 | J34: Účet | K34: Air | L34: Ano | O34: Zaplaceno 27.10.
A35: 11 | E35: Místní | F35: Ešus | G35: Boček/Kokta pronájem kolem vstupu | I35: 1500 | J35: Účet | K35: Air | L35: Ano | O35: Zaplaceno 27.10.
A36: 12 | E36: Místní | F36: Ešus | G36: Hrázný Fučík | I36: 500 | J36: Účet | K36: Air | L36: Ano | O36: Zaplaceno 27.10.
A37: 13 | E37: Místní | F37: Ešus | G37: Feit - Louka na výstupu Dvoreček | I37: 1500 | J37: Účet | K37: Air | L37: Ano | O37: Zaplaceno 27.10.
A38: 14 | E38: Příprava | F38: Ešus | G38: Nafta do auta (2x) | I38: =1961+525.4 -> 2486.4 | J38: Účet | K38: Air | L38: Ano | O38: Zaplaceno 27.10.
A39: 15 | E39: Dotace | F39: Dittrichová | G39: Část dotace pro Hradečáky | I39: 5000 | J39: Účet | K39: Air | L39: Ano | O39: Zaplaceno 25.11.2021
A40: 16 | F40: TJ Bohemians | G40: Trička, mikiny a další propagace | I40: 1062 | J40: Účet | K40: TJ | L40: Ano | O40: Zaplaceno 31.12.2021
A41: 17 | E41: Sponzoři | F41: Ešus | G41: poslání bannerů do Brna a do Č. Budějovic | I41: 0 | L41: Zatím neznám ani cenu | M41: 500 | O41: Zatím jen předpoklad výdajů
A42: 18 | E42: Doprava | F42: Simona Kl. | G42: Doprava náklady | I42: 0 | L42: Zatím neznám ani cenu | M42: 650 | O42: Zatím jen předpoklad výdajů
A43: 19 | E43: Doprava | F43: Roman Liška | G43: Doprava náklady | I43: 0 | L43: Zatím neznám ani cenu | M43: 1000 | O43: Zatím jen předpoklad výdajů
A44: 20 | E44: Doprava | F44: Amos | G44: Doprava náklady | H44: ne | I44: 0 | L44: Zatím neznám ani cenu | M44: 750 | O44: Zatím jen předpoklad výdajů
A45: 21 | E45: Doprava | F45: Ešus / Tonda Ž | G45: Oprava dveře od auta | I45: 0 | M45: 5000
A46: 22
...

Sheet Výdaje hotově
A1: ID | B1: Datum | C1: Čas | D1: Skupina | E1: Kategorie | F1: Komu | G1: Účel | H1: Doklad (použitelný pro vyúčtování) | I1: Částka | J1: Forma | K1: Zdroj | L1: Vyplaceno | M1: Záloha | N1: Zůstatek | O1: Poznámka pro Pavelkovou | P1: Sken/dokument | Q1: Celkové vyúčtování
G4: SUMA náklady na místě | I4: 11005
A6: 10 | B6: 44836 | C6: 0.5 | D6: Splutí | E6: Ubytování | F6: Kemp | G6: Ubytování - chatky, lidi, autobusy, auta | H6: ano | I6: 50100 | J6: Hotově | K6: Hamerák | L6: Ano
A7: 11 | B7: 44858 | C7: 0.77083333 | D7: MHD | E7: Doprava | F7: J. Kukla | G7: Autobusy | H7: ne | I7: 102000 | J7: Hotově | K7: Hamerák | L7: Ano
G11: Výdaje hotovost celkem: | I11: =SUM(I2:I10) -> 163105
G14: V pokladně fyzicky je: | I14: 151497
I15: -10000 | J15: osobní
I16: -102000 | J16: autobusy
I17: =SUM(I14:I16) -> 39497 | J17: toto je zřejmě v pokladně
A19: 1 | B19: 44471 | C19: 0.70833333 | D19: MHD | E19: Doprava | F19: Amos | G19: Hornbach | H19: ano | I19: 2070 | J19: Hotově | K19: Hamerák
A20: 2 | B20: 44471 | C20: 0.70833333 | D20: Splutí | E20: Branky | F20: Amos | G20: Sprej proti vosám | H20: ano | I20: 99 | J20: Hotově | K20: Hamerák
A21: 3 | B21: 44471 | C21: 0.77083333 | D21: Splutí | E21: Branky | F21: Jáchym | G21: Pytle na odpadky | H21: ano | I21: 55 | J21: Hotově | K21: Hamerák
A22: 4 | B22: 44471 | C22: 0.83333333 | D22: Splutí | E22: Občerstvení | F22: Jana O. | G22: Občerstvení | H22: ano | I22: 39.8 | J22: Hotově | K22: Hamerák
A23: 5 | B23: 44471 | C23: 0.83333333 | D23: Splutí | E23: Občerstvení | F23: Jana O. | G23: Občerstvení | H23: ano | I23: 99 | J23: Hotově | K23: Hamerák
A24: 6 | B24: 44471 | C24: 0.83333333 | D24: Splutí | E24: Občerstvení | F24: Jana O. | G24: Občerstvení | H24: ne | I24: 1422 | J24: Hotově | K24: Hamerák
A25: 7 | B25: 44472 | C25: 0.5 | D25: Splutí | E25: Občerstvení | F25: Milan | G25: Pivo sudy | H25: ne | I25: 5000 | J25: Hotově | K25: Hamerák
A26: 8 | B26: 44472 | C26: 0.5 | D26: Splutí | E26: Občerstvení | F26: Milan | G26: Chleba | H26: ne | I26: 1600 | J26: Hotově | K26: Hamerák
A27: 9 | B27: 44472 | C27: 0.5 | D27: Splutí | E27: Příprava | F27: Milan | G27: Auto - cesty | H27: ne | I27: 400 | J27: Hotově | K27: Hamerák

Sheet Výdaje dotace
A1: ID | B1: Datum | C1: Čas | D1: Skupina | E1: Kategorie | F1: Komu | G1: Účel | H1: Doklad (použitelný pro vyúčtování) | I1: Částka | J1: Forma | K1: Zdroj | L1: Vyplaceno | M1: Záloha | N1: Zůstatek | O1: Poznámka pro Pavelkovou | P1: Sken/dokument | Q1: Celkové vyúčtování
A2: 1 | B2: 44471 | C2: 0.70833333 | D2: MHD | E2: Doprava | F2: Amos | G2: Hornbach | H2: ano | I2: 2070 | J2: Hotově | K2: Hamerák | L2: Ano | P2: H_uctenky_3.pdf
A3: 2 | B3: 44471 | C3: 0.70833333 | D3: Splutí | E3: Branky | F3: Amos | G3: Sprej proti vosám | H3: ano | I3: 99 | J3: Hotově | K3: Hamerák | L3: Ano | P3: H_uctenky_2.pdf
A4: 3 | B4: 44471 | C4: 0.77083333 | D4: Splutí | E4: Branky | F4: Jáchym | G4: Pytle na odpadky | H4: ano | I4: 55 | J4: Hotově | K4: Hamerák | L4: Ano | P4: H_uctenky_2.pdf
A5: 4 | B5: 44471 | C5: 0.83333333 | D5: Splutí | E5: Občerstvení | F5: Jana O. | G5: Občerstvení | H5: ano | I5: 39.8 | J5: Hotově | K5: Hamerák | L5: Ano | P5: H_uctenky_1.pdf
A6: 5 | B6: 44471 | C6: 0.83333333 | D6: Splutí | E6: Občerstvení | F6: Jana O. | G6: Občerstvení | H6: ano | I6: 99 | J6: Hotově | K6: Hamerák | L6: Ano | P6: H_uctenky_1.pdf
A7: 2 | B7: 44449 | C7: 0.54513889 | D7: Kelímky | E7: Kelímky | F7: NickNack | G7: Výroba kelímků | H7: ano | I7: 18452.5 | J7: Účet | K7: TJ | L7: Ano | P7: fa_NICKNACK.pdf
A8: 3 | B8: 44446 | C8: 0.82291667 | D8: Splutí | E8: Branky | F8: Lukáš Kopřiva | G8: Vázací drát | H8: ano | I8: 1292 | J8: Účet | K8: Air | L8: Ano | P8: H21_vazaci_drat.jpg
A9: 6 | B9: 44468 | C9: 0.79166667 | D9: Splutí | E9: Finance | F9: Tomáš Bauer | G9: Papírnictví - potřeby | H9: ano | I9: 809 | L9: Zatím ne | P9: H_uctenky_3.pdf
A10: 7 | B10: 44469 | C10: 0.625 | D10: Splutí | E10: Finance | F10: Tomáš Bauer | G10: Nové pokladny | H10: ano | I10: 768 | L10: Zatím ne | P10: H_uctenky_4.pdf
A11: 9 | B11: 44477 | D11: Splutí | E11: Ceny | F11: Milan Hrabák | G11: Hrnky (část s dokladem) | H11: ano | I11: 7025 | L11: Ano | P11: uct_Falon.jpg
A12: 1 | D12: Splutí | E12: Místní | F12: Rybáři | G12: Puštění vody na splutí | H12: ano | I12: 14520 | J12: Účet | K12: TJ | L12: Nevím | O12: Nevím, jestli jsme platili a kdy | P12: FA_rybari.pdf
B13: 43767 | E13: Doprava | F13: Michal Menčík | G13: Cesťák Hamerák | H13: ano | I13: 603 | J13: Doklad | L13: Ne | P13: cest_MM.pdf
B14: 43767 | E14: Doprava | F14: Jáchym Kopřiva | G14: Cesťák Hamerák | H14: ano | I14: 539 | J14: Doklad | L14: Ne | P14: cest_JK.pdf
E15: TOM dotace | F15: Jirka Klíma | G15: Stany pro TOM | H15: ano | I15: 19540 | P15: stany_TOM.pdf
E16: TOM dotace | F16: Jirka Klíma | G16: Vybavení | H16: ano | I16: 3354 | P16: uctenka_vybaveni.jpg
E17: Servisní náklady | F17: TJ | G17: Interní nájmy | H17: ano | I17: 3296 | P17: OVT_najmy.pdf
E18: Servisní náklady | F18: TJ | G18: Interní nájmy | H18: ano | I18: 6103 | P18: OVT_najmy.pdf
A19: 10 | B19: 44472 | C19: 0.54166667 | D19: Splutí | E19: Ubytování | F19: Kemp | G19: Ubytování - chatky, lidi, autobusy, auta | H19: ano | I19: 44380 | J19: Hotově | K19: Hamerák | L19: Ano | P19: fa_ubytování_MR.pdf
I26: =SUM(I2:I25) -> 123044.3
H27: Zbývá / přes: | I27: =I26-I28 -> 11732.3
I28: 111312
G29: Dotace celkem: | I29: 111.312,-Kč (slovy: stojednatisíctřistadvanáctkorun)

Sheet Dotace_formát_smlouva
A1: Účel celkové dotace | B1: ID | C1: Datum | D1: Čas | E1: Skupina | F1: Kategorie | G1: Komu | H1: Účel | I1: Doklad (použitelný pro vyúčtování) | J1: Částka | K1: Forma | L1: Zdroj | M1: Vyplaceno | N1: Záloha | O1: Zůstatek | P1: Poznámka pro Pavelkovou | Q1: Sken/dokument | R1: Celkové vyúčtování
A2: Spotřeba materiálu | B2: 1 | C2: 44471 | D2: 0.70833333 | E2: MHD | F2: Doprava | G2: Amos | H2: Hornbach | I2: ano | J2: 2070 | K2: Hotově | L2: Hamerák | M2: Ano | Q2: H_uctenky_3.pdf
A3: Spotřeba materiálu | B3: 2 | C3: 44471 | D3: 0.70833333 | E3: Splutí | F3: Branky | G3: Amos | H3: Sprej proti vosám | I3: ano | J3: 99 | K3: Hotově | L3: Hamerák | M3: Ano | Q3: H_uctenky_2.pdf
A4: Spotřeba materiálu | B4: 3 | C4: 44471 | D4: 0.77083333 | E4: Splutí | F4: Branky | G4: Jáchym | H4: Pytle na odpadky | I4: ano | J4: 55 | K4: Hotově | L4: Hamerák | M4: Ano | Q4: H_uctenky_2.pdf
A5: Ostatní služby (stravování, ubytování, nájemné sportovišť, doprava, jiné služby) | B5: 4 | C5: 44471 | D5: 0.83333333 | E5: Splutí | F5: Občerstvení | G5: Jana O. | H5: Občerstvení | I5: ano | J5: 39.8 | K5: Hotově | L5: Hamerák | M5: Ano | Q5: H_uctenky_1.pdf
A6: Ostatní služby (stravování, ubytování, nájemné sportovišť, doprava, jiné služby) | B6: 5 | C6: 44471 | D6: 0.83333333 | E6: Splutí | F6: Občerstvení | G6: Jana O. | H6: Občerstvení | I6: ano | J6: 99 | K6: Hotově | L6: Hamerák | M6: Ano | Q6: H_uctenky_1.pdf
A7: Spotřeba materiálu | B7: 2 | C7: 44449 | D7: 0.54513889 | E7: Kelímky | F7: Kelímky | G7: NickNack | H7: Výroba kelímků | I7: ano | J7: 18452.5 | K7: Účet | L7: TJ | M7: Ano | Q7: fa_NICKNACK.pdf
A8: Spotřeba materiálu | B8: 3 | C8: 44446 | D8: 0.82291667 | E8: Splutí | F8: Branky | G8: Lukáš Kopřiva | H8: Vázací drát | I8: ano | J8: 1292 | K8: Účet | L8: Air | M8: Ano | Q8: H21_vazaci_drat.jpg
A9: Spotřeba materiálu | B9: 6 | C9: 44468 | D9: 0.79166667 | E9: Splutí | F9: Finance | G9: Tomáš Bauer | H9: Papírnictví - potřeby | I9: ano | J9: 809 | M9: Zatím ne | Q9: H_uctenky_3.pdf
A10: Spotřeba materiálu | B10: 7 | C10: 44469 | D10: 0.625 | E10: Splutí | F10: Finance | G10: Tomáš Bauer | H10: Nové pokladny | I10: ano | J10: 768 | M10: Zatím ne | Q10: H_uctenky_4.pdf
A11: Spotřeba materiálu | B11: 9 | C11: 44477 | E11: Splutí | F11: Ceny | G11: Milan Hrabák | H11: Hrnky (část s dokladem) | I11: ano | J11: 7025 | M11: Ano | Q11: uct_Falon.jpg
A12: Ostatní služby (stravování, ubytování, nájemné sportovišť, doprava, jiné služby) | B12: 1 | E12: Splutí | F12: Místní | G12: Rybáři | H12: Puštění vody na splutí | I12: ano | J12: 14520 | K12: Účet | L12: TJ | M12: Nevím | Q12: FA_rybari.pdf
A13: Pohonné hmoty | C13: 43767 | F13: Doprava | G13: Michal Menčík | H13: Cesťák Hamerák | I13: ano | J13: 603 | K13: Doklad | M13: Ne | Q13: cest_MM.pdf
A14: Pohonné hmoty | C14: 43767 | F14: Doprava | G14: Jáchym Kopřiva | H14: Cesťák Hamerák | I14: ano | J14: 539 | K14: Doklad | M14: Ne | Q14: cest_JK.pdf
A15: Spotřeba materiálu | F15: TOM dotace | G15: Jirka Klíma | H15: Stany pro TOM | I15: ano | J15: 19540 | Q15: stany_TOM.pdf
A16: Spotřeba materiálu | F16: TOM dotace | G16: Jirka Klíma | H16: Vybavení | I16: ano | J16: 3354 | Q16: uctenka_vybaveni.jpg
A17: Ostatní služby (stravování, ubytování, nájemné sportovišť, doprava, jiné služby) | F17: OVT nájem | G17: TJ | H17: Interní nájmy | I17: ano | J17: 3296 | Q17: OVT_najmy.pdf
A18: Ostatní služby (stravování, ubytování, nájemné sportovišť, doprava, jiné služby) | F18: OVT nájem | G18: TJ | H18: Interní nájmy | I18: ano | J18: 6103 | Q18: OVT_najmy.pdf
A19: Ostatní služby (stravování, ubytování, nájemné sportovišť, doprava, jiné služby) | B19: 10 | C19: 44472 | D19: 0.54166667 | E19: Splutí | F19: Ubytování | G19: Kemp | H19: Ubytování - chatky, lidi, autobusy, auta | I19: ano | J19: 44380 | K19: Hotově | L19: Hamerák | M19: Ano | Q19: fa_ubytování_MR.pdf
A23: Spotřeba materiálu (sportovní vybavení do 60 tis. Kč):
A24: Pohonné hmoty
A25: Opravy sportovního vybavení
A26: Cestovné | J26: =SUM(J2:J25) -> 123044.3
A27: Ostatní služby (stravování, ubytování, nájemné sportovišť, doprava, jiné služby) | I27: Zbývá / přes: | J27: =J26-J28 -> 11732.3
A28: Osobní náklady trenérů, trenérské služby | J28: 111312
H29: Dotace celkem: | J29: 111.312,-Kč (slovy: stojednatisíctřistadvanáctkorun)

Sheet Pokladny
I1: Příjmy celkem | J1: Příjmy závod | K1: Příjmy splutí | L1: Příjmy doprava | M1: Příjmy kelímky | N1: Příjem hotovost | O1: Rozdíl součty | P1: Počet závod | Q1: Splutí VIK | R1: Splutí SO | S1: Splutí NE | T1: Permice VIK | U1: Permice SO | V1: Permice NE | W1: Kelímek | X1: Žeton na kelímek
I2: =SUM(J2:M2) -> 169610 | J2: =SUM(J3:J986) -> 38400 | K2: =SUM(K3:K986) -> 51560 | L2: =SUM(L3:L986) -> 68900 | M2: =SUM(M3:M986) -> 10750 | N2: =SUM(N3:N986) -> 169767 | O2: =SUM(O3:O986) -> 157 | P2: =SUM(P3:P986) -> 256 | Q2: =SUM(Q3:Q986) -> 138 | ... X2: =SUM(X3:X986) -> 65
B3: #1
B4: Závod chatka | D4: Zodpovědný: | E4: Milan | G4: Pokladna: | H4: Modrá velká
B6: Cenina | C6: Cena | D6: Otevření | E6: Během dne | F6: Oprávky | G6: Uzavření | H6: Výsledek | I6: F výsledek
B7: Peníze | D7: 10000 | G7: 57950 | H7: =G7+F7-E7-D7 -> 47950 | I7: =H7 -> 47950 | N7: =I7 -> 47950
B8: Závod | C8: =VLOOKUP(B8,Přehled!$A$3:$B$15,2,FALSE) -> 150 | D8: 500 | G8: 244 | H8: =G8+F8-E8-D8 -> -256 | I8: =H8*C8 -> -38400 | J8: =-I8 -> 38400 | P8: =-$H8 -> 256
B9: Splutí víkend | C9: =VLOOKUP(B9,Přehled!$A$3:$B$15,2,FALSE) -> 150 | D9: 500 | F9: 6 | G9: 191 | H9: =G9+F9-E9-D9-H8 -> -47 | I9: =H9*C9 -> -7050 | K9: =-I9 -> 7050 | Q9: =-$H9 -> 47
B10: Splutí sobota | C10: =VLOOKUP(B10,Přehled!$A$3:$B$15,2,FALSE) -> 100 | D10: 50 | G10: 25 | H10: =G10+F10-E10-D10 -> -25 | I10: =H10*C10 -> -2500 | K10: =-I10 -> 2500 | R10: =-$H10 -> 25
B11: Splutí neděle | C11: =VLOOKUP(B11,Přehled!$A$3:$B$15,2,FALSE) -> 120 | H11: =G11+F11-E11-D11 -> 0 | I11: =H11*C11 -> 0 | K11: =-I11 -> 0 | S11: =-$H11 -> 0
B12: Permice víkend | C12: =VLOOKUP(B12,Přehled!$A$3:$B$15,2,FALSE) -> 200 | H12: =G12+F12-E12-D12 -> 0 | I12: =H12*C12 -> 0 | L12: =-I12 -> 0 | T12: =-$H12 -> 0
B13: Permice sobota | C13: =VLOOKUP(B13,Přehled!$A$3:$B$15,2,FALSE) -> 150 | H13: =G13+F13-E13-D13 -> 0 | I13: =H13*C13 -> 0 | L13: =-I13 -> 0 | U13: =-$H13 -> 0
B14: Permice neděle | C14: =VLOOKUP(B14,Přehled!$A$3:$B$15,2,FALSE) -> 150 | H14: =G14+F14-E14-D14 -> 0 | I14: =H14*C14 -> 0 | L14: =-I14 -> 0 | V14: =-$H14 -> 0
B15: Kelímek | C15: =VLOOKUP(B15,Přehled!$A$3:$B$15,2,FALSE) -> 50 | H15: =G15+F15-E15-D15 -> 0 | I15: =H15*C15 -> 0 | M15: =-I15 -> 0 | W15: =-$H15 -> 0
B16: Žeton na kelímek | C16: =VLOOKUP(B16,Přehled!$A$3:$B$15,2,FALSE) -> 50 | H16: =G16+F16-E16-D16 -> 0 | I16: =H16*C16 -> 0 | M16: =-I16 -> 0 | X16: =-$H16 -> 0
H17: =G17+F17-E17-D17 -> 0 | I17: =H17*C17 -> 0
H18: =G18+F18-E18-D18 -> 0 | I18: =H18*C18 -> 0
B19: Uzavřeno papír: | C19: 44471 | E19: Uzavřeno PC: | F19: 44477 | H19: Rozdíl: | I19: =SUM(I7:I18) -> 0 | O19: =I19 -> 0
B21: #2
B22: Permice chatka | D22: Zodpovědný: | E22: Jana B. | G22: Pokladna: | H22: Červená stará
B24: Cenina | C24: Cena | D24: Otevření | E24: Během dne | F24: Oprávky | G24: Uzavření | H24: Výsledek | I24: F výsledek
B25: Peníze | D25: 5000 | G25: =43250+1200 -> 44450 | H25: =G25+F25-E25-D25 -> 39450 | I25: =H25 -> 39450 | N25: =I25 -> 39450
B26: Závod | C26: =VLOOKUP(B26,Přehled!$A$3:$B$15,2,FALSE) -> 150 | D26: 0 | H26: =G26+F26-E26-D26 -> 0 | I26: =H26*C26 -> 0 | J26: =-I26 -> 0 | P26: =-$H26 -> 0
B27: Splutí víkend | C27: =VLOOKUP(B27,Přehled!$A$3:$B$15,2,FALSE) -> 150 | D27: 0 | H27: =G27+F27-E27-D27-H26 -> 0 | I27: =H27*C27 -> 0 | K27: =-I27 -> 0 | Q27: =-$H27 -> 0
B28: Splutí sobota | C28: =VLOOKUP(B28,Přehled!$A$3:$B$15,2,FALSE) -> 100 | D28: 0 | H28: =G28+F28-E28-D28 -> 0 | I28: =H28*C28 -> 0 | K28: =-I28 -> 0 | R28: =-$H28 -> 0
B29: Splutí neděle | C29: =VLOOKUP(B29,Přehled!$A$3:$B$15,2,FALSE) -> 120 | D29: 0 | H29: =G29+F29-E29-D29 -> 0 | I29: =H29*C29 -> 0 | K29: =-I29 -> 0 | S29: =-$H29 -> 0
B30: Permice víkend | C30: =VLOOKUP(B30,Přehled!$A$3:$B$15,2,FALSE) -> 200 | D30: 300 | G30: 151 | H30: =G30+F30-E30-D30 -> -149 | I30: =H30*C30 -> -29800 | L30: =-I30 -> 29800 | T30: =-$H30 -> 149
B31: Permice sobota | C31: =VLOOKUP(B31,Přehled!$A$3:$B$15,2,FALSE) -> 150 | D31: 200 | G31: 136 | H31: =G31+F31-E31-D31 -> -64 | I31: =H31*C31 -> -9600 | L31: =-I31 -> 9600 | U31: =-$H31 -> 64
B32: Permice neděle | C32: =VLOOKUP(B32,Přehled!$A$3:$B$15,2,FALSE) -> 150 | H32: =G32+F32-E32-D32 -> 0 | I32: =H32*C32 -> 0 | L32: =-I32 -> 0 | V32: =-$H32 -> 0
B33: Kelímek | C33: =VLOOKUP(B33,Přehled!$A$3:$B$15,2,FALSE) -> 50 | H33: =G33+F33-E33-D33 -> 0 | I33: =H33*C33 -> 0 | M33: =-I33 -> 0 | W33: =-$H33 -> 0
B34: Žeton na kelímek | C34: =VLOOKUP(B34,Přehled!$A$3:$B$15,2,FALSE) -> 50 | H34: =G34+F34-E34-D34 -> 0 | I34: =H34*C34 -> 0 | M34: =-I34 -> 0 | X34: =-$H34 -> 0
H35: =G35+F35-E35-D35 -> 0 | I35: =H35*C35 -> 0
H36: =G36+F36-E36-D36 -> 0 | I36: =H36*C36 -> 0
B37: Uzavřeno papír: | C37: 44471 | E37: Uzavřeno PC: | F37: 44477 | H37: Rozdíl: | I37: =SUM(I25:I36) -> 50 | O37: =I37 -> 50
B39: #3
B40: Kelímky chatka | D40: Zodpovědný: | E40: Terka a Bára | G40: Pokladna: | H40: Červená nová (kulatější)
B42: Cenina | C42: Cena | D42: Otevření | E42: Během dne | F42: Oprávky | G42: Uzavření | H42: Výsledek | I42: F výsledek
B43: Peníze | D43: 5000 | G43: 12750 | H43: =G43+F43-E43-D43 -> 7750 | I43: =H43 -> 7750 | N43: =I43 -> 7750
B44: Závod | C44: =VLOOKUP(B44,Přehled!$A$3:$B$15,2,FALSE) -> 150 | D44: 0 | G44: 0 | H44: =G44+F44-E44-D44 -> 0 | I44: =H44*C44 -> 0 | J44: =-I44 -> 0 | P44: =-$H44 -> 0
B45: Splutí víkend | C45: =VLOOKUP(B45,Přehled!$A$3:$B$15,2,FALSE) -> 150 | D45: 0 | G45: 0 | H45: =G45+F45-E45-D45-H44 -> 0 | I45: =H45*C45 -> 0 | K45: =-I45 -> 0 | Q45: =-$H45 -> 0
...
